Workbook

Sheet Hypothèses
A1: Paramètre | B1: Valeur
A2: Capital initial (€) | B2: 4900
A3: Frais fixes infra départ (€/mois) | B3: 500
A4: Hausse frais fixes / trimestre | B4: 0.15
A5: Frais variables (% CA HT) | B5: 0.01
A6: TVA (%) | B6: 0.2
A7: Churn — début (mois) | B7: 9
A8: Churn initial (%/mois) | B8: 0.05
A9: Décroissance churn (%/mois) | B9: 0.1
A10: Rattrapage rampe (%/mois) | B10: 0.4
A11: Prix Atelier TTC (€/mois) | B11: 59
A12: Prix Horizon TTC (€/mois) | B12: 149
A13: Prix Rayonnement TTC (€/mois) | B13: 549
... A15: Jours / mois / développeur | B15: 10
A16: Coût mensuel / développeur (€ HT) | B16: =B14*B15
A18: Facturation par année
A19: A1 | B19: 0.6 | C19: 0.05 | D19: 20
A20: A2 | B20: 0.5 | C20: 0.1 | D20: 25
A21: A3 | B21: 0.4 | C21: 0.12 | D21: 30
A23: Effectifs cibles fin d'année (base, avant facteur scénario)
A24: Plan | B24: Fin A1 | C24: Fin A2 | D24: Fin A3
A25: Atelier | B25: 5 | C25: 10 | D25: 20
A26: Horizon | B26: 10 | C26: 35 | D26: 70
A27: Rayonnement | B27: 0 | C27: 2 | D27: 5
A28: Zénith (contrats) | B28: 0 | C28: 1 | D28: 3
A30: Zénith — montants TTC (base)
A31: Mois 18 | B31: 15000
A32: Mois 30/34 | B32: 17000
A34: Note | B34: Modifier les valeurs ci-dessus : les 3 onglets scénario se recalculent automatiquement.

Sheet Prudent (-30%)
A1: Facteur clients (scénario) | B1: 0.7
A2: Zénith fin A2 (cible) | B2: =ROUND(Hypothèses!$C$28*$B$1,0) | C2: Zénith fin A3 (cible) | D2: =ROUND(Hypothèses!$D$28*$B$1,0)
A3: Mois | B3: Année | C3: Atelier | D3: Horizon | E3: Rayonnement | F3: Cible Atelier | G3: Cible Horizon | H3: Cible Rayonn. | I3: Taux churn | J3: Clients payants | K3: MRR abo TTC | L3: Options TTC | M3: Zénith TTC | N3: CA TTC | O3: CA HT | P3: Frais fixes infra | Q3: Nb développeurs | R3: Sous-traitance dev (HT) | S3: Frais variables 1% | T3: EBITDA | U3: Trésorerie
A4: 1 | B4: =INT((A4-1)/12)+1 | C4: =ROUND(IF(MOD($A4,12)=0,F4,(IF(4=4,0,C3))*(1-$I4)+IF((IF(4=4,0,C3))*(1-$I4)<F4,(F4-(IF(4=4,0,C3))*(1-$I4))*Hypothèses!$B$10,0)),1) | D4: =ROUND(IF(MOD($A4,12)=0,G4,(IF(4=4,0,D3))*(1-$I4)+IF((IF(4=4,0,D3))*(1-$I4)<G4,(G4-(IF(4=4,0,D3))*(1-$I4))*Hypothèses!$B$10,0)),1) | E4: =ROUND(IF(MOD($A4,12)=0,H4,(IF(4=4,0,E3))*(1-$I4)+IF((IF(4=4,0,E3))*(1-$I4)<H4,(H4-(IF(4=4,0,E3))*(1-$I4))*Hypothèses!$B$10,0)),1) | F4: =(IF(B4=1,0,IF(B4=2,Hypothèses!$B$25,IF(B4=3,Hypothèses!$C$25,Hypothèses!$D$25)))+(IF(B4=1,Hypothèses!$B$25,IF(B4=2,Hypothèses!$C$25,IF(B4=3,Hypothèses!$D$25,Hypothèses!$D$25)))-(IF(B4=1,0,IF(B4=2,Hypothèses!$B$25,IF(B4=3,Hypothèses!$C$25,Hypothèses!$D$25)))))*((A4)-INT((A4-1)/12)*12)/12)*$B$1 | G4: =(IF(B4=1,0,IF(B4=2,Hypothèses!$B$26,IF(B4=3,Hypothèses!$C$26,Hypothèses!$D$26)))+(IF(B4=1,Hypothèses!$B$26,IF(B4=2,Hypothèses!$C$26,IF(B4=3,Hypothèses!$D$26,Hypothèses!$D$26)))-(IF(B4=1,0,IF(B4=2,Hypothèses!$B$26,IF(B4=3,Hypothèses!$C$26,Hypothèses!$D$26)))))*((A4)-INT((A4-1)/12)*12)/12)*$B$1 | H4: =(IF(B4=1,0,IF(B4=2,Hypothèses!$B$27,IF(B4=3,Hypothèses!$C$27,Hypothèses!$D$27)))+(IF(B4=1,Hypothèses!$B$27,IF(B4=2,Hypothèses!$C$27,IF(B4=3,Hypothèses!$D$27,Hypothèses!$D$27)))-(IF(B4=1,0,IF(B4=2,Hypothèses!$B$27,IF(B4=3,Hypothèses!$C$27,Hypothèses!$D$27)))))*((A4)-INT((A4-1)/12)*12)/12)*$B$1 | I4: =IF(A4<Hypothèses!$B$7,0,Hypothèses!$B$8*(1-Hypothèses!$B$9)^(A4-Hypothèses!$B$7)) | J4: =C4+D4+E4 | K4: =(C4*Hypothèses!$B$11+D4*Hypothèses!$B$12+E4*Hypothèses!$B$13)*(IF(B4=1,Hypothèses!$B$19,IF(B4=2,Hypothèses!$B$20,Hypothèses!$B$21))+(1-(IF(B4=1,Hypothèses!$B$19,IF(B4=2,Hypothèses!$B$20,Hypothèses!$B$21))))*11/12) | L4: =J4*IF(B4=1,Hypothèses!$C$19,IF(B4=2,Hypothèses!$C$20,Hypothèses!$C$21))*IF(B4=1,Hypothèses!$D$19,IF(B4=2,Hypothèses!$D$20,Hypothèses!$D$21)) | M4: =IF(A4=18,IF($B$2>=1,Hypothèses!$B$31,0),IF(AND(OR(A4=30,A4=34),$D$2>=1),Hypothèses!$B$32*MIN(1,$D$2/3),0)) | N4: =K4+L4+M4 | O4: =N4/(1+Hypothèses!$B$6) | P4: =Hypothèses!$B$3*(1+Hypothèses!$B$4)^INT((A4-1)/3) | Q4: =0 | R4: =Q4*Hypothèses!$B$16 | S4: =O4*Hypothèses!$B$5 | T4: =O4-P4-R4-S4 | U4: =Hypothèses!$B$2+T4
A5: 2 | B5: =INT((A5-1)/12)+1 | C5: =ROUND(IF(MOD($A5,12)=0,F5,(IF(5=4,0,C4))*(1-$I5)+IF((IF(5=4,0,C4))*(1-$I5)<F5,(F5-(IF(5=4,0,C4))*(1-$I5))*Hypothèses!$B$10,0)),1) | D5: =ROUND(IF(MOD($A5,12)=0,G5,(IF(5=4,0,D4))*(1-$I5)+IF((IF(5=4,0,D4))*(1-$I5)<G5,(G5-(IF(5=4,0,D4))*(1-$I5))*Hypothèses!$B$10,0)),1) | E5: =ROUND(IF(MOD($A5,12)=0,H5,(IF(5=4,0,E4))*(1-$I5)+IF((IF(5=4,0,E4))*(1-$I5)<H5,(H5-(IF(5=4,0,E4))*(1-$I5))*Hypothèses!$B$10,0)),1) | F5: =(IF(B5=1,0,IF(B5=2,Hypothèses!$B$25,IF(B5=3,Hypothèses!$C$25,Hypothèses!$D$25)))+(IF(B5=1,Hypothèses!$B$25,IF(B5=2,Hypothèses!$C$25,IF(B5=3,Hypothèses!$D$25,Hypothèses!$D$25)))-(IF(B5=1,0,IF(B5=2,Hypothèses!$B$25,IF(B5=3,Hypothèses!$C$25,Hypothèses!$D$25)))))*((A5)-INT((A5-1)/12)*12)/12)*$B$1 | G5: =(IF(B5=1,0,IF(B5=2,Hypothèses!$B$26,IF(B5=3,Hypothèses!$C$26,Hypothèses!$D$26)))+(IF(B5=1,Hypothèses!$B$26,IF(B5=2,Hypothèses!$C$26,IF(B5=3,Hypothèses!$D$26,Hypothèses!$D$26)))-(IF(B5=1,0,IF(B5=2,Hypothèses!$B$26,IF(B5=3,Hypothèses!$C$26,Hypothèses!$D$26)))))*((A5)-INT((A5-1)/12)*12)/12)*$B$1 | H5: =(IF(B5=1,0,IF(B5=2,Hypothèses!$B$27,IF(B5=3,Hypothèses!$C$27,Hypothèses!$D$27)))+(IF(B5=1,Hypothèses!$B$27,IF(B5=2,Hypothèses!$C$27,IF(B5=3,Hypothèses!$D$27,Hypothèses!$D$27)))-(IF(B5=1,0,IF(B5=2,Hypothèses!$B$27,IF(B5=3,Hypothèses!$C$27,Hypothèses!$D$27)))))*((A5)-INT((A5-1)/12)*12)/12)*$B$1 | I5: =IF(A5<Hypothèses!$B$7,0,Hypothèses!$B$8*(1-Hypothèses!$B$9)^(A5-Hypothèses!$B$7)) | J5: =C5+D5+E5 | K5: =(C5*Hypothèses!$B$11+D5*Hypothèses!$B$12+E5*Hypothèses!$B$13)*(IF(B5=1,Hypothèses!$B$19,IF(B5=2,Hypothèses!$B$20,Hypothèses!$B$21))+(1-(IF(B5=1,Hypothèses!$B$19,IF(B5=2,Hypothèses!$B$20,Hypothèses!$B$21))))*11/12) | L5: =J5*IF(B5=1,Hypothèses!$C$19,IF(B5=2,Hypothèses!$C$20,Hypothèses!$C$21))*IF(B5=1,Hypothèses!$D$19,IF(B5=2,Hypothèses!$D$20,Hypothèses!$D$21)) | M5: =IF(A5=18,IF($B$2>=1,Hypothèses!$B$31,0),IF(AND(OR(A5=30,A5=34),$D$2>=1),Hypothèses!$B$32*MIN(1,$D$2/3),0)) | N5: =K5+L5+M5 | O5: =N5/(1+Hypothèses!$B$6) | P5: =Hypothèses!$B$3*(1+Hypothèses!$B$4)^INT((A5-1)/3) | Q5: =0 | R5: =Q5*Hypothèses!$B$16 | S5: =O5*Hypothèses!$B$5 | T5: =O5-P5-R5-S5 | U5: =U4+T5
A6: 3 | B6: =INT((A6-1)/12)+1 | C6: =ROUND(IF(MOD($A6,12)=0,F6,(IF(6=4,0,C5))*(1-$I6)+IF((IF(6=4,0,C5))*(1-$I6)<F6,(F6-(IF(6=4,0,C5))*(1-$I6))*Hypothèses!$B$10,0)),1) | D6: =ROUND(IF(MOD($A6,12)=0,G6,(IF(6=4,0,D5))*(1-$I6)+IF((IF(6=4,0,D5))*(1-$I6)<G6,(G6-(IF(6=4,0,D5))*(1-$I6))*Hypothèses!$B$10,0)),1) | E6: =ROUND(IF(MOD($A6,12)=0,H6,(IF(6=4,0,E5))*(1-$I6)+IF((IF(6=4,0,E5))*(1-$I6)<H6,(H6-(IF(6=4,0,E5))*(1-$I6))*Hypothèses!$B$10,0)),1) | F6: =(IF(B6=1,0,IF(B6=2,Hypothèses!$B$25,IF(B6=3,Hypothèses!$C$25,Hypothèses!$D$25)))+(IF(B6=1,Hypothèses!$B$25,IF(B6=2,Hypothèses!$C$25,IF(B6=3,Hypothèses!$D$25,Hypothèses!$D$25)))-(IF(B6=1,0,IF(B6=2,Hypothèses!$B$25,IF(B6=3,Hypothèses!$C$25,Hypothèses!$D$25)))))*((A6)-INT((A6-1)/12)*12)/12)*$B$1 | G6: =(IF(B6=1,0,IF(B6=2,Hypothèses!$B$26,IF(B6=3,Hypothèses!$C$26,Hypothèses!$D$26)))+(IF(B6=1,Hypothèses!$B$26,IF(B6=2,Hypothèses!$C$26,IF(B6=3,Hypothèses!$D$26,Hypothèses!$D$26)))-(IF(B6=1,0,IF(B6=2,Hypothèses!$B$26,IF(B6=3,Hypothèses!$C$26,Hypothèses!$D$26)))))*((A6)-INT((A6-1)/12)*12)/12)*$B$1 | H6: =(IF(B6=1,0,IF(B6=2,Hypothèses!$B$27,IF(B6=3,Hypothèses!$C$27,Hypothèses!$D$27)))+(IF(B6=1,Hypothèses!$B$27,IF(B6=2,Hypothèses!$C$27,IF(B6=3,Hypothèses!$D$27,Hypothèses!$D$27)))-(IF(B6=1,0,IF(B6=2,Hypothèses!$B$27,IF(B6=3,Hypothèses!$C$27,Hypothèses!$D$27)))))*((A6)-INT((A6-1)/12)*12)/12)*$B$1 | I6: =IF(A6<Hypothèses!$B$7,0,Hypothèses!$B$8*(1-Hypothèses!$B$9)^(A6-Hypothèses!$B$7)) | J6: =C6+D6+E6 | K6: =(C6*Hypothèses!$B$11+D6*Hypothèses!$B$12+E6*Hypothèses!$B$13)*(IF(B6=1,Hypothèses!$B$19,IF(B6=2,Hypothèses!$B$20,Hypothèses!$B$21))+(1-(IF(B6=1,Hypothèses!$B$19,IF(B6=2,Hypothèses!$B$20,Hypothèses!$B$21))))*11/12) | L6: =J6*IF(B6=1,Hypothèses!$C$19,IF(B6=2,Hypothèses!$C$20,Hypothèses!$C$21))*IF(B6=1,Hypothèses!$D$19,IF(B6=2,Hypothèses!$D$20,Hypothèses!$D$21)) | M6: =IF(A6=18,IF($B$2>=1,Hypothèses!$B$31,0),IF(AND(OR(A6=30,A6=34),$D$2>=1),Hypothèses!$B$32*MIN(1,$D$2/3),0)) | N6: =K6+L6+M6 | O6: =N6/(1+Hypothèses!$B$6) | P6: =Hypothèses!$B$3*(1+Hypothèses!$B$4)^INT((A6-1)/3) | Q6: =0 | R6: =Q6*Hypothèses!$B$16 | S6: =O6*Hypothèses!$B$5 | T6: =O6-P6-R6-S6 | U6: =U5+T6
A7: 4 | B7: =INT((A7-1)/12)+1 | C7: =ROUND(IF(MOD($A7,12)=0,F7,(IF(7=4,0,C6))*(1-$I7)+IF((IF(7=4,0,C6))*(1-$I7)<F7,(F7-(IF(7=4,0,C6))*(1-$I7))*Hypothèses!$B$10,0)),1) | D7: =ROUND(IF(MOD($A7,12)=0,G7,(IF(7=4,0,D6))*(1-$I7)+IF((IF(7=4,0,D6))*(1-$I7)<G7,(G7-(IF(7=4,0,D6))*(1-$I7))*Hypothèses!$B$10,0)),1) | E7: =ROUND(IF(MOD($A7,12)=0,H7,(IF(7=4,0,E6))*(1-$I7)+IF((IF(7=4,0,E6))*(1-$I7)<H7,(H7-(IF(7=4,0,E6))*(1-$I7))*Hypothèses!$B$10,0)),1) | F7: =(IF(B7=1,0,IF(B7=2,Hypothèses!$B$25,IF(B7=3,Hypothèses!$C$25,Hypothèses!$D$25)))+(IF(B7=1,Hypothèses!$B$25,IF(B7=2,Hypothèses!$C$25,IF(B7=3,Hypothèses!$D$25,Hypothèses!$D$25)))-(IF(B7=1,0,IF(B7=2,Hypothèses!$B$25,IF(B7=3,Hypothèses!$C$25,Hypothèses!$D$25)))))*((A7)-INT((A7-1)/12)*12)/12)*$B$1 | G7: =(IF(B7=1,0,IF(B7=2,Hypothèses!$B$26,IF(B7=3,Hypothèses!$C$26,Hypothèses!$D$26)))+(IF(B7=1,Hypothèses!$B$26,IF(B7=2,Hypothèses!$C$26,IF(B7=3,Hypothèses!$D$26,Hypothèses!$D$26)))-(IF(B7=1,0,IF(B7=2,Hypothèses!$B$26,IF(B7=3,Hypothèses!$C$26,Hypothèses!$D$26)))))*((A7)-INT((A7-1)/12)*12)/12)*$B$1 | H7: =(IF(B7=1,0,IF(B7=2,Hypothèses!$B$27,IF(B7=3,Hypothèses!$C$27,Hypothèses!$D$27)))+(IF(B7=1,Hypothèses!$B$27,IF(B7=2,Hypothèses!$C$27,IF(B7=3,Hypothèses!$D$27,Hypothèses!$D$27)))-(IF(B7=1,0,IF(B7=2,Hypothèses!$B$27,IF(B7=3,Hypothèses!$C$27,Hypothèses!$D$27)))))*((A7)-INT((A7-1)/12)*12)/12)*$B$1 | I7: =IF(A7<Hypothèses!$B$7,0,Hypothèses!$B$8*(1-Hypothèses!$B$9)^(A7-Hypothèses!$B$7)) | J7: =C7+D7+E7 | K7: =(C7*Hypothèses!$B$11+D7*Hypothèses!$B$12+E7*Hypothèses!$B$13)*(IF(B7=1,Hypothèses!$B$19,IF(B7=2,Hypothèses!$B$20,Hypothèses!$B$21))+(1-(IF(B7=1,Hypothèses!$B$19,IF(B7=2,Hypothèses!$B$20,Hypothèses!$B$21))))*11/12) | L7: =J7*IF(B7=1,Hypothèses!$C$19,IF(B7=2,Hypothèses!$C$20,Hypothèses!$C$21))*IF(B7=1,Hypothèses!$D$19,IF(B7=2,Hypothèses!$D$20,Hypothèses!$D$21)) | M7: =IF(A7=18,IF($B$2>=1,Hypothèses!$B$31,0),IF(AND(OR(A7=30,A7=34),$D$2>=1),Hypothèses!$B$32*MIN(1,$D$2/3),0)) | N7: =K7+L7+M7 | O7: =N7/(1+Hypothèses!$B$6) | P7: =Hypothèses!$B$3*(1+Hypothèses!$B$4)^INT((A7-1)/3) | Q7: =0 | R7: =Q7*Hypothèses!$B$16 | S7: =O7*Hypothèses!$B$5 | T7: =O7-P7-R7-S7 | U7: =U6+T7
A8: 5 | B8: =INT((A8-1)/12)+1 | C8: =ROUND(IF(MOD($A8,12)=0,F8,(IF(8=4,0,C7))*(1-$I8)+IF((IF(8=4,0,C7))*(1-$I8)<F8,(F8-(IF(8=4,0,C7))*(1-$I8))*Hypothèses!$B$10,0)),1) | D8: =ROUND(IF(MOD($A8,12)=0,G8,(IF(8=4,0,D7))*(1-$I8)+IF((IF(8=4,0,D7))*(1-$I8)<G8,(G8-(IF(8=4,0,D7))*(1-$I8))*Hypothèses!$B$10,0)),1) | E8: =ROUND(IF(MOD($A8,12)=0,H8,(IF(8=4,0,E7))*(1-$I8)+IF((IF(8=4,0,E7))*(1-$I8)<H8,(H8-(IF(8=4,0,E7))*(1-$I8))*Hypothèses!$B$10,0)),1) | F8: =(IF(B8=1,0,IF(B8=2,Hypothèses!$B$25,IF(B8=3,Hypothèses!$C$25,Hypothèses!$D$25)))+(IF(B8=1,Hypothèses!$B$25,IF(B8=2,Hypothèses!$C$25,IF(B8=3,Hypothèses!$D$25,Hypothèses!$D$25)))-(IF(B8=1,0,IF(B8=2,Hypothèses!$B$25,IF(B8=3,Hypothèses!$C$25,Hypothèses!$D$25)))))*((A8)-INT((A8-1)/12)*12)/12)*$B$1 | G8: =(IF(B8=1,0,IF(B8=2,Hypothèses!$B$26,IF(B8=3,Hypothèses!$C$26,Hypothèses!$D$26)))+(IF(B8=1,Hypothèses!$B$26,IF(B8=2,Hypothèses!$C$26,IF(B8=3,Hypothèses!$D$26,Hypothèses!$D$26)))-(IF(B8=1,0,IF(B8=2,Hypothèses!$B$26,IF(B8=3,Hypothèses!$C$26,Hypothèses!$D$26)))))*((A8)-INT((A8-1)/12)*12)/12)*$B$1 | H8: =(IF(B8=1,0,IF(B8=2,Hypothèses!$B$27,IF(B8=3,Hypothèses!$C$27,Hypothèses!$D$27)))+(IF(B8=1,Hypothèses!$B$27,IF(B8=2,Hypothèses!$C$27,IF(B8=3,Hypothèses!$D$27,Hypothèses!$D$27)))-(IF(B8=1,0,IF(B8=2,Hypothèses!$B$27,IF(B8=3,Hypothèses!$C$27,Hypothèses!$D$27)))))*((A8)-INT((A8-1)/12)*12)/12)*$B$1 | I8: =IF(A8<Hypothèses!$B$7,0,Hypothèses!$B$8*(1-Hypothèses!$B$9)^(A8-Hypothèses!$B$7)) | J8: =C8+D8+E8 | K8: =(C8*Hypothèses!$B$11+D8*Hypothèses!$B$12+E8*Hypothèses!$B$13)*(IF(B8=1,Hypothèses!$B$19,IF(B8=2,Hypothèses!$B$20,Hypothèses!$B$21))+(1-(IF(B8=1,Hypothèses!$B$19,IF(B8=2,Hypothèses!$B$20,Hypothèses!$B$21))))*11/12) | L8: =J8*IF(B8=1,Hypothèses!$C$19,IF(B8=2,Hypothèses!$C$20,Hypothèses!$C$21))*IF(B8=1,Hypothèses!$D$19,IF(B8=2,Hypothèses!$D$20,Hypothèses!$D$21)) | M8: =IF(A8=18,IF($B$2>=1,Hypothèses!$B$31,0),IF(AND(OR(A8=30,A8=34),$D$2>=1),Hypothèses!$B$32*MIN(1,$D$2/3),0)) | N8: =K8+L8+M8 | O8: =N8/(1+Hypothèses!$B$6) | P8: =Hypothèses!$B$3*(1+Hypothèses!$B$4)^INT((A8-1)/3) | Q8: =0 | R8: =Q8*Hypothèses!$B$16 | S8: =O8*Hypothèses!$B$5 | T8: =O8-P8-R8-S8 | U8: =U7+T8
A9: 6 | B9: =INT((A9-1)/12)+1 | C9: =ROUND(IF(MOD($A9,12)=0,F9,(IF(9=4,0,C8))*(1-$I9)+IF((IF(9=4,0,C8))*(1-$I9)<F9,(F9-(IF(9=4,0,C8))*(1-$I9))*Hypothèses!$B$10,0)),1) | D9: =ROUND(IF(MOD($A9,12)=0,G9,(IF(9=4,0,D8))*(1-$I9)+IF((IF(9=4,0,D8))*(1-$I9)<G9,(G9-(IF(9=4,0,D8))*(1-$I9))*Hypothèses!$B$10,0)),1) | E9: =ROUND(IF(MOD($A9,12)=0,H9,(IF(9=4,0,E8))*(1-$I9)+IF((IF(9=4,0,E8))*(1-$I9)<H9,(H9-(IF(9=4,0,E8))*(1-$I9))*Hypothèses!$B$10,0)),1) | F9: =(IF(B9=1,0,IF(B9=2,Hypothèses!$B$25,IF(B9=3,Hypothèses!$C$25,Hypothèses!$D$25)))+(IF(B9=1,Hypothèses!$B$25,IF(B9=2,Hypothèses!$C$25,IF(B9=3,Hypothèses!$D$25,Hypothèses!$D$25)))-(IF(B9=1,0,IF(B9=2,Hypothèses!$B$25,IF(B9=3,Hypothèses!$C$25,Hypothèses!$D$25)))))*((A9)-INT((A9-1)/12)*12)/12)*$B$1 | G9: =(IF(B9=1,0,IF(B9=2,Hypothèses!$B$26,IF(B9=3,Hypothèses!$C$26,Hypothèses!$D$26)))+(IF(B9=1,Hypothèses!$B$26,IF(B9=2,Hypothèses!$C$26,IF(B9=3,Hypothèses!$D$26,Hypothèses!$D$26)))-(IF(B9=1,0,IF(B9=2,Hypothèses!$B$26,IF(B9=3,Hypothèses!$C$26,Hypothèses!$D$26)))))*((A9)-INT((A9-1)/12)*12)/12)*$B$1 | H9: =(IF(B9=1,0,IF(B9=2,Hypothèses!$B$27,IF(B9=3,Hypothèses!$C$27,Hypothèses!$D$27)))+(IF(B9=1,Hypothèses!$B$27,IF(B9=2,Hypothèses!$C$27,IF(B9=3,Hypothèses!$D$27,Hypothèses!$D$27)))-(IF(B9=1,0,IF(B9=2,Hypothèses!$B$27,IF(B9=3,Hypothèses!$C$27,Hypothèses!$D$27)))))*((A9)-INT((A9-1)/12)*12)/12)*$B$1 | I9: =IF(A9<Hypothèses!$B$7,0,Hypothèses!$B$8*(1-Hypothèses!$B$9)^(A9-Hypothèses!$B$7)) | J9: =C9+D9+E9 | K9: =(C9*Hypothèses!$B$11+D9*Hypothèses!$B$12+E9*Hypothèses!$B$13)*(IF(B9=1,Hypothèses!$B$19,IF(B9=2,Hypothèses!$B$20,Hypothèses!$B$21))+(1-(IF(B9=1,Hypothèses!$B$19,IF(B9=2,Hypothèses!$B$20,Hypothèses!$B$21))))*11/12) | L9: =J9*IF(B9=1,Hypothèses!$C$19,IF(B9=2,Hypothèses!$C$20,Hypothèses!$C$21))*IF(B9=1,Hypothèses!$D$19,IF(B9=2,Hypothèses!$D$20,Hypothèses!$D$21)) | M9: =IF(A9=18,IF($B$2>=1,Hypothèses!$B$31,0),IF(AND(OR(A9=30,A9=34),$D$2>=1),Hypothèses!$B$32*MIN(1,$D$2/3),0)) | N9: =K9+L9+M9 | O9: =N9/(1+Hypothèses!$B$6) | P9: =Hypothèses!$B$3*(1+Hypothèses!$B$4)^INT((A9-1)/3) | Q9: =0 | R9: =Q9*Hypothèses!$B$16 | S9: =O9*Hypothèses!$B$5 | T9: =O9-P9-R9-S9 | U9: =U8+T9
A10: 7 | B10: =INT((A10-1)/12)+1 | C10: =ROUND(IF(MOD($A10,12)=0,F10,(IF(10=4,0,C9))*(1-$I10)+IF((IF(10=4,0,C9))*(1-$I10)<F10,(F10-(IF(10=4,0,C9))*(1-$I10))*Hypothèses!$B$10,0)),1) | D10: =ROUND(IF(MOD($A10,12)=0,G10,(IF(10=4,0,D9))*(1-$I10)+IF((IF(10=4,0,D9))*(1-$I10)<G10,(G10-(IF(10=4,0,D9))*(1-$I10))*Hypothèses!$B$10,0)),1) | E10: =ROUND(IF(MOD($A10,12)=0,H10,(IF(10=4,0,E9))*(1-$I10)+IF((IF(10=4,0,E9))*(1-$I10)<H10,(H10-(IF(10=4,0,E9))*(1-$I10))*Hypothèses!$B$10,0)),1) | F10: =(IF(B10=1,0,IF(B10=2,Hypothèses!$B$25,IF(B10=3,Hypothèses!$C$25,Hypothèses!$D$25)))+(IF(B10=1,Hypothèses!$B$25,IF(B10=2,Hypothèses!$C$25,IF(B10=3,Hypothèses!$D$25,Hypothèses!$D$25)))-(IF(B10=1,0,IF(B10=2,Hypothèses!$B$25,IF(B10=3,Hypothèses!$C$25,Hypothèses!$D$25)))))*((A10)-INT((A10-1)/12)*12)/12)*$B$1 | G10: =(IF(B10=1,0,IF(B10=2,Hypothèses!$B$26,IF(B10=3,Hypothèses!$C$26,Hypothèses!$D$26)))+(IF(B10=1,Hypothèses!$B$26,IF(B10=2,Hypothèses!$C$26,IF(B10=3,Hypothèses!$D$26,Hypothèses!$D$26)))-(IF(B10=1,0,IF(B10=2,Hypothèses!$B$26,IF(B10=3,Hypothèses!$C$26,Hypothèses!$D$26)))))*((A10)-INT((A10-1)/12)*12)/12)*$B$1 | H10: =(IF(B10=1,0,IF(B10=2,Hypothèses!$B$27,IF(B10=3,Hypothèses!$C$27,Hypothèses!$D$27)))+(IF(B10=1,Hypothèses!$B$27,IF(B10=2,Hypothèses!$C$27,IF(B10=3,Hypothèses!$D$27,Hypothèses!$D$27)))-(IF(B10=1,0,IF(B10=2,Hypothèses!$B$27,IF(B10=3,Hypothèses!$C$27,Hypothèses!$D$27)))))*((A10)-INT((A10-1)/12)*12)/12)*$B$1 | I10: =IF(A10<Hypothèses!$B$7,0,Hypothèses!$B$8*(1-Hypothèses!$B$9)^(A10-Hypothèses!$B$7)) | J10: =C10+D10+E10 | K10: =(C10*Hypothèses!$B$11+D10*Hypothèses!$B$12+E10*Hypothèses!$B$13)*(IF(B10=1,Hypothèses!$B$19,IF(B10=2,Hypothèses!$B$20,Hypothèses!$B$21))+(1-(IF(B10=1,Hypothèses!$B$19,IF(B10=2,Hypothèses!$B$20,Hypothèses!$B$21))))*11/12) | L10: =J10*IF(B10=1,Hypothèses!$C$19,IF(B10=2,Hypothèses!$C$20,Hypothèses!$C$21))*IF(B10=1,Hypothèses!$D$19,IF(B10=2,Hypothèses!$D$20,Hypothèses!$D$21)) | M10: =IF(A10=18,IF($B$2>=1,Hypothèses!$B$31,0),IF(AND(OR(A10=30,A10=34),$D$2>=1),Hypothèses!$B$32*MIN(1,$D$2/3),0)) | N10: =K10+L10+M10 | O10: =N10/(1+Hypothèses!$B$6) | P10: =Hypothèses!$B$3*(1+Hypothèses!$B$4)^INT((A10-1)/3) | Q10: =0 | R10: =Q10*Hypothèses!$B$16 | S10: =O10*Hypothèses!$B$5 | T10: =O10-P10-R10-S10 | U10: =U9+T10
A11: 8 | B11: =INT((A11-1)/12)+1 | C11: =ROUND(IF(MOD($A11,12)=0,F11,(IF(11=4,0,C10))*(1-$I11)+IF((IF(11=4,0,C10))*(1-$I11)<F11,(F11-(IF(11=4,0,C10))*(1-$I11))*Hypothèses!$B$10,0)),1) | D11: =ROUND(IF(MOD($A11,12)=0,G11,(IF(11=4,0,D10))*(1-$I11)+IF((IF(11=4,0,D10))*(1-$I11)<G11,(G11-(IF(11=4,0,D10))*(1-$I11))*Hypothèses!$B$10,0)),1) | E11: =ROUND(IF(MOD($A11,12)=0,H11,(IF(11=4,0,E10))*(1-$I11)+IF((IF(11=4,0,E10))*(1-$I11)<H11,(H11-(IF(11=4,0,E10))*(1-$I11))*Hypothèses!$B$10,0)),1) | F11: =(IF(B11=1,0,IF(B11=2,Hypothèses!$B$25,IF(B11=3,Hypothèses!$C$25,Hypothèses!$D$25)))+(IF(B11=1,Hypothèses!$B$25,IF(B11=2,Hypothèses!$C$25,IF(B11=3,Hypothèses!$D$25,Hypothèses!$D$25)))-(IF(B11=1,0,IF(B11=2,Hypothèses!$B$25,IF(B11=3,Hypothèses!$C$25,Hypothèses!$D$25)))))*((A11)-INT((A11-1)/12)*12)/12)*$B$1 | G11: =(IF(B11=1,0,IF(B11=2,Hypothèses!$B$26,IF(B11=3,Hypothèses!$C$26,Hypothèses!$D$26)))+(IF(B11=1,Hypothèses!$B$26,IF(B11=2,Hypothèses!$C$26,IF(B11=3,Hypothèses!$D$26,Hypothèses!$D$26)))-(IF(B11=1,0,IF(B11=2,Hypothèses!$B$26,IF(B11=3,Hypothèses!$C$26,Hypothèses!$D$26)))))*((A11)-INT((A11-1)/12)*12)/12)*$B$1 | H11: =(IF(B11=1,0,IF(B11=2,Hypothèses!$B$27,IF(B11=3,Hypothèses!$C$27,Hypothèses!$D$27)))+(IF(B11=1,Hypothèses!$B$27,IF(B11=2,Hypothèses!$C$27,IF(B11=3,Hypothèses!$D$27,Hypothèses!$D$27)))-(IF(B11=1,0,IF(B11=2,Hypothèses!$B$27,IF(B11=3,Hypothèses!$C$27,Hypothèses!$D$27)))))*((A11)-INT((A11-1)/12)*12)/12)*$B$1 | I11: =IF(A11<Hypothèses!$B$7,0,Hypothèses!$B$8*(1-Hypothèses!$B$9)^(A11-Hypothèses!$B$7)) | J11: =C11+D11+E11 | K11: =(C11*Hypothèses!$B$11+D11*Hypothèses!$B$12+E11*Hypothèses!$B$13)*(IF(B11=1,Hypothèses!$B$19,IF(B11=2,Hypothèses!$B$20,Hypothèses!$B$21))+(1-(IF(B11=1,Hypothèses!$B$19,IF(B11=2,Hypothèses!$B$20,Hypothèses!$B$21))))*11/12) | L11: =J11*IF(B11=1,Hypothèses!$C$19,IF(B11=2,Hypothèses!$C$20,Hypothèses!$C$21))*IF(B11=1,Hypothèses!$D$19,IF(B11=2,Hypothèses!$D$20,Hypothèses!$D$21)) | M11: =IF(A11=18,IF($B$2>=1,Hypothèses!$B$31,0),IF(AND(OR(A11=30,A11=34),$D$2>=1),Hypothèses!$B$32*MIN(1,$D$2/3),0)) | N11: =K11+L11+M11 | O11: =N11/(1+Hypothèses!$B$6) | P11: =Hypothèses!$B$3*(1+Hypothèses!$B$4)^INT((A11-1)/3) | Q11: =0 | R11: =Q11*Hypothèses!$B$16 | S11: =O11*Hypothèses!$B$5 | T11: =O11-P11-R11-S11 | U11: =U10+T11
A12: 9 | B12: =INT((A12-1)/12)+1 | C12: =ROUND(IF(MOD($A12,12)=0,F12,(IF(12=4,0,C11))*(1-$I12)+IF((IF(12=4,0,C11))*(1-$I12)<F12,(F12-(IF(12=4,0,C11))*(1-$I12))*Hypothèses!$B$10,0)),1) | D12: =ROUND(IF(MOD($A12,12)=0,G12,(IF(12=4,0,D11))*(1-$I12)+IF((IF(12=4,0,D11))*(1-$I12)<G12,(G12-(IF(12=4,0,D11))*(1-$I12))*Hypothèses!$B$10,0)),1) | E12: =ROUND(IF(MOD($A12,12)=0,H12,(IF(12=4,0,E11))*(1-$I12)+IF((IF(12=4,0,E11))*(1-$I12)<H12,(H12-(IF(12=4,0,E11))*(1-$I12))*Hypothèses!$B$10,0)),1) | F12: =(IF(B12=1,0,IF(B12=2,Hypothèses!$B$25,IF(B12=3,Hypothèses!$C$25,Hypothèses!$D$25)))+(IF(B12=1,Hypothèses!$B$25,IF(B12=2,Hypothèses!$C$25,IF(B12=3,Hypothèses!$D$25,Hypothèses!$D$25)))-(IF(B12=1,0,IF(B12=2,Hypothèses!$B$25,IF(B12=3,Hypothèses!$C$25,Hypothèses!$D$25)))))*((A12)-INT((A12-1)/12)*12)/12)*$B$1 | G12: =(IF(B12=1,0,IF(B12=2,Hypothèses!$B$26,IF(B12=3,Hypothèses!$C$26,Hypothèses!$D$26)))+(IF(B12=1,Hypothèses!$B$26,IF(B12=2,Hypothèses!$C$26,IF(B12=3,Hypothèses!$D$26,Hypothèses!$D$26)))-(IF(B12=1,0,IF(B12=2,Hypothèses!$B$26,IF(B12=3,Hypothèses!$C$26,Hypothèses!$D$26)))))*((A12)-INT((A12-1)/12)*12)/12)*$B$1 | H12: =(IF(B12=1,0,IF(B12=2,Hypothèses!$B$27,IF(B12=3,Hypothèses!$C$27,Hypothèses!$D$27)))+(IF(B12=1,Hypothèses!$B$27,IF(B12=2,Hypothèses!$C$27,IF(B12=3,Hypothèses!$D$27,Hypothèses!$D$27)))-(IF(B12=1,0,IF(B12=2,Hypothèses!$B$27,IF(B12=3,Hypothèses!$C$27,Hypothèses!$D$27)))))*((A12)-INT((A12-1)/12)*12)/12)*$B$1 | I12: =IF(A12<Hypothèses!$B$7,0,Hypothèses!$B$8*(1-Hypothèses!$B$9)^(A12-Hypothèses!$B$7)) | J12: =C12+D12+E12 | K12: =(C12*Hypothèses!$B$11+D12*Hypothèses!$B$12+E12*Hypothèses!$B$13)*(IF(B12=1,Hypothèses!$B$19,IF(B12=2,Hypothèses!$B$20,Hypothèses!$B$21))+(1-(IF(B12=1,Hypothèses!$B$19,IF(B12=2,Hypothèses!$B$20,Hypothèses!$B$21))))*11/12) | L12: =J12*IF(B12=1,Hypothèses!$C$19,IF(B12=2,Hypothèses!$C$20,Hypothèses!$C$21))*IF(B12=1,Hypothèses!$D$19,IF(B12=2,Hypothèses!$D$20,Hypothèses!$D$21)) | M12: =IF(A12=18,IF($B$2>=1,Hypothèses!$B$31,0),IF(AND(OR(A12=30,A12=34),$D$2>=1),Hypothèses!$B$32*MIN(1,$D$2/3),0)) | N12: =K12+L12+M12 | O12: =N12/(1+Hypothèses!$B$6) | P12: =Hypothèses!$B$3*(1+Hypothèses!$B$4)^INT((A12-1)/3) | Q12: =0 | R12: =Q12*Hypothèses!$B$16 | S12: =O12*Hypothèses!$B$5 | T12: =O12-P12-R12-S12 | U12: =U11+T12
A13: 10 | B13: =INT((A13-1)/12)+1 | C13: =ROUND(IF(MOD($A13,12)=0,F13,(IF(13=4,0,C12))*(1-$I13)+IF((IF(13=4,0,C12))*(1-$I13)<F13,(F13-(IF(13=4,0,C12))*(1-$I13))*Hypothèses!$B$10,0)),1) | D13: =ROUND(IF(MOD($A13,12)=0,G13,(IF(13=4,0,D12))*(1-$I13)+IF((IF(13=4,0,D12))*(1-$I13)<G13,(G13-(IF(13=4,0,D12))*(1-$I13))*Hypothèses!$B$10,0)),1) | E13: =ROUND(IF(MOD($A13,12)=0,H13,(IF(13=4,0,E12))*(1-$I13)+IF((IF(13=4,0,E12))*(1-$I13)<H13,(H13-(IF(13=4,0,E12))*(1-$I13))*Hypothèses!$B$10,0)),1) | F13: =(IF(B13=1,0,IF(B13=2,Hypothèses!$B$25,IF(B13=3,Hypothèses!$C$25,Hypothèses!$D$25)))+(IF(B13=1,Hypothèses!$B$25,IF(B13=2,Hypothèses!$C$25,IF(B13=3,Hypothèses!$D$25,Hypothèses!$D$25)))-(IF(B13=1,0,IF(B13=2,Hypothèses!$B$25,IF(B13=3,Hypothèses!$C$25,Hypothèses!$D$25)))))*((A13)-INT((A13-1)/12)*12)/12)*$B$1 | G13: =(IF(B13=1,0,IF(B13=2,Hypothèses!$B$26,IF(B13=3,Hypothèses!$C$26,Hypothèses!$D$26)))+(IF(B13=1,Hypothèses!$B$26,IF(B13=2,Hypothèses!$C$26,IF(B13=3,Hypothèses!$D$26,Hypothèses!$D$26)))-(IF(B13=1,0,IF(B13=2,Hypothèses!$B$26,IF(B13=3,Hypothèses!$C$26,Hypothèses!$D$26)))))*((A13)-INT((A13-1)/12)*12)/12)*$B$1 | H13: =(IF(B13=1,0,IF(B13=2,Hypothèses!$B$27,IF(B13=3,Hypothèses!$C$27,Hypothèses!$D$27)))+(IF(B13=1,Hypothèses!$B$27,IF(B13=2,Hypothèses!$C$27,IF(B13=3,Hypothèses!$D$27,Hypothèses!$D$27)))-(IF(B13=1,0,IF(B13=2,Hypothèses!$B$27,IF(B13=3,Hypothèses!$C$27,Hypothèses!$D$27)))))*((A13)-INT((A13-1)/12)*12)/12)*$B$1 | I13: =IF(A13<Hypothèses!$B$7,0,Hypothèses!$B$8*(1-Hypothèses!$B$9)^(A13-Hypothèses!$B$7)) | J13: =C13+D13+E13 | K13: =(C13*Hypothèses!$B$11+D13*Hypothèses!$B$12+E13*Hypothèses!$B$13)*(IF(B13=1,Hypothèses!$B$19,IF(B13=2,Hypothèses!$B$20,Hypothèses!$B$21))+(1-(IF(B13=1,Hypothèses!$B$19,IF(B13=2,Hypothèses!$B$20,Hypothèses!$B$21))))*11/12) | L13: =J13*IF(B13=1,Hypothèses!$C$19,IF(B13=2,Hypothèses!$C$20,Hypothèses!$C$21))*IF(B13=1,Hypothèses!$D$19,IF(B13=2,Hypothèses!$D$20,Hypothèses!$D$21)) | M13: =IF(A13=18,IF($B$2>=1,Hypothèses!$B$31,0),IF(AND(OR(A13=30,A13=34),$D$2>=1),Hypothèses!$B$32*MIN(1,$D$2/3),0)) | N13: =K13+L13+M13 | O13: =N13/(1+Hypothèses!$B$6) | P13: =Hypothèses!$B$3*(1+Hypothèses!$B$4)^INT((A13-1)/3) | Q13: =0 | R13: =Q13*Hypothèses!$B$16 | S13: =O13*Hypothèses!$B$5 | T13: =O13-P13-R13-S13 | U13: =U12+T13
A14: 11 | B14: =INT((A14-1)/12)+1 | C14: =ROUND(IF(MOD($A14,12)=0,F14,(IF(14=4,0,C13))*(1-$I14)+IF((IF(14=4,0,C13))*(1-$I14)<F14,(F14-(IF(14=4,0,C13))*(1-$I14))*Hypothèses!$B$10,0)),1) | D14: =ROUND(IF(MOD($A14,12)=0,G14,(IF(14=4,0,D13))*(1-$I14)+IF((IF(14=4,0,D13))*(1-$I14)<G14,(G14-(IF(14=4,0,D13))*(1-$I14))*Hypothèses!$B$10,0)),1) | E14: =ROUND(IF(MOD($A14,12)=0,H14,(IF(14=4,0,E13))*(1-$I14)+IF((IF(14=4,0,E13))*(1-$I14)<H14,(H14-(IF(14=4,0,E13))*(1-$I14))*Hypothèses!$B$10,0)),1) | F14: =(IF(B14=1,0,IF(B14=2,Hypothèses!$B$25,IF(B14=3,Hypothèses!$C$25,Hypothèses!$D$25)))+(IF(B14=1,Hypothèses!$B$25,IF(B14=2,Hypothèses!$C$25,IF(B14=3,Hypothèses!$D$25,Hypothèses!$D$25)))-(IF(B14=1,0,IF(B14=2,Hypothèses!$B$25,IF(B14=3,Hypothèses!$C$25,Hypothèses!$D$25)))))*((A14)-INT((A14-1)/12)*12)/12)*$B$1 | G14: =(IF(B14=1,0,IF(B14=2,Hypothèses!$B$26,IF(B14=3,Hypothèses!$C$26,Hypothèses!$D$26)))+(IF(B14=1,Hypothèses!$B$26,IF(B14=2,Hypothèses!$C$26,IF(B14=3,Hypothèses!$D$26,Hypothèses!$D$26)))-(IF(B14=1,0,IF(B14=2,Hypothèses!$B$26,IF(B14=3,Hypothèses!$C$26,Hypothèses!$D$26)))))*((A14)-INT((A14-1)/12)*12)/12)*$B$1 | H14: =(IF(B14=1,0,IF(B14=2,Hypothèses!$B$27,IF(B14=3,Hypothèses!$C$27,Hypothèses!$D$27)))+(IF(B14=1,Hypothèses!$B$27,IF(B14=2,Hypothèses!$C$27,IF(B14=3,Hypothèses!$D$27,Hypothèses!$D$27)))-(IF(B14=1,0,IF(B14=2,Hypothèses!$B$27,IF(B14=3,Hypothèses!$C$27,Hypothèses!$D$27)))))*((A14)-INT((A14-1)/12)*12)/12)*$B$1 | I14: =IF(A14<Hypothèses!$B$7,0,Hypothèses!$B$8*(1-Hypothèses!$B$9)^(A14-Hypothèses!$B$7)) | J14: =C14+D14+E14 | K14: =(C14*Hypothèses!$B$11+D14*Hypothèses!$B$12+E14*Hypothèses!$B$13)*(IF(B14=1,Hypothèses!$B$19,IF(B14=2,Hypothèses!$B$20,Hypothèses!$B$21))+(1-(IF(B14=1,Hypothèses!$B$19,IF(B14=2,Hypothèses!$B$20,Hypothèses!$B$21))))*11/12) | L14: =J14*IF(B14=1,Hypothèses!$C$19,IF(B14=2,Hypothèses!$C$20,Hypothèses!$C$21))*IF(B14=1,Hypothèses!$D$19,IF(B14=2,Hypothèses!$D$20,Hypothèses!$D$21)) | M14: =IF(A14=18,IF($B$2>=1,Hypothèses!$B$31,0),IF(AND(OR(A14=30,A14=34),$D$2>=1),Hypothèses!$B$32*MIN(1,$D$2/3),0)) | N14: =K14+L14+M14 | O14: =N14/(1+Hypothèses!$B$6) | P14: =Hypothèses!$B$3*(1+Hypothèses!$B$4)^INT((A14-1)/3) | Q14: =0 | R14: =Q14*Hypothèses!$B$16 | S14: =O14*Hypothèses!$B$5 | T14: =O14-P14-R14-S14 | U14: =U13+T14
A15: 12 | B15: =INT((A15-1)/12)+1 | C15: =ROUND(IF(MOD($A15,12)=0,F15,(IF(15=4,0,C14))*(1-$I15)+IF((IF(15=4,0,C14))*(1-$I15)<F15,(F15-(IF(15=4,0,C14))*(1-$I15))*Hypothèses!$B$10,0)),1) | D15: =ROUND(IF(MOD($A15,12)=0,G15,(IF(15=4,0,D14))*(1-$I15)+IF((IF(15=4,0,D14))*(1-$I15)<G15,(G15-(IF(15=4,0,D14))*(1-$I15))*Hypothèses!$B$10,0)),1) | E15: =ROUND(IF(MOD($A15,12)=0,H15,(IF(15=4,0,E14))*(1-$I15)+IF((IF(15=4,0,E14))*(1-$I15)<H15,(H15-(IF(15=4,0,E14))*(1-$I15))*Hypothèses!$B$10,0)),1) | F15: =(IF(B15=1,0,IF(B15=2,Hypothèses!$B$25,IF(B15=3,Hypothèses!$C$25,Hypothèses!$D$25)))+(IF(B15=1,Hypothèses!$B$25,IF(B15=2,Hypothèses!$C$25,IF(B15=3,Hypothèses!$D$25,Hypothèses!$D$25)))-(IF(B15=1,0,IF(B15=2,Hypothèses!$B$25,IF(B15=3,Hypothèses!$C$25,Hypothèses!$D$25)))))*((A15)-INT((A15-1)/12)*12)/12)*$B$1 | G15: =(IF(B15=1,0,IF(B15=2,Hypothèses!$B$26,IF(B15=3,Hypothèses!$C$26,Hypothèses!$D$26)))+(IF(B15=1,Hypothèses!$B$26,IF(B15=2,Hypothèses!$C$26,IF(B15=3,Hypothèses!$D$26,Hypothèses!$D$26)))-(IF(B15=1,0,IF(B15=2,Hypothèses!$B$26,IF(B15=3,Hypothèses!$C$26,Hypothèses!$D$26)))))*((A15)-INT((A15-1)/12)*12)/12)*$B$1 | H15: =(IF(B15=1,0,IF(B15=2,Hypothèses!$B$27,IF(B15=3,Hypothèses!$C$27,Hypothèses!$D$27)))+(IF(B15=1,Hypothèses!$B$27,IF(B15=2,Hypothèses!$C$27,IF(B15=3,Hypothèses!$D$27,Hypothèses!$D$27)))-(IF(B15=1,0,IF(B15=2,Hypothèses!$B$27,IF(B15=3,Hypothèses!$C$27,Hypothèses!$D$27)))))*((A15)-INT((A15-1)/12)*12)/12)*$B$1 | I15: =IF(A15<Hypothèses!$B$7,0,Hypothèses!$B$8*(1-Hypothèses!$B$9)^(A15-Hypothèses!$B$7)) | J15: =C15+D15+E15 | K15: =(C15*Hypothèses!$B$11+D15*Hypothèses!$B$12+E15*Hypothèses!$B$13)*(IF(B15=1,Hypothèses!$B$19,IF(B15=2,Hypothèses!$B$20,Hypothèses!$B$21))+(1-(IF(B15=1,Hypothèses!$B$19,IF(B15=2,Hypothèses!$B$20,Hypothèses!$B$21))))*11/12) | L15: =J15*IF(B15=1,Hypothèses!$C$19,IF(B15=2,Hypothèses!$C$20,Hypothèses!$C$21))*IF(B15=1,Hypothèses!$D$19,IF(B15=2,Hypothèses!$D$20,Hypothèses!$D$21)) | M15: =IF(A15=18,IF($B$2>=1,Hypothèses!$B$31,0),IF(AND(OR(A15=30,A15=34),$D$2>=1),Hypothèses!$B$32*MIN(1,$D$2/3),0)) | N15: =K15+L15+M15 | O15: =N15/(1+Hypothèses!$B$6) | P15: =Hypothèses!$B$3*(1+Hypothèses!$B$4)^INT((A15-1)/3) | Q15: =0 | R15: =Q15*Hypothèses!$B$16 | S15: =O15*Hypothèses!$B$5 | T15: =O15-P15-R15-S15 | U15: =U14+T15
A16: 13 | B16: =INT((A16-1)/12)+1 | C16: =ROUND(IF(MOD($A16,12)=0,F16,(IF(16=4,0,C15))*(1-$I16)+IF((IF(16=4,0,C15))*(1-$I16)<F16,(F16-(IF(16=4,0,C15))*(1-$I16))*Hypothèses!$B$10,0)),1) | D16: =ROUND(IF(MOD($A16,12)=0,G16,(IF(16=4,0,D15))*(1-$I16)+IF((IF(16=4,0,D15))*(1-$I16)<G16,(G16-(IF(16=4,0,D15))*(1-$I16))*Hypothèses!$B$10,0)),1) | E16: =ROUND(IF(MOD($A16,12)=0,H16,(IF(16=4,0,E15))*(1-$I16)+IF((IF(16=4,0,E15))*(1-$I16)<H16,(H16-(IF(16=4,0,E15))*(1-$I16))*Hypothèses!$B$10,0)),1) | F16: =(IF(B16=1,0,IF(B16=2,Hypothèses!$B$25,IF(B16=3,Hypothèses!$C$25,Hypothèses!$D$25)))+(IF(B16=1,Hypothèses!$B$25,IF(B16=2,Hypothèses!$C$25,IF(B16=3,Hypothèses!$D$25,Hypothèses!$D$25)))-(IF(B16=1,0,IF(B16=2,Hypothèses!$B$25,IF(B16=3,Hypothèses!$C$25,Hypothèses!$D$25)))))*((A16)-INT((A16-1)/12)*12)/12)*$B$1 | G16: =(IF(B16=1,0,IF(B16=2,Hypothèses!$B$26,IF(B16=3,Hypothèses!$C$26,Hypothèses!$D$26)))+(IF(B16=1,Hypothèses!$B$26,IF(B16=2,Hypothèses!$C$26,IF(B16=3,Hypothèses!$D$26,Hypothèses!$D$26)))-(IF(B16=1,0,IF(B16=2,Hypothèses!$B$26,IF(B16=3,Hypothèses!$C$26,Hypothèses!$D$26)))))*((A16)-INT((A16-1)/12)*12)/12)*$B$1 | H16: =(IF(B16=1,0,IF(B16=2,Hypothèses!$B$27,IF(B16=3,Hypothèses!$C$27,Hypothèses!$D$27)))+(IF(B16=1,Hypothèses!$B$27,IF(B16=2,Hypothèses!$C$27,IF(B16=3,Hypothèses!$D$27,Hypothèses!$D$27)))-(IF(B16=1,0,IF(B16=2,Hypothèses!$B$27,IF(B16=3,Hypothèses!$C$27,Hypothèses!$D$27)))))*((A16)-INT((A16-1)/12)*12)/12)*$B$1 | I16: =IF(A16<Hypothèses!$B$7,0,Hypothèses!$B$8*(1-Hypothèses!$B$9)^(A16-Hypothèses!$B$7)) | J16: =C16+D16+E16 | K16: =(C16*Hypothèses!$B$11+D16*Hypothèses!$B$12+E16*Hypothèses!$B$13)*(IF(B16=1,Hypothèses!$B$19,IF(B16=2,Hypothèses!$B$20,Hypothèses!$B$21))+(1-(IF(B16=1,Hypothèses!$B$19,IF(B16=2,Hypothèses!$B$20,Hypothèses!$B$21))))*11/12) | L16: =J16*IF(B16=1,Hypothèses!$C$19,IF(B16=2,Hypothèses!$C$20,Hypothèses!$C$21))*IF(B16=1,Hypothèses!$D$19,IF(B16=2,Hypothèses!$D$20,Hypothèses!$D$21)) | M16: =IF(A16=18,IF($B$2>=1,Hypothèses!$B$31,0),IF(AND(OR(A16=30,A16=34),$D$2>=1),Hypothèses!$B$32*MIN(1,$D$2/3),0)) | N16: =K16+L16+M16 | O16: =N16/(1+Hypothèses!$B$6) | P16: =Hypothèses!$B$3*(1+Hypothèses!$B$4)^INT((A16-1)/3) | Q16: =0 | R16: =Q16*Hypothèses!$B$16 | S16: =O16*Hypothèses!$B$5 | T16: =O16-P16-R16-S16 | U16: =U15+T16
A17: 14 | B17: =INT((A17-1)/12)+1 | C17: =ROUND(IF(MOD($A17,12)=0,F17,(IF(17=4,0,C16))*(1-$I17)+IF((IF(17=4,0,C16))*(1-$I17)<F17,(F17-(IF(17=4,0,C16))*(1-$I17))*Hypothèses!$B$10,0)),1) | D17: =ROUND(IF(MOD($A17,12)=0,G17,(IF(17=4,0,D16))*(1-$I17)+IF((IF(17=4,0,D16))*(1-$I17)<G17,(G17-(IF(17=4,0,D16))*(1-$I17))*Hypothèses!$B$10,0)),1) | E17: =ROUND(IF(MOD($A17,12)=0,H17,(IF(17=4,0,E16))*(1-$I17)+IF((IF(17=4,0,E16))*(1-$I17)<H17,(H17-(IF(17=4,0,E16))*(1-$I17))*Hypothèses!$B$10,0)),1) | F17: =(IF(B17=1,0,IF(B17=2,Hypothèses!$B$25,IF(B17=3,Hypothèses!$C$25,Hypothèses!$D$25)))+(IF(B17=1,Hypothèses!$B$25,IF(B17=2,Hypothèses!$C$25,IF(B17=3,Hypothèses!$D$25,Hypothèses!$D$25)))-(IF(B17=1,0,IF(B17=2,Hypothèses!$B$25,IF(B17=3,Hypothèses!$C$25,Hypothèses!$D$25)))))*((A17)-INT((A17-1)/12)*12)/12)*$B$1 | G17: =(IF(B17=1,0,IF(B17=2,Hypothèses!$B$26,IF(B17=3,Hypothèses!$C$26,Hypothèses!$D$26)))+(IF(B17=1,Hypothèses!$B$26,IF(B17=2,Hypothèses!$C$26,IF(B17=3,Hypothèses!$D$26,Hypothèses!$D$26)))-(IF(B17=1,0,IF(B17=2,Hypothèses!$B$26,IF(B17=3,Hypothèses!$C$26,Hypothèses!$D$26)))))*((A17)-INT((A17-1)/12)*12)/12)*$B$1 | H17: =(IF(B17=1,0,IF(B17=2,Hypothèses!$B$27,IF(B17=3,Hypothèses!$C$27,Hypothèses!$D$27)))+(IF(B17=1,Hypothèses!$B$27,IF(B17=2,Hypothèses!$C$27,IF(B17=3,Hypothèses!$D$27,Hypothèses!$D$27)))-(IF(B17=1,0,IF(B17=2,Hypothèses!$B$27,IF(B17=3,Hypothèses!$C$27,Hypothèses!$D$27)))))*((A17)-INT((A17-1)/12)*12)/12)*$B$1 | I17: =IF(A17<Hypothèses!$B$7,0,Hypothèses!$B$8*(1-Hypothèses!$B$9)^(A17-Hypothèses!$B$7)) | J17: =C17+D17+E17 | K17: =(C17*Hypothèses!$B$11+D17*Hypothèses!$B$12+E17*Hypothèses!$B$13)*(IF(B17=1,Hypothèses!$B$19,IF(B17=2,Hypothèses!$B$20,Hypothèses!$B$21))+(1-(IF(B17=1,Hypothèses!$B$19,IF(B17=2,Hypothèses!$B$20,Hypothèses!$B$21))))*11/12) | L17: =J17*IF(B17=1,Hypothèses!$C$19,IF(B17=2,Hypothèses!$C$20,Hypothèses!$C$21))*IF(B17=1,Hypothèses!$D$19,IF(B17=2,Hypothèses!$D$20,Hypothèses!$D$21)) | M17: =IF(A17=18,IF($B$2>=1,Hypothèses!$B$31,0),IF(AND(OR(A17=30,A17=34),$D$2>=1),Hypothèses!$B$32*MIN(1,$D$2/3),0)) | N17: =K17+L17+M17 | O17: =N17/(1+Hypothèses!$B$6) | P17: =Hypothèses!$B$3*(1+Hypothèses!$B$4)^INT((A17-1)/3) | Q17: =0 | R17: =Q17*Hypothèses!$B$16 | S17: =O17*Hypothèses!$B$5 | T17: =O17-P17-R17-S17 | U17: =U16+T17
A18: 15 | B18: =INT((A18-1)/12)+1 | C18: =ROUND(IF(MOD($A18,12)=0,F18,(IF(18=4,0,C17))*(1-$I18)+IF((IF(18=4,0,C17))*(1-$I18)<F18,(F18-(IF(18=4,0,C17))*(1-$I18))*Hypothèses!$B$10,0)),1) | D18: =ROUND(IF(MOD($A18,12)=0,G18,(IF(18=4,0,D17))*(1-$I18)+IF((IF(18=4,0,D17))*(1-$I18)<G18,(G18-(IF(18=4,0,D17))*(1-$I18))*Hypothèses!$B$10,0)),1) | E18: =ROUND(IF(MOD($A18,12)=0,H18,(IF(18=4,0,E17))*(1-$I18)+IF((IF(18=4,0,E17))*(1-$I18)<H18,(H18-(IF(18=4,0,E17))*(1-$I18))*Hypothèses!$B$10,0)),1) | F18: =(IF(B18=1,0,IF(B18=2,Hypothèses!$B$25,IF(B18=3,Hypothèses!$C$25,Hypothèses!$D$25)))+(IF(B18=1,Hypothèses!$B$25,IF(B18=2,Hypothèses!$C$25,IF(B18=3,Hypothèses!$D$25,Hypothèses!$D$25)))-(IF(B18=1,0,IF(B18=2,Hypothèses!$B$25,IF(B18=3,Hypothèses!$C$25,Hypothèses!$D$25)))))*((A18)-INT((A18-1)/12)*12)/12)*$B$1 | G18: =(IF(B18=1,0,IF(B18=2,Hypothèses!$B$26,IF(B18=3,Hypothèses!$C$26,Hypothèses!$D$26)))+(IF(B18=1,Hypothèses!$B$26,IF(B18=2,Hypothèses!$C$26,IF(B18=3,Hypothèses!$D$26,Hypothèses!$D$26)))-(IF(B18=1,0,IF(B18=2,Hypothèses!$B$26,IF(B18=3,Hypothèses!$C$26,Hypothèses!$D$26)))))*((A18)-INT((A18-1)/12)*12)/12)*$B$1 | H18: =(IF(B18=1,0,IF(B18=2,Hypothèses!$B$27,IF(B18=3,Hypothèses!$C$27,Hypothèses!$D$27)))+(IF(B18=1,Hypothèses!$B$27,IF(B18=2,Hypothèses!$C$27,IF(B18=3,Hypothèses!$D$27,Hypothèses!$D$27)))-(IF(B18=1,0,IF(B18=2,Hypothèses!$B$27,IF(B18=3,Hypothèses!$C$27,Hypothèses!$D$27)))))*((A18)-INT((A18-1)/12)*12)/12)*$B$1 | I18: =IF(A18<Hypothèses!$B$7,0,Hypothèses!$B$8*(1-Hypothèses!$B$9)^(A18-Hypothèses!$B$7)) | J18: =C18+D18+E18 | K18: =(C18*Hypothèses!$B$11+D18*Hypothèses!$B$12+E18*Hypothèses!$B$13)*(IF(B18=1,Hypothèses!$B$19,IF(B18=2,Hypothèses!$B$20,Hypothèses!$B$21))+(1-(IF(B18=1,Hypothèses!$B$19,IF(B18=2,Hypothèses!$B$20,Hypothèses!$B$21))))*11/12) | L18: =J18*IF(B18=1,Hypothèses!$C$19,IF(B18=2,Hypothèses!$C$20,Hypothèses!$C$21))*IF(B18=1,Hypothèses!$D$19,IF(B18=2,Hypothèses!$D$20,Hypothèses!$D$21)) | M18: =IF(A18=18,IF($B$2>=1,Hypothèses!$B$31,0),IF(AND(OR(A18=30,A18=34),$D$2>=1),Hypothèses!$B$32*MIN(1,$D$2/3),0)) | N18: =K18+L18+M18 | O18: =N18/(1+Hypothèses!$B$6) | P18: =Hypothèses!$B$3*(1+Hypothèses!$B$4)^INT((A18-1)/3) | Q18: =0 | R18: =Q18*Hypothèses!$B$16 | S18: =O18*Hypothèses!$B$5 | T18: =O18-P18-R18-S18 | U18: =U17+T18
A19: 16 | B19: =INT((A19-1)/12)+1 | C19: =ROUND(IF(MOD($A19,12)=0,F19,(IF(19=4,0,C18))*(1-$I19)+IF((IF(19=4,0,C18))*(1-$I19)<F19,(F19-(IF(19=4,0,C18))*(1-$I19))*Hypothèses!$B$10,0)),1) | D19: =ROUND(IF(MOD($A19,12)=0,G19,(IF(19=4,0,D18))*(1-$I19)+IF((IF(19=4,0,D18))*(1-$I19)<G19,(G19-(IF(19=4,0,D18))*(1-$I19))*Hypothèses!$B$10,0)),1) | E19: =ROUND(IF(MOD($A19,12)=0,H19,(IF(19=4,0,E18))*(1-$I19)+IF((IF(19=4,0,E18))*(1-$I19)<H19,(H19-(IF(19=4,0,E18))*(1-$I19))*Hypothèses!$B$10,0)),1) | F19: =(IF(B19=1,0,IF(B19=2,Hypothèses!$B$25,IF(B19=3,Hypothèses!$C$25,Hypothèses!$D$25)))+(IF(B19=1,Hypothèses!$B$25,IF(B19=2,Hypothèses!$C$25,IF(B19=3,Hypothèses!$D$25,Hypothèses!$D$25)))-(IF(B19=1,0,IF(B19=2,Hypothèses!$B$25,IF(B19=3,Hypothèses!$C$25,Hypothèses!$D$25)))))*((A19)-INT((A19-1)/12)*12)/12)*$B$1 | G19: =(IF(B19=1,0,IF(B19=2,Hypothèses!$B$26,IF(B19=3,Hypothèses!$C$26,Hypothèses!$D$26)))+(IF(B19=1,Hypothèses!$B$26,IF(B19=2,Hypothèses!$C$26,IF(B19=3,Hypothèses!$D$26,Hypothèses!$D$26)))-(IF(B19=1,0,IF(B19=2,Hypothèses!$B$26,IF(B19=3,Hypothèses!$C$26,Hypothèses!$D$26)))))*((A19)-INT((A19-1)/12)*12)/12)*$B$1 | H19: =(IF(B19=1,0,IF(B19=2,Hypothèses!$B$27,IF(B19=3,Hypothèses!$C$27,Hypothèses!$D$27)))+(IF(B19=1,Hypothèses!$B$27,IF(B19=2,Hypothèses!$C$27,IF(B19=3,Hypothèses!$D$27,Hypothèses!$D$27)))-(IF(B19=1,0,IF(B19=2,Hypothèses!$B$27,IF(B19=3,Hypothèses!$C$27,Hypothèses!$D$27)))))*((A19)-INT((A19-1)/12)*12)/12)*$B$1 | I19: =IF(A19<Hypothèses!$B$7,0,Hypothèses!$B$8*(1-Hypothèses!$B$9)^(A19-Hypothèses!$B$7)) | J19: =C19+D19+E19 | K19: =(C19*Hypothèses!$B$11+D19*Hypothèses!$B$12+E19*Hypothèses!$B$13)*(IF(B19=1,Hypothèses!$B$19,IF(B19=2,Hypothèses!$B$20,Hypothèses!$B$21))+(1-(IF(B19=1,Hypothèses!$B$19,IF(B19=2,Hypothèses!$B$20,Hypothèses!$B$21))))*11/12) | L19: =J19*IF(B19=1,Hypothèses!$C$19,IF(B19=2,Hypothèses!$C$20,Hypothèses!$C$21))*IF(B19=1,Hypothèses!$D$19,IF(B19=2,Hypothèses!$D$20,Hypothèses!$D$21)) | M19: =IF(A19=18,IF($B$2>=1,Hypothèses!$B$31,0),IF(AND(OR(A19=30,A19=34),$D$2>=1),Hypothèses!$B$32*MIN(1,$D$2/3),0)) | N19: =K19+L19+M19 | O19: =N19/(1+Hypothèses!$B$6) | P19: =Hypothèses!$B$3*(1+Hypothèses!$B$4)^INT((A19-1)/3) | Q19: =0 | R19: =Q19*Hypothèses!$B$16 | S19: =O19*Hypothèses!$B$5 | T19: =O19-P19-R19-S19 | U19: =U18+T19
A20: 17 | B20: =INT((A20-1)/12)+1 | C20: =ROUND(IF(MOD($A20,12)=0,F20,(IF(20=4,0,C19))*(1-$I20)+IF((IF(20=4,0,C19))*(1-$I20)<F20,(F20-(IF(20=4,0,C19))*(1-$I20))*Hypothèses!$B$10,0)),1) | D20: =ROUND(IF(MOD($A20,12)=0,G20,(IF(20=4,0,D19))*(1-$I20)+IF((IF(20=4,0,D19))*(1-$I20)<G20,(G20-(IF(20=4,0,D19))*(1-$I20))*Hypothèses!$B$10,0)),1) | E20: =ROUND(IF(MOD($A20,12)=0,H20,(IF(20=4,0,E19))*(1-$I20)+IF((IF(20=4,0,E19))*(1-$I20)<H20,(H20-(IF(20=4,0,E19))*(1-$I20))*Hypothèses!$B$10,0)),1) | F20: =(IF(B20=1,0,IF(B20=2,Hypothèses!$B$25,IF(B20=3,Hypothèses!$C$25,Hypothèses!$D$25)))+(IF(B20=1,Hypothèses!$B$25,IF(B20=2,Hypothèses!$C$25,IF(B20=3,Hypothèses!$D$25,Hypothèses!$D$25)))-(IF(B20=1,0,IF(B20=2,Hypothèses!$B$25,IF(B20=3,Hypothèses!$C$25,Hypothèses!$D$25)))))*((A20)-INT((A20-1)/12)*12)/12)*$B$1 | G20: =(IF(B20=1,0,IF(B20=2,Hypothèses!$B$26,IF(B20=3,Hypothèses!$C$26,Hypothèses!$D$26)))+(IF(B20=1,Hypothèses!$B$26,IF(B20=2,Hypothèses!$C$26,IF(B20=3,Hypothèses!$D$26,Hypothèses!$D$26)))-(IF(B20=1,0,IF(B20=2,Hypothèses!$B$26,IF(B20=3,Hypothèses!$C$26,Hypothèses!$D$26)))))*((A20)-INT((A20-1)/12)*12)/12)*$B$1 | H20: =(IF(B20=1,0,IF(B20=2,Hypothèses!$B$27,IF(B20=3,Hypothèses!$C$27,Hypothèses!$D$27)))+(IF(B20=1,Hypothèses!$B$27,IF(B20=2,Hypothèses!$C$27,IF(B20=3,Hypothèses!$D$27,Hypothèses!$D$27)))-(IF(B20=1,0,IF(B20=2,Hypothèses!$B$27,IF(B20=3,Hypothèses!$C$27,Hypothèses!$D$27)))))*((A20)-INT((A20-1)/12)*12)/12)*$B$1 | I20: =IF(A20<Hypothèses!$B$7,0,Hypothèses!$B$8*(1-Hypothèses!$B$9)^(A20-Hypothèses!$B$7)) | J20: =C20+D20+E20 | K20: =(C20*Hypothèses!$B$11+D20*Hypothèses!$B$12+E20*Hypothèses!$B$13)*(IF(B20=1,Hypothèses!$B$19,IF(B20=2,Hypothèses!$B$20,Hypothèses!$B$21))+(1-(IF(B20=1,Hypothèses!$B$19,IF(B20=2,Hypothèses!$B$20,Hypothèses!$B$21))))*11/12) | L20: =J20*IF(B20=1,Hypothèses!$C$19,IF(B20=2,Hypothèses!$C$20,Hypothèses!$C$21))*IF(B20=1,Hypothèses!$D$19,IF(B20=2,Hypothèses!$D$20,Hypothèses!$D$21)) | M20: =IF(A20=18,IF($B$2>=1,Hypothèses!$B$31,0),IF(AND(OR(A20=30,A20=34),$D$2>=1),Hypothèses!$B$32*MIN(1,$D$2/3),0)) | N20: =K20+L20+M20 | O20: =N20/(1+Hypothèses!$B$6) | P20: =Hypothèses!$B$3*(1+Hypothèses!$B$4)^INT((A20-1)/3) | Q20: =0 | R20: =Q20*Hypothèses!$B$16 | S20: =O20*Hypothèses!$B$5 | T20: =O20-P20-R20-S20 | U20: =U19+T20
A21: 18 | B21: =INT((A21-1)/12)+1 | C21: =ROUND(IF(MOD($A21,12)=0,F21,(IF(21=4,0,C20))*(1-$I21)+IF((IF(21=4,0,C20))*(1-$I21)<F21,(F21-(IF(21=4,0,C20))*(1-$I21))*Hypothèses!$B$10,0)),1) | D21: =ROUND(IF(MOD($A21,12)=0,G21,(IF(21=4,0,D20))*(1-$I21)+IF((IF(21=4,0,D20))*(1-$I21)<G21,(G21-(IF(21=4,0,D20))*(1-$I21))*Hypothèses!$B$10,0)),1) | E21: =ROUND(IF(MOD($A21,12)=0,H21,(IF(21=4,0,E20))*(1-$I21)+IF((IF(21=4,0,E20))*(1-$I21)<H21,(H21-(IF(21=4,0,E20))*(1-$I21))*Hypothèses!$B$10,0)),1) | F21: =(IF(B21=1,0,IF(B21=2,Hypothèses!$B$25,IF(B21=3,Hypothèses!$C$25,Hypothèses!$D$25)))+(IF(B21=1,Hypothèses!$B$25,IF(B21=2,Hypothèses!$C$25,IF(B21=3,Hypothèses!$D$25,Hypothèses!$D$25)))-(IF(B21=1,0,IF(B21=2,Hypothèses!$B$25,IF(B21=3,Hypothèses!$C$25,Hypothèses!$D$25)))))*((A21)-INT((A21-1)/12)*12)/12)*$B$1 | G21: =(IF(B21=1,0,IF(B21=2,Hypothèses!$B$26,IF(B21=3,Hypothèses!$C$26,Hypothèses!$D$26)))+(IF(B21=1,Hypothèses!$B$26,IF(B21=2,Hypothèses!$C$26,IF(B21=3,Hypothèses!$D$26,Hypothèses!$D$26)))-(IF(B21=1,0,IF(B21=2,Hypothèses!$B$26,IF(B21=3,Hypothèses!$C$26,Hypothèses!$D$26)))))*((A21)-INT((A21-1)/12)*12)/12)*$B$1 | H21: =(IF(B21=1,0,IF(B21=2,Hypothèses!$B$27,IF(B21=3,Hypothèses!$C$27,Hypothèses!$D$27)))+(IF(B21=1,Hypothèses!$B$27,IF(B21=2,Hypothèses!$C$27,IF(B21=3,Hypothèses!$D$27,Hypothèses!$D$27)))-(IF(B21=1,0,IF(B21=2,Hypothèses!$B$27,IF(B21=3,Hypothèses!$C$27,Hypothèses!$D$27)))))*((A21)-INT((A21-1)/12)*12)/12)*$B$1 | I21: =IF(A21<Hypothèses!$B$7,0,Hypothèses!$B$8*(1-Hypothèses!$B$9)^(A21-Hypothèses!$B$7)) | J21: =C21+D21+E21 | K21: =(C21*Hypothèses!$B$11+D21*Hypothèses!$B$12+E21*Hypothèses!$B$13)*(IF(B21=1,Hypothèses!$B$19,IF(B21=2,Hypothèses!$B$20,Hypothèses!$B$21))+(1-(IF(B21=1,Hypothèses!$B$19,IF(B21=2,Hypothèses!$B$20,Hypothèses!$B$21))))*11/12) | L21: =J21*IF(B21=1,Hypothèses!$C$19,IF(B21=2,Hypothèses!$C$20,Hypothèses!$C$21))*IF(B21=1,Hypothèses!$D$19,IF(B21=2,Hypothèses!$D$20,Hypothèses!$D$21)) | M21: =IF(A21=18,IF($B$2>=1,Hypothèses!$B$31,0),IF(AND(OR(A21=30,A21=34),$D$2>=1),Hypothèses!$B$32*MIN(1,$D$2/3),0)) | N21: =K21+L21+M21 | O21: =N21/(1+Hypothèses!$B$6) | P21: =Hypothèses!$B$3*(1+Hypothèses!$B$4)^INT((A21-1)/3) | Q21: =0 | R21: =Q21*Hypothèses!$B$16 | S21: =O21*Hypothèses!$B$5 | T21: =O21-P21-R21-S21 | U21: =U20+T21
A22: 19 | B22: =INT((A22-1)/12)+1 | C22: =ROUND(IF(MOD($A22,12)=0,F22,(IF(22=4,0,C21))*(1-$I22)+IF((IF(22=4,0,C21))*(1-$I22)<F22,(F22-(IF(22=4,0,C21))*(1-$I22))*Hypothèses!$B$10,0)),1) | D22: =ROUND(IF(MOD($A22,12)=0,G22,(IF(22=4,0,D21))*(1-$I22)+IF((IF(22=4,0,D21))*(1-$I22)<G22,(G22-(IF(22=4,0,D21))*(1-$I22))*Hypothèses!$B$10,0)),1) | E22: =ROUND(IF(MOD($A22,12)=0,H22,(IF(22=4,0,E21))*(1-$I22)+IF((IF(22=4,0,E21))*(1-$I22)<H22,(H22-(IF(22=4,0,E21))*(1-$I22))*Hypothèses!$B$10,0)),1) | F22: =(IF(B22=1,0,IF(B22=2,Hypothèses!$B$25,IF(B22=3,Hypothèses!$C$25,Hypothèses!$D$25)))+(IF(B22=1,Hypothèses!$B$25,IF(B22=2,Hypothèses!$C$25,IF(B22=3,Hypothèses!$D$25,Hypothèses!$D$25)))-(IF(B22=1,0,IF(B22=2,Hypothèses!$B$25,IF(B22=3,Hypothèses!$C$25,Hypothèses!$D$25)))))*((A22)-INT((A22-1)/12)*12)/12)*$B$1 | G22: =(IF(B22=1,0,IF(B22=2,Hypothèses!$B$26,IF(B22=3,Hypothèses!$C$26,Hypothèses!$D$26)))+(IF(B22=1,Hypothèses!$B$26,IF(B22=2,Hypothèses!$C$26,IF(B22=3,Hypothèses!$D$26,Hypothèses!$D$26)))-(IF(B22=1,0,IF(B22=2,Hypothèses!$B$26,IF(B22=3,Hypothèses!$C$26,Hypothèses!$D$26)))))*((A22)-INT((A22-1)/12)*12)/12)*$B$1 | H22: =(IF(B22=1,0,IF(B22=2,Hypothèses!$B$27,IF(B22=3,Hypothèses!$C$27,Hypothèses!$D$27)))+(IF(B22=1,Hypothèses!$B$27,IF(B22=2,Hypothèses!$C$27,IF(B22=3,Hypothèses!$D$27,Hypothèses!$D$27)))-(IF(B22=1,0,IF(B22=2,Hypothèses!$B$27,IF(B22=3,Hypothèses!$C$27,Hypothèses!$D$27)))))*((A22)-INT((A22-1)/12)*12)/12)*$B$1 | I22: =IF(A22<Hypothèses!$B$7,0,Hypothèses!$B$8*(1-Hypothèses!$B$9)^(A22-Hypothèses!$B$7)) | J22: =C22+D22+E22 | K22: =(C22*Hypothèses!$B$11+D22*Hypothèses!$B$12+E22*Hypothèses!$B$13)*(IF(B22=1,Hypothèses!$B$19,IF(B22=2,Hypothèses!$B$20,Hypothèses!$B$21))+(1-(IF(B22=1,Hypothèses!$B$19,IF(B22=2,Hypothèses!$B$20,Hypothèses!$B$21))))*11/12) | L22: =J22*IF(B22=1,Hypothèses!$C$19,IF(B22=2,Hypothèses!$C$20,Hypothèses!$C$21))*IF(B22=1,Hypothèses!$D$19,IF(B22=2,Hypothèses!$D$20,Hypothèses!$D$21)) | M22: =IF(A22=18,IF($B$2>=1,Hypothèses!$B$31,0),IF(AND(OR(A22=30,A22=34),$D$2>=1),Hypothèses!$B$32*MIN(1,$D$2/3),0)) | N22: =K22+L22+M22 | O22: =N22/(1+Hypothèses!$B$6) | P22: =Hypothèses!$B$3*(1+Hypothèses!$B$4)^INT((A22-1)/3) | Q22: =0 | R22: =Q22*Hypothèses!$B$16 | S22: =O22*Hypothèses!$B$5 | T22: =O22-P22-R22-S22 | U22: =U21+T22
A23: 20 | B23: =INT((A23-1)/12)+1 | C23: =ROUND(IF(MOD($A23,12)=0,F23,(IF(23=4,0,C22))*(1-$I23)+IF((IF(23=4,0,C22))*(1-$I23)<F23,(F23-(IF(23=4,0,C22))*(1-$I23))*Hypothèses!$B$10,0)),1) | D23: =ROUND(IF(MOD($A23,12)=0,G23,(IF(23=4,0,D22))*(1-$I23)+IF((IF(23=4,0,D22))*(1-$I23)<G23,(G23-(IF(23=4,0,D22))*(1-$I23))*Hypothèses!$B$10,0)),1) | E23: =ROUND(IF(MOD($A23,12)=0,H23,(IF(23=4,0,E22))*(1-$I23)+IF((IF(23=4,0,E22))*(1-$I23)<H23,(H23-(IF(23=4,0,E22))*(1-$I23))*Hypothèses!$B$10,0)),1) | F23: =(IF(B23=1,0,IF(B23=2,Hypothèses!$B$25,IF(B23=3,Hypothèses!$C$25,Hypothèses!$D$25)))+(IF(B23=1,Hypothèses!$B$25,IF(B23=2,Hypothèses!$C$25,IF(B23=3,Hypothèses!$D$25,Hypothèses!$D$25)))-(IF(B23=1,0,IF(B23=2,Hypothèses!$B$25,IF(B23=3,Hypothèses!$C$25,Hypothèses!$D$25)))))*((A23)-INT((A23-1)/12)*12)/12)*$B$1 | G23: =(IF(B23=1,0,IF(B23=2,Hypothèses!$B$26,IF(B23=3,Hypothèses!$C$26,Hypothèses!$D$26)))+(IF(B23=1,Hypothèses!$B$26,IF(B23=2,Hypothèses!$C$26,IF(B23=3,Hypothèses!$D$26,Hypothèses!$D$26)))-(IF(B23=1,0,IF(B23=2,Hypothèses!$B$26,IF(B23=3,Hypothèses!$C$26,Hypothèses!$D$26)))))*((A23)-INT((A23-1)/12)*12)/12)*$B$1 | H23: =(IF(B23=1,0,IF(B23=2,Hypothèses!$B$27,IF(B23=3,Hypothèses!$C$27,Hypothèses!$D$27)))+(IF(B23=1,Hypothèses!$B$27,IF(B23=2,Hypothèses!$C$27,IF(B23=3,Hypothèses!$D$27,Hypothèses!$D$27)))-(IF(B23=1,0,IF(B23=2,Hypothèses!$B$27,IF(B23=3,Hypothèses!$C$27,Hypothèses!$D$27)))))*((A23)-INT((A23-1)/12)*12)/12)*$B$1 | I23: =IF(A23<Hypothèses!$B$7,0,Hypothèses!$B$8*(1-Hypothèses!$B$9)^(A23-Hypothèses!$B$7)) | J23: =C23+D23+E23 | K23: =(C23*Hypothèses!$B$11+D23*Hypothèses!$B$12+E23*Hypothèses!$B$13)*(IF(B23=1,Hypothèses!$B$19,IF(B23=2,Hypothèses!$B$20,Hypothèses!$B$21))+(1-(IF(B23=1,Hypothèses!$B$19,IF(B23=2,Hypothèses!$B$20,Hypothèses!$B$21))))*11/12) | L23: =J23*IF(B23=1,Hypothèses!$C$19,IF(B23=2,Hypothèses!$C$20,Hypothèses!$C$21))*IF(B23=1,Hypothèses!$D$19,IF(B23=2,Hypothèses!$D$20,Hypothèses!$D$21)) | M23: =IF(A23=18,IF($B$2>=1,Hypothèses!$B$31,0),IF(AND(OR(A23=30,A23=34),$D$2>=1),Hypothèses!$B$32*MIN(1,$D$2/3),0)) | N23: =K23+L23+M23 | O23: =N23/(1+Hypothèses!$B$6) | P23: =Hypothèses!$B$3*(1+Hypothèses!$B$4)^INT((A23-1)/3) | Q23: =0 | R23: =Q23*Hypothèses!$B$16 | S23: =O23*Hypothèses!$B$5 | T23: =O23-P23-R23-S23 | U23: =U22+T23
A24: 21 | B24: =INT((A24-1)/12)+1 | C24: =ROUND(IF(MOD($A24,12)=0,F24,(IF(24=4,0,C23))*(1-$I24)+IF((IF(24=4,0,C23))*(1-$I24)<F24,(F24-(IF(24=4,0,C23))*(1-$I24))*Hypothèses!$B$10,0)),1) | D24: =ROUND(IF(MOD($A24,12)=0,G24,(IF(24=4,0,D23))*(1-$I24)+IF((IF(24=4,0,D23))*(1-$I24)<G24,(G24-(IF(24=4,0,D23))*(1-$I24))*Hypothèses!$B$10,0)),1) | E24: =ROUND(IF(MOD($A24,12)=0,H24,(IF(24=4,0,E23))*(1-$I24)+IF((IF(24=4,0,E23))*(1-$I24)<H24,(H24-(IF(24=4,0,E23))*(1-$I24))*Hypothèses!$B$10,0)),1) | F24: =(IF(B24=1,0,IF(B24=2,Hypothèses!$B$25,IF(B24=3,Hypothèses!$C$25,Hypothèses!$D$25)))+(IF(B24=1,Hypothèses!$B$25,IF(B24=2,Hypothèses!$C$25,IF(B24=3,Hypothèses!$D$25,Hypothèses!$D$25)))-(IF(B24=1,0,IF(B24=2,Hypothèses!$B$25,IF(B24=3,Hypothèses!$C$25,Hypothèses!$D$25)))))*((A24)-INT((A24-1)/12)*12)/12)*$B$1 | G24: =(IF(B24=1,0,IF(B24=2,Hypothèses!$B$26,IF(B24=3,Hypothèses!$C$26,Hypothèses!$D$26)))+(IF(B24=1,Hypothèses!$B$26,IF(B24=2,Hypothèses!$C$26,IF(B24=3,Hypothèses!$D$26,Hypothèses!$D$26)))-(IF(B24=1,0,IF(B24=2,Hypothèses!$B$26,IF(B24=3,Hypothèses!$C$26,Hypothèses!$D$26)))))*((A24)-INT((A24-1)/12)*12)/12)*$B$1 | H24: =(IF(B24=1,0,IF(B24=2,Hypothèses!$B$27,IF(B24=3,Hypothèses!$C$27,Hypothèses!$D$27)))+(IF(B24=1,Hypothèses!$B$27,IF(B24=2,Hypothèses!$C$27,IF(B24=3,Hypothèses!$D$27,Hypothèses!$D$27)))-(IF(B24=1,0,IF(B24=2,Hypothèses!$B$27,IF(B24=3,Hypothèses!$C$27,Hypothèses!$D$27)))))*((A24)-INT((A24-1)/12)*12)/12)*$B$1 | I24: =IF(A24<Hypothèses!$B$7,0,Hypothèses!$B$8*(1-Hypothèses!$B$9)^(A24-Hypothèses!$B$7)) | J24: =C24+D24+E24 | K24: =(C24*Hypothèses!$B$11+D24*Hypothèses!$B$12+E24*Hypothèses!$B$13)*(IF(B24=1,Hypothèses!$B$19,IF(B24=2,Hypothèses!$B$20,Hypothèses!$B$21))+(1-(IF(B24=1,Hypothèses!$B$19,IF(B24=2,Hypothèses!$B$20,Hypothèses!$B$21))))*11/12) | L24: =J24*IF(B24=1,Hypothèses!$C$19,IF(B24=2,Hypothèses!$C$20,Hypothèses!$C$21))*IF(B24=1,Hypothèses!$D$19,IF(B24=2,Hypothèses!$D$20,Hypothèses!$D$21)) | M24: =IF(A24=18,IF($B$2>=1,Hypothèses!$B$31,0),IF(AND(OR(A24=30,A24=34),$D$2>=1),Hypothèses!$B$32*MIN(1,$D$2/3),0)) | N24: =K24+L24+M24 | O24: =N24/(1+Hypothèses!$B$6) | P24: =Hypothèses!$B$3*(1+Hypothèses!$B$4)^INT((A24-1)/3) | Q24: =0 | R24: =Q24*Hypothèses!$B$16 | S24: =O24*Hypothèses!$B$5 | T24: =O24-P24-R24-S24 | U24: =U23+T24
A25: 22 | B25: =INT((A25-1)/12)+1 | C25: =ROUND(IF(MOD($A25,12)=0,F25,(IF(25=4,0,C24))*(1-$I25)+IF((IF(25=4,0,C24))*(1-$I25)<F25,(F25-(IF(25=4,0,C24))*(1-$I25))*Hypothèses!$B$10,0)),1) | D25: =ROUND(IF(MOD($A25,12)=0,G25,(IF(25=4,0,D24))*(1-$I25)+IF((IF(25=4,0,D24))*(1-$I25)<G25,(G25-(IF(25=4,0,D24))*(1-$I25))*Hypothèses!$B$10,0)),1) | E25: =ROUND(IF(MOD($A25,12)=0,H25,(IF(25=4,0,E24))*(1-$I25)+IF((IF(25=4,0,E24))*(1-$I25)<H25,(H25-(IF(25=4,0,E24))*(1-$I25))*Hypothèses!$B$10,0)),1) | F25: =(IF(B25=1,0,IF(B25=2,Hypothèses!$B$25,IF(B25=3,Hypothèses!$C$25,Hypothèses!$D$25)))+(IF(B25=1,Hypothèses!$B$25,IF(B25=2,Hypothèses!$C$25,IF(B25=3,Hypothèses!$D$25,Hypothèses!$D$25)))-(IF(B25=1,0,IF(B25=2,Hypothèses!$B$25,IF(B25=3,Hypothèses!$C$25,Hypothèses!$D$25)))))*((A25)-INT((A25-1)/12)*12)/12)*$B$1 | G25: =(IF(B25=1,0,IF(B25=2,Hypothèses!$B$26,IF(B25=3,Hypothèses!$C$26,Hypothèses!$D$26)))+(IF(B25=1,Hypothèses!$B$26,IF(B25=2,Hypothèses!$C$26,IF(B25=3,Hypothèses!$D$26,Hypothèses!$D$26)))-(IF(B25=1,0,IF(B25=2,Hypothèses!$B$26,IF(B25=3,Hypothèses!$C$26,Hypothèses!$D$26)))))*((A25)-INT((A25-1)/12)*12)/12)*$B$1 | H25: =(IF(B25=1,0,IF(B25=2,Hypothèses!$B$27,IF(B25=3,Hypothèses!$C$27,Hypothèses!$D$27)))+(IF(B25=1,Hypothèses!$B$27,IF(B25=2,Hypothèses!$C$27,IF(B25=3,Hypothèses!$D$27,Hypothèses!$D$27)))-(IF(B25=1,0,IF(B25=2,Hypothèses!$B$27,IF(B25=3,Hypothèses!$C$27,Hypothèses!$D$27)))))*((A25)-INT((A25-1)/12)*12)/12)*$B$1 | I25: =IF(A25<Hypothèses!$B$7,0,Hypothèses!$B$8*(1-Hypothèses!$B$9)^(A25-Hypothèses!$B$7)) | J25: =C25+D25+E25 | K25: =(C25*Hypothèses!$B$11+D25*Hypothèses!$B$12+E25*Hypothèses!$B$13)*(IF(B25=1,Hypothèses!$B$19,IF(B25=2,Hypothèses!$B$20,Hypothèses!$B$21))+(1-(IF(B25=1,Hypothèses!$B$19,IF(B25=2,Hypothèses!$B$20,Hypothèses!$B$21))))*11/12) | L25: =J25*IF(B25=1,Hypothèses!$C$19,IF(B25=2,Hypothèses!$C$20,Hypothèses!$C$21))*IF(B25=1,Hypothèses!$D$19,IF(B25=2,Hypothèses!$D$20,Hypothèses!$D$21)) | M25: =IF(A25=18,IF($B$2>=1,Hypothèses!$B$31,0),IF(AND(OR(A25=30,A25=34),$D$2>=1),Hypothèses!$B$32*MIN(1,$D$2/3),0)) | N25: =K25+L25+M25 | O25: =N25/(1+Hypothèses!$B$6) | P25: =Hypothèses!$B$3*(1+Hypothèses!$B$4)^INT((A25-1)/3) | Q25: =0 | R25: =Q25*Hypothèses!$B$16 | S25: =O25*Hypothèses!$B$5 | T25: =O25-P25-R25-S25 | U25: =U24+T25
A26: 23 | B26: =INT((A26-1)/12)+1 | C26: =ROUND(IF(MOD($A26,12)=0,F26,(IF(26=4,0,C25))*(1-$I26)+IF((IF(26=4,0,C25))*(1-$I26)<F26,(F26-(IF(26=4,0,C25))*(1-$I26))*Hypothèses!$B$10,0)),1) | D26: =ROUND(IF(MOD($A26,12)=0,G26,(IF(26=4,0,D25))*(1-$I26)+IF((IF(26=4,0,D25))*(1-$I26)<G26,(G26-(IF(26=4,0,D25))*(1-$I26))*Hypothèses!$B$10,0)),1) | E26: =ROUND(IF(MOD($A26,12)=0,H26,(IF(26=4,0,E25))*(1-$I26)+IF((IF(26=4,0,E25))*(1-$I26)<H26,(H26-(IF(26=4,0,E25))*(1-$I26))*Hypothèses!$B$10,0)),1) | F26: =(IF(B26=1,0,IF(B26=2,Hypothèses!$B$25,IF(B26=3,Hypothèses!$C$25,Hypothèses!$D$25)))+(IF(B26=1,Hypothèses!$B$25,IF(B26=2,Hypothèses!$C$25,IF(B26=3,Hypothèses!$D$25,Hypothèses!$D$25)))-(IF(B26=1,0,IF(B26=2,Hypothèses!$B$25,IF(B26=3,Hypothèses!$C$25,Hypothèses!$D$25)))))*((A26)-INT((A26-1)/12)*12)/12)*$B$1 | G26: =(IF(B26=1,0,IF(B26=2,Hypothèses!$B$26,IF(B26=3,Hypothèses!$C$26,Hypothèses!$D$26)))+(IF(B26=1,Hypothèses!$B$26,IF(B26=2,Hypothèses!$C$26,IF(B26=3,Hypothèses!$D$26,Hypothèses!$D$26)))-(IF(B26=1,0,IF(B26=2,Hypothèses!$B$26,IF(B26=3,Hypothèses!$C$26,Hypothèses!$D$26)))))*((A26)-INT((A26-1)/12)*12)/12)*$B$1 | H26: =(IF(B26=1,0,IF(B26=2,Hypothèses!$B$27,IF(B26=3,Hypothèses!$C$27,Hypothèses!$D$27)))+(IF(B26=1,Hypothèses!$B$27,IF(B26=2,Hypothèses!$C$27,IF(B26=3,Hypothèses!$D$27,Hypothèses!$D$27)))-(IF(B26=1,0,IF(B26=2,Hypothèses!$B$27,IF(B26=3,Hypothèses!$C$27,Hypothèses!$D$27)))))*((A26)-INT((A26-1)/12)*12)/12)*$B$1 | I26: =IF(A26<Hypothèses!$B$7,0,Hypothèses!$B$8*(1-Hypothèses!$B$9)^(A26-Hypothèses!$B$7)) | J26: =C26+D26+E26 | K26: =(C26*Hypothèses!$B$11+D26*Hypothèses!$B$12+E26*Hypothèses!$B$13)*(IF(B26=1,Hypothèses!$B$19,IF(B26=2,Hypothèses!$B$20,Hypothèses!$B$21))+(1-(IF(B26=1,Hypothèses!$B$19,IF(B26=2,Hypothèses!$B$20,Hypothèses!$B$21))))*11/12) | L26: =J26*IF(B26=1,Hypothèses!$C$19,IF(B26=2,Hypothèses!$C$20,Hypothèses!$C$21))*IF(B26=1,Hypothèses!$D$19,IF(B26=2,Hypothèses!$D$20,Hypothèses!$D$21)) | M26: =IF(A26=18,IF($B$2>=1,Hypothèses!$B$31,0),IF(AND(OR(A26=30,A26=34),$D$2>=1),Hypothèses!$B$32*MIN(1,$D$2/3),0)) | N26: =K26+L26+M26 | O26: =N26/(1+Hypothèses!$B$6) | P26: =Hypothèses!$B$3*(1+Hypothèses!$B$4)^INT((A26-1)/3) | Q26: =0 | R26: =Q26*Hypothèses!$B$16 | S26: =O26*Hypothèses!$B$5 | T26: =O26-P26-R26-S26 | U26: =U25+T26
A27: 24 | B27: =INT((A27-1)/12)+1 | C27: =ROUND(IF(MOD($A27,12)=0,F27,(IF(27=4,0,C26))*(1-$I27)+IF((IF(27=4,0,C26))*(1-$I27)<F27,(F27-(IF(27=4,0,C26))*(1-$I27))*Hypothèses!$B$10,0)),1) | D27: =ROUND(IF(MOD($A27,12)=0,G27,(IF(27=4,0,D26))*(1-$I27)+IF((IF(27=4,0,D26))*(1-$I27)<G27,(G27-(IF(27=4,0,D26))*(1-$I27))*Hypothèses!$B$10,0)),1) | E27: =ROUND(IF(MOD($A27,12)=0,H27,(IF(27=4,0,E26))*(1-$I27)+IF((IF(27=4,0,E26))*(1-$I27)<H27,(H27-(IF(27=4,0,E26))*(1-$I27))*Hypothèses!$B$10,0)),1) | F27: =(IF(B27=1,0,IF(B27=2,Hypothèses!$B$25,IF(B27=3,Hypothèses!$C$25,Hypothèses!$D$25)))+(IF(B27=1,Hypothèses!$B$25,IF(B27=2,Hypothèses!$C$25,IF(B27=3,Hypothèses!$D$25,Hypothèses!$D$25)))-(IF(B27=1,0,IF(B27=2,Hypothèses!$B$25,IF(B27=3,Hypothèses!$C$25,Hypothèses!$D$25)))))*((A27)-INT((A27-1)/12)*12)/12)*$B$1 | G27: =(IF(B27=1,0,IF(B27=2,Hypothèses!$B$26,IF(B27=3,Hypothèses!$C$26,Hypothèses!$D$26)))+(IF(B27=1,Hypothèses!$B$26,IF(B27=2,Hypothèses!$C$26,IF(B27=3,Hypothèses!$D$26,Hypothèses!$D$26)))-(IF(B27=1,0,IF(B27=2,Hypothèses!$B$26,IF(B27=3,Hypothèses!$C$26,Hypothèses!$D$26)))))*((A27)-INT((A27-1)/12)*12)/12)*$B$1 | H27: =(IF(B27=1,0,IF(B27=2,Hypothèses!$B$27,IF(B27=3,Hypothèses!$C$27,Hypothèses!$D$27)))+(IF(B27=1,Hypothèses!$B$27,IF(B27=2,Hypothèses!$C$27,IF(B27=3,Hypothèses!$D$27,Hypothèses!$D$27)))-(IF(B27=1,0,IF(B27=2,Hypothèses!$B$27,IF(B27=3,Hypothèses!$C$27,Hypothèses!$D$27)))))*((A27)-INT((A27-1)/12)*12)/12)*$B$1 | I27: =IF(A27<Hypothèses!$B$7,0,Hypothèses!$B$8*(1-Hypothèses!$B$9)^(A27-Hypothèses!$B$7)) | J27: =C27+D27+E27 | K27: =(C27*Hypothèses!$B$11+D27*Hypothèses!$B$12+E27*Hypothèses!$B$13)*(IF(B27=1,Hypothèses!$B$19,IF(B27=2,Hypothèses!$B$20,Hypothèses!$B$21))+(1-(IF(B27=1,Hypothèses!$B$19,IF(B27=2,Hypothèses!$B$20,Hypothèses!$B$21))))*11/12) | L27: =J27*IF(B27=1,Hypothèses!$C$19,IF(B27=2,Hypothèses!$C$20,Hypothèses!$C$21))*IF(B27=1,Hypothèses!$D$19,IF(B27=2,Hypothèses!$D$20,Hypothèses!$D$21)) | M27: =IF(A27=18,IF($B$2>=1,Hypothèses!$B$31,0),IF(AND(OR(A27=30,A27=34),$D$2>=1),Hypothèses!$B$32*MIN(1,$D$2/3),0)) | N27: =K27+L27+M27 | O27: =N27/(1+Hypothèses!$B$6) | P27: =Hypothèses!$B$3*(1+Hypothèses!$B$4)^INT((A27-1)/3) | Q27: =0 | R27: =Q27*Hypothèses!$B$16 | S27: =O27*Hypothèses!$B$5 | T27: =O27-P27-R27-S27 | U27: =U26+T27
A28: 25 | B28: =INT((A28-1)/12)+1 | C28: =ROUND(IF(MOD($A28,12)=0,F28,(IF(28=4,0,C27))*(1-$I28)+IF((IF(28=4,0,C27))*(1-$I28)<F28,(F28-(IF(28=4,0,C27))*(1-$I28))*Hypothèses!$B$10,0)),1) | D28: =ROUND(IF(MOD($A28,12)=0,G28,(IF(28=4,0,D27))*(1-$I28)+IF((IF(28=4,0,D27))*(1-$I28)<G28,(G28-(IF(28=4,0,D27))*(1-$I28))*Hypothèses!$B$10,0)),1) | E28: =ROUND(IF(MOD($A28,12)=0,H28,(IF(28=4,0,E27))*(1-$I28)+IF((IF(28=4,0,E27))*(1-$I28)<H28,(H28-(IF(28=4,0,E27))*(1-$I28))*Hypothèses!$B$10,0)),1) | F28: =(IF(B28=1,0,IF(B28=2,Hypothèses!$B$25,IF(B28=3,Hypothèses!$C$25,Hypothèses!$D$25)))+(IF(B28=1,Hypothèses!$B$25,IF(B28=2,Hypothèses!$C$25,IF(B28=3,Hypothèses!$D$25,Hypothèses!$D$25)))-(IF(B28=1,0,IF(B28=2,Hypothèses!$B$25,IF(B28=3,Hypothèses!$C$25,Hypothèses!$D$25)))))*((A28)-INT((A28-1)/12)*12)/12)*$B$1 | G28: =(IF(B28=1,0,IF(B28=2,Hypothèses!$B$26,IF(B28=3,Hypothèses!$C$26,Hypothèses!$D$26)))+(IF(B28=1,Hypothèses!$B$26,IF(B28=2,Hypothèses!$C$26,IF(B28=3,Hypothèses!$D$26,Hypothèses!$D$26)))-(IF(B28=1,0,IF(B28=2,Hypothèses!$B$26,IF(B28=3,Hypothèses!$C$26,Hypothèses!$D$26)))))*((A28)-INT((A28-1)/12)*12)/12)*$B$1 | H28: =(IF(B28=1,0,IF(B28=2,Hypothèses!$B$27,IF(B28=3,Hypothèses!$C$27,Hypothèses!$D$27)))+(IF(B28=1,Hypothèses!$B$27,IF(B28=2,Hypothèses!$C$27,IF(B28=3,Hypothèses!$D$27,Hypothèses!$D$27)))-(IF(B28=1,0,IF(B28=2,Hypothèses!$B$27,IF(B28=3,Hypothèses!$C$27,Hypothèses!$D$27)))))*((A28)-INT((A28-1)/12)*12)/12)*$B$1 | I28: =IF(A28<Hypothèses!$B$7,0,Hypothèses!$B$8*(1-Hypothèses!$B$9)^(A28-Hypothèses!$B$7)) | J28: =C28+D28+E28 | K28: =(C28*Hypothèses!$B$11+D28*Hypothèses!$B$12+E28*Hypothèses!$B$13)*(IF(B28=1,Hypothèses!$B$19,IF(B28=2,Hypothèses!$B$20,Hypothèses!$B$21))+(1-(IF(B28=1,Hypothèses!$B$19,IF(B28=2,Hypothèses!$B$20,Hypothèses!$B$21))))*11/12) | L28: =J28*IF(B28=1,Hypothèses!$C$19,IF(B28=2,Hypothèses!$C$20,Hypothèses!$C$21))*IF(B28=1,Hypothèses!$D$19,IF(B28=2,Hypothèses!$D$20,Hypothèses!$D$21)) | M28: =IF(A28=18,IF($B$2>=1,Hypothèses!$B$31,0),IF(AND(OR(A28=30,A28=34),$D$2>=1),Hypothèses!$B$32*MIN(1,$D$2/3),0)) | N28: =K28+L28+M28 | O28: =N28/(1+Hypothèses!$B$6) | P28: =Hypothèses!$B$3*(1+Hypothèses!$B$4)^INT((A28-1)/3) | Q28: =0 | R28: =Q28*Hypothèses!$B$16 | S28: =O28*Hypothèses!$B$5 | T28: =O28-P28-R28-S28 | U28: =U27+T28
A29: 26 | B29: =INT((A29-1)/12)+1 | C29: =ROUND(IF(MOD($A29,12)=0,F29,(IF(29=4,0,C28))*(1-$I29)+IF((IF(29=4,0,C28))*(1-$I29)<F29,(F29-(IF(29=4,0,C28))*(1-$I29))*Hypothèses!$B$10,0)),1) | D29: =ROUND(IF(MOD($A29,12)=0,G29,(IF(29=4,0,D28))*(1-$I29)+IF((IF(29=4,0,D28))*(1-$I29)<G29,(G29-(IF(29=4,0,D28))*(1-$I29))*Hypothèses!$B$10,0)),1) | E29: =ROUND(IF(MOD($A29,12)=0,H29,(IF(29=4,0,E28))*(1-$I29)+IF((IF(29=4,0,E28))*(1-$I29)<H29,(H29-(IF(29=4,0,E28))*(1-$I29))*Hypothèses!$B$10,0)),1) | F29: =(IF(B29=1,0,IF(B29=2,Hypothèses!$B$25,IF(B29=3,Hypothèses!$C$25,Hypothèses!$D$25)))+(IF(B29=1,Hypothèses!$B$25,IF(B29=2,Hypothèses!$C$25,IF(B29=3,Hypothèses!$D$25,Hypothèses!$D$25)))-(IF(B29=1,0,IF(B29=2,Hypothèses!$B$25,IF(B29=3,Hypothèses!$C$25,Hypothèses!$D$25)))))*((A29)-INT((A29-1)/12)*12)/12)*$B$1 | G29: =(IF(B29=1,0,IF(B29=2,Hypothèses!$B$26,IF(B29=3,Hypothèses!$C$26,Hypothèses!$D$26)))+(IF(B29=1,Hypothèses!$B$26,IF(B29=2,Hypothèses!$C$26,IF(B29=3,Hypothèses!$D$26,Hypothèses!$D$26)))-(IF(B29=1,0,IF(B29=2,Hypothèses!$B$26,IF(B29=3,Hypothèses!$C$26,Hypothèses!$D$26)))))*((A29)-INT((A29-1)/12)*12)/12)*$B$1 | H29: =(IF(B29=1,0,IF(B29=2,Hypothèses!$B$27,IF(B29=3,Hypothèses!$C$27,Hypothèses!$D$27)))+(IF(B29=1,Hypothèses!$B$27,IF(B29=2,Hypothèses!$C$27,IF(B29=3,Hypothèses!$D$27,Hypothèses!$D$27)))-(IF(B29=1,0,IF(B29=2,Hypothèses!$B$27,IF(B29=3,Hypothèses!$C$27,Hypothèses!$D$27)))))*((A29)-INT((A29-1)/12)*12)/12)*$B$1 | I29: =IF(A29<Hypothèses!$B$7,0,Hypothèses!$B$8*(1-Hypothèses!$B$9)^(A29-Hypothèses!$B$7)) | J29: =C29+D29+E29 | K29: =(C29*Hypothèses!$B$11+D29*Hypothèses!$B$12+E29*Hypothèses!$B$13)*(IF(B29=1,Hypothèses!$B$19,IF(B29=2,Hypothèses!$B$20,Hypothèses!$B$21))+(1-(IF(B29=1,Hypothèses!$B$19,IF(B29=2,Hypothèses!$B$20,Hypothèses!$B$21))))*11/12) | L29: =J29*IF(B29=1,Hypothèses!$C$19,IF(B29=2,Hypothèses!$C$20,Hypothèses!$C$21))*IF(B29=1,Hypothèses!$D$19,IF(B29=2,Hypothèses!$D$20,Hypothèses!$D$21)) | M29: =IF(A29=18,IF($B$2>=1,Hypothèses!$B$31,0),IF(AND(OR(A29=30,A29=34),$D$2>=1),Hypothèses!$B$32*MIN(1,$D$2/3),0)) | N29: =K29+L29+M29 | O29: =N29/(1+Hypothèses!$B$6) | P29: =Hypothèses!$B$3*(1+Hypothèses!$B$4)^INT((A29-1)/3) | Q29: =0 | R29: =Q29*Hypothèses!$B$16 | S29: =O29*Hypothèses!$B$5 | T29: =O29-P29-R29-S29 | U29: =U28+T29
