Workbook

Sheet Hypothèses
A1: Paramètre | B1: Valeur
A2: Capital initial (€) | B2: 2100
A3: Frais fixes infra départ (€/mois) | B3: 500
A4: Hausse frais fixes / trimestre | B4: 0.15
A5: Frais variables (% CA HT) | B5: 0.01
A6: TVA (%) | B6: 0.2
A7: Churn — début (mois) | B7: 9
A8: Churn initial (%/mois) | B8: 0.05
A9: Décroissance churn (%/mois) | B9: 0.1
A10: Rattrapage rampe (%/mois) | B10: 0.4
A11: Prix Atelier TTC (€/mois) | B11: 89
A12: Prix Horizon TTC (€/mois) | B12: 149
A13: Prix L'Envergure TTC (€/mois) | B13: 499
... A16: Jours / mois / développeur | B16: 10
A17: Coût mensuel / développeur (€ HT) | B17: =B15*B16 -> 4500
A19: Facturation par année
A20: A1 | B20: 0.6 | C20: 0.05 | D20: 20
A21: A2 | B21: 0.5 | C21: 0.1 | D21: 25
A22: A3 | B22: 0.4 | C22: 0.12 | D22: 30
A24: Effectifs cibles fin d'année (base, avant facteur scénario)
A25: Plan | B25: Fin A1 | C25: Fin A2 | D25: Fin A3
A26: Atelier | B26: 5 | C26: 10 | D26: 20
A27: Horizon | B27: 10 | C27: 35 | D27: 70
A28: L'Envergure | B28: 0 | C28: 1 | D28: 3
A29: Rayonnement | B29: 0 | C29: 1 | D29: 2
A30: Zénith (contrats) | B30: 0 | C30: 1 | D30: 3
A32: Zénith — montants TTC (base)
A33: Mois 18 | B33: 15000
A34: Mois 30/34 | B34: 17000
A36: Note | B36: Modifier les valeurs ci-dessus : les 3 onglets scénario se recalculent automatiquement.

Sheet Prudent (-30%)
A1: Facteur clients (scénario) | B1: 0.7
A2: Zénith fin A2 (cible) | B2: =ROUND(Hypothèses!$C$30*$B$1,0) -> 1 | C2: Zénith fin A3 (cible) | D2: =ROUND(Hypothèses!$D$30*$B$1,0) -> 2
A3: Mois | B3: Année | C3: Atelier | D3: Horizon | E3: Envergure | F3: Rayonnement | G3: Cible Atelier | H3: Cible Horizon | I3: Cible Enverg. | J3: Cible Rayonn. | K3: Taux churn | L3: Clients payants | M3: MRR abo TTC | N3: Options TTC | O3: Zénith TTC | P3: CA TTC | Q3: CA HT | R3: Frais fixes infra | S3: Nb développeurs | T3: Sous-traitance dev (HT) | U3: Frais variables 1% | V3: EBITDA | W3: Trésorerie
A4: 1 | B4: =INT((A4-1)/12)+1 -> 1 | C4: =ROUND(IF(MOD($A4,12)=0,G4,(IF(4=4,0,C3))*(1-$K4)+IF((IF(4=4,0,C3))*(1-$K4)<G4,(G4-(IF(4=4,0,C3))*(1-$K4))*Hypothèses!$B$10,0)),1) -> 0.1 | D4: =ROUND(IF(MOD($A4,12)=0,H4,(IF(4=4,0,D3))*(1-$K4)+IF((IF(4=4,0,D3))*(1-$K4)<H4,(H4-(IF(4=4,0,D3))*(1-$K4))*Hypothèses!$B$10,0)),1) -> 0.2 | E4: =ROUND(IF(MOD($A4,12)=0,I4,(IF(4=4,0,E3))*(1-$K4)+IF((IF(4=4,0,E3))*(1-$K4)<I4,(I4-(IF(4=4,0,E3))*(1-$K4))*Hypothèses!$B$10,0)),1) -> 0 | F4: =ROUND(IF(MOD($A4,12)=0,J4,(IF(4=4,0,F3))*(1-$K4)+IF((IF(4=4,0,F3))*(1-$K4)<J4,(J4-(IF(4=4,0,F3))*(1-$K4))*Hypothèses!$B$10,0)),1) -> 0 | G4: =(IF(B4=1,0,IF(B4=2,Hypothèses!$B$26,IF(B4=3,Hypothèses!$C$26,Hypothèses!$D$26)))+(IF(B4=1,Hypothèses!$B$26,IF(B4=2,Hypothèses!$C$26,IF(B4=3,Hypothèses!$D$26,Hypothèses!$D$26)))-(IF(B4=1,0,IF(B4=2,Hypothèses!$B$26,IF(B4=3,Hypothèses!$C$26,Hypothèses!$D$26)))))*((A4)-INT((A4-1)/12)*12)/12)*$B$1 -> 0.29166667 | H4: =(IF(B4=1,0,IF(B4=2,Hypothèses!$B$27,IF(B4=3,Hypothèses!$C$27,Hypothèses!$D$27)))+(IF(B4=1,Hypothèses!$B$27,IF(B4=2,Hypothèses!$C$27,IF(B4=3,Hypothèses!$D$27,Hypothèses!$D$27)))-(IF(B4=1,0,IF(B4=2,Hypothèses!$B$27,IF(B4=3,Hypothèses!$C$27,Hypothèses!$D$27)))))*((A4)-INT((A4-1)/12)*12)/12)*$B$1 -> 0.58333333 | I4: =(IF(B4=1,0,IF(B4=2,Hypothèses!$B$28,IF(B4=3,Hypothèses!$C$28,Hypothèses!$D$28)))+(IF(B4=1,Hypothèses!$B$28,IF(B4=2,Hypothèses!$C$28,IF(B4=3,Hypothèses!$D$28,Hypothèses!$D$28)))-(IF(B4=1,0,IF(B4=2,Hypothèses!$B$28,IF(B4=3,Hypothèses!$C$28,Hypothèses!$D$28)))))*((A4)-INT((A4-1)/12)*12)/12)*$B$1 -> 0 | J4: =(IF(B4=1,0,IF(B4=2,Hypothèses!$B$29,IF(B4=3,Hypothèses!$C$29,Hypothèses!$D$29)))+(IF(B4=1,Hypothèses!$B$29,IF(B4=2,Hypothèses!$C$29,IF(B4=3,Hypothèses!$D$29,Hypothèses!$D$29)))-(IF(B4=1,0,IF(B4=2,Hypothèses!$B$29,IF(B4=3,Hypothèses!$C$29,Hypothèses!$D$29)))))*((A4)-INT((A4-1)/12)*12)/12)*$B$1 -> 0 | K4: =IF(A4<Hypothèses!$B$7,0,Hypothèses!$B$8*(1-Hypothèses!$B$9)^(A4-Hypothèses!$B$7)) -> 0 | L4: =C4+D4+E4+F4 -> 0.3 | M4: =(C4*Hypothèses!$B$11+D4*Hypothèses!$B$12+E4*Hypothèses!$B$13+F4*Hypothèses!$B$14)*(IF(B4=1,Hypothèses!$B$20,IF(B4=2,Hypothèses!$B$21,Hypothèses!$B$22))+(1-(IF(B4=1,Hypothèses!$B$20,IF(B4=2,Hypothèses!$B$21,Hypothèses!$B$22))))*11/12) -> 37.41 | N4: =L4*IF(B4=1,Hypothèses!$C$20,IF(B4=2,Hypothèses!$C$21,Hypothèses!$C$22))*IF(B4=1,Hypothèses!$D$20,IF(B4=2,Hypothèses!$D$21,Hypothèses!$D$22)) -> 0.3 | O4: =IF(A4=18,IF($B$2>=1,Hypothèses!$B$33,0),IF(AND(OR(A4=30,A4=34),$D$2>=1),Hypothèses!$B$34*MIN(1,$D$2/3),0)) -> 0 | P4: =M4+N4+O4 -> 37.71 | Q4: =P4/(1+Hypothèses!$B$6) -> 31.425 | R4: =Hypothèses!$B$3*(1+Hypothèses!$B$4)^INT((A4-1)/3) -> 500 | S4: =0 -> 0 | T4: =S4*Hypothèses!$B$17 -> 0 | U4: =Q4*Hypothèses!$B$5 -> 0.31425 | V4: =Q4-R4-T4-U4 -> -468.88925 | W4: =Hypothèses!$B$2+V4 -> 1631.1108
A5: 2 | B5: =INT((A5-1)/12)+1 -> 1 | C5: =ROUND(IF(MOD($A5,12)=0,G5,(IF(5=4,0,C4))*(1-$K5)+IF((IF(5=4,0,C4))*(1-$K5)<G5,(G5-(IF(5=4,0,C4))*(1-$K5))*Hypothèses!$B$10,0)),1) -> 0.3 | D5: =ROUND(IF(MOD($A5,12)=0,H5,(IF(5=4,0,D4))*(1-$K5)+IF((IF(5=4,0,D4))*(1-$K5)<H5,(H5-(IF(5=4,0,D4))*(1-$K5))*Hypothèses!$B$10,0)),1) -> 0.6 | E5: =ROUND(IF(MOD($A5,12)=0,I5,(IF(5=4,0,E4))*(1-$K5)+IF((IF(5=4,0,E4))*(1-$K5)<I5,(I5-(IF(5=4,0,E4))*(1-$K5))*Hypothèses!$B$10,0)),1) -> 0 | F5: =ROUND(IF(MOD($A5,12)=0,J5,(IF(5=4,0,F4))*(1-$K5)+IF((IF(5=4,0,F4))*(1-$K5)<J5,(J5-(IF(5=4,0,F4))*(1-$K5))*Hypothèses!$B$10,0)),1) -> 0 | G5: =(IF(B5=1,0,IF(B5=2,Hypothèses!$B$26,IF(B5=3,Hypothèses!$C$26,Hypothèses!$D$26)))+(IF(B5=1,Hypothèses!$B$26,IF(B5=2,Hypothèses!$C$26,IF(B5=3,Hypothèses!$D$26,Hypothèses!$D$26)))-(IF(B5=1,0,IF(B5=2,Hypothèses!$B$26,IF(B5=3,Hypothèses!$C$26,Hypothèses!$D$26)))))*((A5)-INT((A5-1)/12)*12)/12)*$B$1 -> 0.58333333 | H5: =(IF(B5=1,0,IF(B5=2,Hypothèses!$B$27,IF(B5=3,Hypothèses!$C$27,Hypothèses!$D$27)))+(IF(B5=1,Hypothèses!$B$27,IF(B5=2,Hypothèses!$C$27,IF(B5=3,Hypothèses!$D$27,Hypothèses!$D$27)))-(IF(B5=1,0,IF(B5=2,Hypothèses!$B$27,IF(B5=3,Hypothèses!$C$27,Hypothèses!$D$27)))))*((A5)-INT((A5-1)/12)*12)/12)*$B$1 -> 1.1666667 | I5: =(IF(B5=1,0,IF(B5=2,Hypothèses!$B$28,IF(B5=3,Hypothèses!$C$28,Hypothèses!$D$28)))+(IF(B5=1,Hypothèses!$B$28,IF(B5=2,Hypothèses!$C$28,IF(B5=3,Hypothèses!$D$28,Hypothèses!$D$28)))-(IF(B5=1,0,IF(B5=2,Hypothèses!$B$28,IF(B5=3,Hypothèses!$C$28,Hypothèses!$D$28)))))*((A5)-INT((A5-1)/12)*12)/12)*$B$1 -> 0 | J5: =(IF(B5=1,0,IF(B5=2,Hypothèses!$B$29,IF(B5=3,Hypothèses!$C$29,Hypothèses!$D$29)))+(IF(B5=1,Hypothèses!$B$29,IF(B5=2,Hypothèses!$C$29,IF(B5=3,Hypothèses!$D$29,Hypothèses!$D$29)))-(IF(B5=1,0,IF(B5=2,Hypothèses!$B$29,IF(B5=3,Hypothèses!$C$29,Hypothèses!$D$29)))))*((A5)-INT((A5-1)/12)*12)/12)*$B$1 -> 0 | K5: =IF(A5<Hypothèses!$B$7,0,Hypothèses!$B$8*(1-Hypothèses!$B$9)^(A5-Hypothèses!$B$7)) -> 0 | L5: =C5+D5+E5+F5 -> 0.9 | M5: =(C5*Hypothèses!$B$11+D5*Hypothèses!$B$12+E5*Hypothèses!$B$13+F5*Hypothèses!$B$14)*(IF(B5=1,Hypothèses!$B$20,IF(B5=2,Hypothèses!$B$21,Hypothèses!$B$22))+(1-(IF(B5=1,Hypothèses!$B$20,IF(B5=2,Hypothèses!$B$21,Hypothèses!$B$22))))*11/12) -> 112.23 | N5: =L5*IF(B5=1,Hypothèses!$C$20,IF(B5=2,Hypothèses!$C$21,Hypothèses!$C$22))*IF(B5=1,Hypothèses!$D$20,IF(B5=2,Hypothèses!$D$21,Hypothèses!$D$22)) -> 0.9 | O5: =IF(A5=18,IF($B$2>=1,Hypothèses!$B$33,0),IF(AND(OR(A5=30,A5=34),$D$2>=1),Hypothèses!$B$34*MIN(1,$D$2/3),0)) -> 0 | P5: =M5+N5+O5 -> 113.13 | Q5: =P5/(1+Hypothèses!$B$6) -> 94.275 | R5: =Hypothèses!$B$3*(1+Hypothèses!$B$4)^INT((A5-1)/3) -> 500 | S5: =0 -> 0 | T5: =S5*Hypothèses!$B$17 -> 0 | U5: =Q5*Hypothèses!$B$5 -> 0.94275 | V5: =Q5-R5-T5-U5 -> -406.66775 | W5: =W4+V5 -> 1224.443
A6: 3 | B6: =INT((A6-1)/12)+1 -> 1 | C6: =ROUND(IF(MOD($A6,12)=0,G6,(IF(6=4,0,C5))*(1-$K6)+IF((IF(6=4,0,C5))*(1-$K6)<G6,(G6-(IF(6=4,0,C5))*(1-$K6))*Hypothèses!$B$10,0)),1) -> 0.5 | D6: =ROUND(IF(MOD($A6,12)=0,H6,(IF(6=4,0,D5))*(1-$K6)+IF((IF(6=4,0,D5))*(1-$K6)<H6,(H6-(IF(6=4,0,D5))*(1-$K6))*Hypothèses!$B$10,0)),1) -> 1.1 | E6: =ROUND(IF(MOD($A6,12)=0,I6,(IF(6=4,0,E5))*(1-$K6)+IF((IF(6=4,0,E5))*(1-$K6)<I6,(I6-(IF(6=4,0,E5))*(1-$K6))*Hypothèses!$B$10,0)),1) -> 0 | F6: =ROUND(IF(MOD($A6,12)=0,J6,(IF(6=4,0,F5))*(1-$K6)+IF((IF(6=4,0,F5))*(1-$K6)<J6,(J6-(IF(6=4,0,F5))*(1-$K6))*Hypothèses!$B$10,0)),1) -> 0 | G6: =(IF(B6=1,0,IF(B6=2,Hypothèses!$B$26,IF(B6=3,Hypothèses!$C$26,Hypothèses!$D$26)))+(IF(B6=1,Hypothèses!$B$26,IF(B6=2,Hypothèses!$C$26,IF(B6=3,Hypothèses!$D$26,Hypothèses!$D$26)))-(IF(B6=1,0,IF(B6=2,Hypothèses!$B$26,IF(B6=3,Hypothèses!$C$26,Hypothèses!$D$26)))))*((A6)-INT((A6-1)/12)*12)/12)*$B$1 -> 0.875 | H6: =(IF(B6=1,0,IF(B6=2,Hypothèses!$B$27,IF(B6=3,Hypothèses!$C$27,Hypothèses!$D$27)))+(IF(B6=1,Hypothèses!$B$27,IF(B6=2,Hypothèses!$C$27,IF(B6=3,Hypothèses!$D$27,Hypothèses!$D$27)))-(IF(B6=1,0,IF(B6=2,Hypothèses!$B$27,IF(B6=3,Hypothèses!$C$27,Hypothèses!$D$27)))))*((A6)-INT((A6-1)/12)*12)/12)*$B$1 -> 1.75 | I6: =(IF(B6=1,0,IF(B6=2,Hypothèses!$B$28,IF(B6=3,Hypothèses!$C$28,Hypothèses!$D$28)))+(IF(B6=1,Hypothèses!$B$28,IF(B6=2,Hypothèses!$C$28,IF(B6=3,Hypothèses!$D$28,Hypothèses!$D$28)))-(IF(B6=1,0,IF(B6=2,Hypothèses!$B$28,IF(B6=3,Hypothèses!$C$28,Hypothèses!$D$28)))))*((A6)-INT((A6-1)/12)*12)/12)*$B$1 -> 0 | J6: =(IF(B6=1,0,IF(B6=2,Hypothèses!$B$29,IF(B6=3,Hypothèses!$C$29,Hypothèses!$D$29)))+(IF(B6=1,Hypothèses!$B$29,IF(B6=2,Hypothèses!$C$29,IF(B6=3,Hypothèses!$D$29,Hypothèses!$D$29)))-(IF(B6=1,0,IF(B6=2,Hypothèses!$B$29,IF(B6=3,Hypothèses!$C$29,Hypothèses!$D$29)))))*((A6)-INT((A6-1)/12)*12)/12)*$B$1 -> 0 | K6: =IF(A6<Hypothèses!$B$7,0,Hypothèses!$B$8*(1-Hypothèses!$B$9)^(A6-Hypothèses!$B$7)) -> 0 | L6: =C6+D6+E6+F6 -> 1.6 | M6: =(C6*Hypothèses!$B$11+D6*Hypothèses!$B$12+E6*Hypothèses!$B$13+F6*Hypothèses!$B$14)*(IF(B6=1,Hypothèses!$B$20,IF(B6=2,Hypothèses!$B$21,Hypothèses!$B$22))+(1-(IF(B6=1,Hypothèses!$B$20,IF(B6=2,Hypothèses!$B$21,Hypothèses!$B$22))))*11/12) -> 201.45333 | N6: =L6*IF(B6=1,Hypothèses!$C$20,IF(B6=2,Hypothèses!$C$21,Hypothèses!$C$22))*IF(B6=1,Hypothèses!$D$20,IF(B6=2,Hypothèses!$D$21,Hypothèses!$D$22)) -> 1.6 | O6: =IF(A6=18,IF($B$2>=1,Hypothèses!$B$33,0),IF(AND(OR(A6=30,A6=34),$D$2>=1),Hypothèses!$B$34*MIN(1,$D$2/3),0)) -> 0 | P6: =M6+N6+O6 -> 203.05333 | Q6: =P6/(1+Hypothèses!$B$6) -> 169.21111 | R6: =Hypothèses!$B$3*(1+Hypothèses!$B$4)^INT((A6-1)/3) -> 500 | S6: =0 -> 0 | T6: =S6*Hypothèses!$B$17 -> 0 | U6: =Q6*Hypothèses!$B$5 -> 1.6921111 | V6: =Q6-R6-T6-U6 -> -332.481 | W6: =W5+V6 -> 891.962
A7: 4 | B7: =INT((A7-1)/12)+1 -> 1 | C7: =ROUND(IF(MOD($A7,12)=0,G7,(IF(7=4,0,C6))*(1-$K7)+IF((IF(7=4,0,C6))*(1-$K7)<G7,(G7-(IF(7=4,0,C6))*(1-$K7))*Hypothèses!$B$10,0)),1) -> 0.8 | D7: =ROUND(IF(MOD($A7,12)=0,H7,(IF(7=4,0,D6))*(1-$K7)+IF((IF(7=4,0,D6))*(1-$K7)<H7,(H7-(IF(7=4,0,D6))*(1-$K7))*Hypothèses!$B$10,0)),1) -> 1.6 | E7: =ROUND(IF(MOD($A7,12)=0,I7,(IF(7=4,0,E6))*(1-$K7)+IF((IF(7=4,0,E6))*(1-$K7)<I7,(I7-(IF(7=4,0,E6))*(1-$K7))*Hypothèses!$B$10,0)),1) -> 0 | F7: =ROUND(IF(MOD($A7,12)=0,J7,(IF(7=4,0,F6))*(1-$K7)+IF((IF(7=4,0,F6))*(1-$K7)<J7,(J7-(IF(7=4,0,F6))*(1-$K7))*Hypothèses!$B$10,0)),1) -> 0 | G7: =(IF(B7=1,0,IF(B7=2,Hypothèses!$B$26,IF(B7=3,Hypothèses!$C$26,Hypothèses!$D$26)))+(IF(B7=1,Hypothèses!$B$26,IF(B7=2,Hypothèses!$C$26,IF(B7=3,Hypothèses!$D$26,Hypothèses!$D$26)))-(IF(B7=1,0,IF(B7=2,Hypothèses!$B$26,IF(B7=3,Hypothèses!$C$26,Hypothèses!$D$26)))))*((A7)-INT((A7-1)/12)*12)/12)*$B$1 -> 1.1666667 | H7: =(IF(B7=1,0,IF(B7=2,Hypothèses!$B$27,IF(B7=3,Hypothèses!$C$27,Hypothèses!$D$27)))+(IF(B7=1,Hypothèses!$B$27,IF(B7=2,Hypothèses!$C$27,IF(B7=3,Hypothèses!$D$27,Hypothèses!$D$27)))-(IF(B7=1,0,IF(B7=2,Hypothèses!$B$27,IF(B7=3,Hypothèses!$C$27,Hypothèses!$D$27)))))*((A7)-INT((A7-1)/12)*12)/12)*$B$1 -> 2.3333333 | I7: =(IF(B7=1,0,IF(B7=2,Hypothèses!$B$28,IF(B7=3,Hypothèses!$C$28,Hypothèses!$D$28)))+(IF(B7=1,Hypothèses!$B$28,IF(B7=2,Hypothèses!$C$28,IF(B7=3,Hypothèses!$D$28,Hypothèses!$D$28)))-(IF(B7=1,0,IF(B7=2,Hypothèses!$B$28,IF(B7=3,Hypothèses!$C$28,Hypothèses!$D$28)))))*((A7)-INT((A7-1)/12)*12)/12)*$B$1 -> 0 | J7: =(IF(B7=1,0,IF(B7=2,Hypothèses!$B$29,IF(B7=3,Hypothèses!$C$29,Hypothèses!$D$29)))+(IF(B7=1,Hypothèses!$B$29,IF(B7=2,Hypothèses!$C$29,IF(B7=3,Hypothèses!$D$29,Hypothèses!$D$29)))-(IF(B7=1,0,IF(B7=2,Hypothèses!$B$29,IF(B7=3,Hypothèses!$C$29,Hypothèses!$D$29)))))*((A7)-INT((A7-1)/12)*12)/12)*$B$1 -> 0 | K7: =IF(A7<Hypothèses!$B$7,0,Hypothèses!$B$8*(1-Hypothèses!$B$9)^(A7-Hypothèses!$B$7)) -> 0 | L7: =C7+D7+E7+F7 -> 2.4 | M7: =(C7*Hypothèses!$B$11+D7*Hypothèses!$B$12+E7*Hypothèses!$B$13+F7*Hypothèses!$B$14)*(IF(B7=1,Hypothèses!$B$20,IF(B7=2,Hypothèses!$B$21,Hypothèses!$B$22))+(1-(IF(B7=1,Hypothèses!$B$20,IF(B7=2,Hypothèses!$B$21,Hypothèses!$B$22))))*11/12) -> 299.28 | N7: =L7*IF(B7=1,Hypothèses!$C$20,IF(B7=2,Hypothèses!$C$21,Hypothèses!$C$22))*IF(B7=1,Hypothèses!$D$20,IF(B7=2,Hypothèses!$D$21,Hypothèses!$D$22)) -> 2.4 | O7: =IF(A7=18,IF($B$2>=1,Hypothèses!$B$33,0),IF(AND(OR(A7=30,A7=34),$D$2>=1),Hypothèses!$B$34*MIN(1,$D$2/3),0)) -> 0 | P7: =M7+N7+O7 -> 301.68 | Q7: =P7/(1+Hypothèses!$B$6) -> 251.4 | R7: =Hypothèses!$B$3*(1+Hypothèses!$B$4)^INT((A7-1)/3) -> 575 | S7: =0 -> 0 | T7: =S7*Hypothèses!$B$17 -> 0 | U7: =Q7*Hypothèses!$B$5 -> 2.514 | V7: =Q7-R7-T7-U7 -> -326.114 | W7: =W6+V7 -> 565.848
A8: 5 | B8: =INT((A8-1)/12)+1 -> 1 | C8: =ROUND(IF(MOD($A8,12)=0,G8,(IF(8=4,0,C7))*(1-$K8)+IF((IF(8=4,0,C7))*(1-$K8)<G8,(G8-(IF(8=4,0,C7))*(1-$K8))*Hypothèses!$B$10,0)),1) -> 1.1 | D8: =ROUND(IF(MOD($A8,12)=0,H8,(IF(8=4,0,D7))*(1-$K8)+IF((IF(8=4,0,D7))*(1-$K8)<H8,(H8-(IF(8=4,0,D7))*(1-$K8))*Hypothèses!$B$10,0)),1) -> 2.1 | E8: =ROUND(IF(MOD($A8,12)=0,I8,(IF(8=4,0,E7))*(1-$K8)+IF((IF(8=4,0,E7))*(1-$K8)<I8,(I8-(IF(8=4,0,E7))*(1-$K8))*Hypothèses!$B$10,0)),1) -> 0 | F8: =ROUND(IF(MOD($A8,12)=0,J8,(IF(8=4,0,F7))*(1-$K8)+IF((IF(8=4,0,F7))*(1-$K8)<J8,(J8-(IF(8=4,0,F7))*(1-$K8))*Hypothèses!$B$10,0)),1) -> 0 | G8: =(IF(B8=1,0,IF(B8=2,Hypothèses!$B$26,IF(B8=3,Hypothèses!$C$26,Hypothèses!$D$26)))+(IF(B8=1,Hypothèses!$B$26,IF(B8=2,Hypothèses!$C$26,IF(B8=3,Hypothèses!$D$26,Hypothèses!$D$26)))-(IF(B8=1,0,IF(B8=2,Hypothèses!$B$26,IF(B8=3,Hypothèses!$C$26,Hypothèses!$D$26)))))*((A8)-INT((A8-1)/12)*12)/12)*$B$1 -> 1.4583333 | H8: =(IF(B8=1,0,IF(B8=2,Hypothèses!$B$27,IF(B8=3,Hypothèses!$C$27,Hypothèses!$D$27)))+(IF(B8=1,Hypothèses!$B$27,IF(B8=2,Hypothèses!$C$27,IF(B8=3,Hypothèses!$D$27,Hypothèses!$D$27)))-(IF(B8=1,0,IF(B8=2,Hypothèses!$B$27,IF(B8=3,Hypothèses!$C$27,Hypothèses!$D$27)))))*((A8)-INT((A8-1)/12)*12)/12)*$B$1 -> 2.9166667 | I8: =(IF(B8=1,0,IF(B8=2,Hypothèses!$B$28,IF(B8=3,Hypothèses!$C$28,Hypothèses!$D$28)))+(IF(B8=1,Hypothèses!$B$28,IF(B8=2,Hypothèses!$C$28,IF(B8=3,Hypothèses!$D$28,Hypothèses!$D$28)))-(IF(B8=1,0,IF(B8=2,Hypothèses!$B$28,IF(B8=3,Hypothèses!$C$28,Hypothèses!$D$28)))))*((A8)-INT((A8-1)/12)*12)/12)*$B$1 -> 0 | J8: =(IF(B8=1,0,IF(B8=2,Hypothèses!$B$29,IF(B8=3,Hypothèses!$C$29,Hypothèses!$D$29)))+(IF(B8=1,Hypothèses!$B$29,IF(B8=2,Hypothèses!$C$29,IF(B8=3,Hypothèses!$D$29,Hypothèses!$D$29)))-(IF(B8=1,0,IF(B8=2,Hypothèses!$B$29,IF(B8=3,Hypothèses!$C$29,Hypothèses!$D$29)))))*((A8)-INT((A8-1)/12)*12)/12)*$B$1 -> 0 | K8: =IF(A8<Hypothèses!$B$7,0,Hypothèses!$B$8*(1-Hypothèses!$B$9)^(A8-Hypothèses!$B$7)) -> 0 | L8: =C8+D8+E8+F8 -> 3.2 | M8: =(C8*Hypothèses!$B$11+D8*Hypothèses!$B$12+E8*Hypothèses!$B$13+F8*Hypothèses!$B$14)*(IF(B8=1,Hypothèses!$B$20,IF(B8=2,Hypothèses!$B$21,Hypothèses!$B$22))+(1-(IF(B8=1,Hypothèses!$B$20,IF(B8=2,Hypothèses!$B$21,Hypothèses!$B$22))))*11/12) -> 397.10667 | N8: =L8*IF(B8=1,Hypothèses!$C$20,IF(B8=2,Hypothèses!$C$21,Hypothèses!$C$22))*IF(B8=1,Hypothèses!$D$20,IF(B8=2,Hypothèses!$D$21,Hypothèses!$D$22)) -> 3.2 | O8: =IF(A8=18,IF($B$2>=1,Hypothèses!$B$33,0),IF(AND(OR(A8=30,A8=34),$D$2>=1),Hypothèses!$B$34*MIN(1,$D$2/3),0)) -> 0 | P8: =M8+N8+O8 -> 400.30667 | Q8: =P8/(1+Hypothèses!$B$6) -> 333.58889 | R8: =Hypothèses!$B$3*(1+Hypothèses!$B$4)^INT((A8-1)/3) -> 575 | S8: =0 -> 0 | T8: =S8*Hypothèses!$B$17 -> 0 | U8: =Q8*Hypothèses!$B$5 -> 3.3358889 | V8: =Q8-R8-T8-U8 -> -244.747 | W8: =W7+V8 -> 321.101
A9: 6 | B9: =INT((A9-1)/12)+1 -> 1 | C9: =ROUND(IF(MOD($A9,12)=0,G9,(IF(9=4,0,C8))*(1-$K9)+IF((IF(9=4,0,C8))*(1-$K9)<G9,(G9-(IF(9=4,0,C8))*(1-$K9))*Hypothèses!$B$10,0)),1) -> 1.4 | D9: =ROUND(IF(MOD($A9,12)=0,H9,(IF(9=4,0,D8))*(1-$K9)+IF((IF(9=4,0,D8))*(1-$K9)<H9,(H9-(IF(9=4,0,D8))*(1-$K9))*Hypothèses!$B$10,0)),1) -> 2.7 | E9: =ROUND(IF(MOD($A9,12)=0,I9,(IF(9=4,0,E8))*(1-$K9)+IF((IF(9=4,0,E8))*(1-$K9)<I9,(I9-(IF(9=4,0,E8))*(1-$K9))*Hypothèses!$B$10,0)),1) -> 0 | F9: =ROUND(IF(MOD($A9,12)=0,J9,(IF(9=4,0,F8))*(1-$K9)+IF((IF(9=4,0,F8))*(1-$K9)<J9,(J9-(IF(9=4,0,F8))*(1-$K9))*Hypothèses!$B$10,0)),1) -> 0 | G9: =(IF(B9=1,0,IF(B9=2,Hypothèses!$B$26,IF(B9=3,Hypothèses!$C$26,Hypothèses!$D$26)))+(IF(B9=1,Hypothèses!$B$26,IF(B9=2,Hypothèses!$C$26,IF(B9=3,Hypothèses!$D$26,Hypothèses!$D$26)))-(IF(B9=1,0,IF(B9=2,Hypothèses!$B$26,IF(B9=3,Hypothèses!$C$26,Hypothèses!$D$26)))))*((A9)-INT((A9-1)/12)*12)/12)*$B$1 -> 1.75 | H9: =(IF(B9=1,0,IF(B9=2,Hypothèses!$B$27,IF(B9=3,Hypothèses!$C$27,Hypothèses!$D$27)))+(IF(B9=1,Hypothèses!$B$27,IF(B9=2,Hypothèses!$C$27,IF(B9=3,Hypothèses!$D$27,Hypothèses!$D$27)))-(IF(B9=1,0,IF(B9=2,Hypothèses!$B$27,IF(B9=3,Hypothèses!$C$27,Hypothèses!$D$27)))))*((A9)-INT((A9-1)/12)*12)/12)*$B$1 -> 3.5 | I9: =(IF(B9=1,0,IF(B9=2,Hypothèses!$B$28,IF(B9=3,Hypothèses!$C$28,Hypothèses!$D$28)))+(IF(B9=1,Hypothèses!$B$28,IF(B9=2,Hypothèses!$C$28,IF(B9=3,Hypothèses!$D$28,Hypothèses!$D$28)))-(IF(B9=1,0,IF(B9=2,Hypothèses!$B$28,IF(B9=3,Hypothèses!$C$28,Hypothèses!$D$28)))))*((A9)-INT((A9-1)/12)*12)/12)*$B$1 -> 0 | J9: =(IF(B9=1,0,IF(B9=2,Hypothèses!$B$29,IF(B9=3,Hypothèses!$C$29,Hypothèses!$D$29)))+(IF(B9=1,Hypothèses!$B$29,IF(B9=2,Hypothèses!$C$29,IF(B9=3,Hypothèses!$D$29,Hypothèses!$D$29)))-(IF(B9=1,0,IF(B9=2,Hypothèses!$B$29,IF(B9=3,Hypothèses!$C$29,Hypothèses!$D$29)))))*((A9)-INT((A9-1)/12)*12)/12)*$B$1 -> 0 | K9: =IF(A9<Hypothèses!$B$7,0,Hypothèses!$B$8*(1-Hypothèses!$B$9)^(A9-Hypothèses!$B$7)) -> 0 | L9: =C9+D9+E9+F9 -> 4.1 | M9: =(C9*Hypothèses!$B$11+D9*Hypothèses!$B$12+E9*Hypothèses!$B$13+F9*Hypothèses!$B$14)*(IF(B9=1,Hypothèses!$B$20,IF(B9=2,Hypothèses!$B$21,Hypothèses!$B$22))+(1-(IF(B9=1,Hypothèses!$B$20,IF(B9=2,Hypothèses!$B$21,Hypothèses!$B$22))))*11/12) -> 509.33667 | N9: =L9*IF(B9=1,Hypothèses!$C$20,IF(B9=2,Hypothèses!$C$21,Hypothèses!$C$22))*IF(B9=1,Hypothèses!$D$20,IF(B9=2,Hypothèses!$D$21,Hypothèses!$D$22)) -> 4.1 | O9: =IF(A9=18,IF($B$2>=1,Hypothèses!$B$33,0),IF(AND(OR(A9=30,A9=34),$D$2>=1),Hypothèses!$B$34*MIN(1,$D$2/3),0)) -> 0 | P9: =M9+N9+O9 -> 513.43667 | Q9: =P9/(1+Hypothèses!$B$6) -> 427.86389 | R9: =Hypothèses!$B$3*(1+Hypothèses!$B$4)^INT((A9-1)/3) -> 575 | S9: =0 -> 0 | T9: =S9*Hypothèses!$B$17 -> 0 | U9: =Q9*Hypothèses!$B$5 -> 4.2786389 | V9: =Q9-R9-T9-U9 -> -151.41475 | W9: =W8+V9 -> 169.68625
A10: 7 | B10: =INT((A10-1)/12)+1 -> 1 | C10: =ROUND(IF(MOD($A10,12)=0,G10,(IF(10=4,0,C9))*(1-$K10)+IF((IF(10=4,0,C9))*(1-$K10)<G10,(G10-(IF(10=4,0,C9))*(1-$K10))*Hypothèses!$B$10,0)),1) -> 1.7 | D10: =ROUND(IF(MOD($A10,12)=0,H10,(IF(10=4,0,D9))*(1-$K10)+IF((IF(10=4,0,D9))*(1-$K10)<H10,(H10-(IF(10=4,0,D9))*(1-$K10))*Hypothèses!$B$10,0)),1) -> 3.3 | E10: =ROUND(IF(MOD($A10,12)=0,I10,(IF(10=4,0,E9))*(1-$K10)+IF((IF(10=4,0,E9))*(1-$K10)<I10,(I10-(IF(10=4,0,E9))*(1-$K10))*Hypothèses!$B$10,0)),1) -> 0 | F10: =ROUND(IF(MOD($A10,12)=0,J10,(IF(10=4,0,F9))*(1-$K10)+IF((IF(10=4,0,F9))*(1-$K10)<J10,(J10-(IF(10=4,0,F9))*(1-$K10))*Hypothèses!$B$10,0)),1) -> 0 | G10: =(IF(B10=1,0,IF(B10=2,Hypothèses!$B$26,IF(B10=3,Hypothèses!$C$26,Hypothèses!$D$26)))+(IF(B10=1,Hypothèses!$B$26,IF(B10=2,Hypothèses!$C$26,IF(B10=3,Hypothèses!$D$26,Hypothèses!$D$26)))-(IF(B10=1,0,IF(B10=2,Hypothèses!$B$26,IF(B10=3,Hypothèses!$C$26,Hypothèses!$D$26)))))*((A10)-INT((A10-1)/12)*12)/12)*$B$1 -> 2.0416667 | H10: =(IF(B10=1,0,IF(B10=2,Hypothèses!$B$27,IF(B10=3,Hypothèses!$C$27,Hypothèses!$D$27)))+(IF(B10=1,Hypothèses!$B$27,IF(B10=2,Hypothèses!$C$27,IF(B10=3,Hypothèses!$D$27,Hypothèses!$D$27)))-(IF(B10=1,0,IF(B10=2,Hypothèses!$B$27,IF(B10=3,Hypothèses!$C$27,Hypothèses!$D$27)))))*((A10)-INT((A10-1)/12)*12)/12)*$B$1 -> 4.0833333 | I10: =(IF(B10=1,0,IF(B10=2,Hypothèses!$B$28,IF(B10=3,Hypothèses!$C$28,Hypothèses!$D$28)))+(IF(B10=1,Hypothèses!$B$28,IF(B10=2,Hypothèses!$C$28,IF(B10=3,Hypothèses!$D$28,Hypothèses!$D$28)))-(IF(B10=1,0,IF(B10=2,Hypothèses!$B$28,IF(B10=3,Hypothèses!$C$28,Hypothèses!$D$28)))))*((A10)-INT((A10-1)/12)*12)/12)*$B$1 -> 0 | J10: =(IF(B10=1,0,IF(B10=2,Hypothèses!$B$29,IF(B10=3,Hypothèses!$C$29,Hypothèses!$D$29)))+(IF(B10=1,Hypothèses!$B$29,IF(B10=2,Hypothèses!$C$29,IF(B10=3,Hypothèses!$D$29,Hypothèses!$D$29)))-(IF(B10=1,0,IF(B10=2,Hypothèses!$B$29,IF(B10=3,Hypothèses!$C$29,Hypothèses!$D$29)))))*((A10)-INT((A10-1)/12)*12)/12)*$B$1 -> 0 | K10: =IF(A10<Hypothèses!$B$7,0,Hypothèses!$B$8*(1-Hypothèses!$B$9)^(A10-Hypothèses!$B$7)) -> 0 | L10: =C10+D10+E10+F10 -> 5 | M10: =(C10*Hypothèses!$B$11+D10*Hypothèses!$B$12+E10*Hypothèses!$B$13+F10*Hypothèses!$B$14)*(IF(B10=1,Hypothèses!$B$20,IF(B10=2,Hypothèses!$B$21,Hypothèses!$B$22))+(1-(IF(B10=1,Hypothèses!$B$20,IF(B10=2,Hypothèses!$B$21,Hypothèses!$B$22))))*11/12) -> 621.56667 | N10: =L10*IF(B10=1,Hypothèses!$C$20,IF(B10=2,Hypothèses!$C$21,Hypothèses!$C$22))*IF(B10=1,Hypothèses!$D$20,IF(B10=2,Hypothèses!$D$21,Hypothèses!$D$22)) -> 5 | O10: =IF(A10=18,IF($B$2>=1,Hypothèses!$B$33,0),IF(AND(OR(A10=30,A10=34),$D$2>=1),Hypothèses!$B$34*MIN(1,$D$2/3),0)) -> 0 | P10: =M10+N10+O10 -> 626.56667 | Q10: =P10/(1+Hypothèses!$B$6) -> 522.13889 | R10: =Hypothèses!$B$3*(1+Hypothèses!$B$4)^INT((A10-1)/3) -> 661.25 | S10: =0 -> 0 | T10: =S10*Hypothèses!$B$17 -> 0 | U10: =Q10*Hypothèses!$B$5 -> 5.2213889 | V10: =Q10-R10-T10-U10 -> -144.3325 | W10: =W9+V10 -> 25.35375
A11: 8 | B11: =INT((A11-1)/12)+1 -> 1 | C11: =ROUND(IF(MOD($A11,12)=0,G11,(IF(11=4,0,C10))*(1-$K11)+IF((IF(11=4,0,C10))*(1-$K11)<G11,(G11-(IF(11=4,0,C10))*(1-$K11))*Hypothèses!$B$10,0)),1) -> 2 | D11: =ROUND(IF(MOD($A11,12)=0,H11,(IF(11=4,0,D10))*(1-$K11)+IF((IF(11=4,0,D10))*(1-$K11)<H11,(H11-(IF(11=4,0,D10))*(1-$K11))*Hypothèses!$B$10,0)),1) -> 3.8 | E11: =ROUND(IF(MOD($A11,12)=0,I11,(IF(11=4,0,E10))*(1-$K11)+IF((IF(11=4,0,E10))*(1-$K11)<I11,(I11-(IF(11=4,0,E10))*(1-$K11))*Hypothèses!$B$10,0)),1) -> 0 | F11: =ROUND(IF(MOD($A11,12)=0,J11,(IF(11=4,0,F10))*(1-$K11)+IF((IF(11=4,0,F10))*(1-$K11)<J11,(J11-(IF(11=4,0,F10))*(1-$K11))*Hypothèses!$B$10,0)),1) -> 0 | G11: =(IF(B11=1,0,IF(B11=2,Hypothèses!$B$26,IF(B11=3,Hypothèses!$C$26,Hypothèses!$D$26)))+(IF(B11=1,Hypothèses!$B$26,IF(B11=2,Hypothèses!$C$26,IF(B11=3,Hypothèses!$D$26,Hypothèses!$D$26)))-(IF(B11=1,0,IF(B11=2,Hypothèses!$B$26,IF(B11=3,Hypothèses!$C$26,Hypothèses!$D$26)))))*((A11)-INT((A11-1)/12)*12)/12)*$B$1 -> 2.3333333 | H11: =(IF(B11=1,0,IF(B11=2,Hypothèses!$B$27,IF(B11=3,Hypothèses!$C$27,Hypothèses!$D$27)))+(IF(B11=1,Hypothèses!$B$27,IF(B11=2,Hypothèses!$C$27,IF(B11=3,Hypothèses!$D$27,Hypothèses!$D$27)))-(IF(B11=1,0,IF(B11=2,Hypothèses!$B$27,IF(B11=3,Hypothèses!$C$27,Hypothèses!$D$27)))))*((A11)-INT((A11-1)/12)*12)/12)*$B$1 -> 4.6666667 | I11: =(IF(B11=1,0,IF(B11=2,Hypothèses!$B$28,IF(B11=3,Hypothèses!$C$28,Hypothèses!$D$28)))+(IF(B11=1,Hypothèses!$B$28,IF(B11=2,Hypothèses!$C$28,IF(B11=3,Hypothèses!$D$28,Hypothèses!$D$28)))-(IF(B11=1,0,IF(B11=2,Hypothèses!$B$28,IF(B11=3,Hypothèses!$C$28,Hypothèses!$D$28)))))*((A11)-INT((A11-1)/12)*12)/12)*$B$1 -> 0 | J11: =(IF(B11=1,0,IF(B11=2,Hypothèses!$B$29,IF(B11=3,Hypothèses!$C$29,Hypothèses!$D$29)))+(IF(B11=1,Hypothèses!$B$29,IF(B11=2,Hypothèses!$C$29,IF(B11=3,Hypothèses!$D$29,Hypothèses!$D$29)))-(IF(B11=1,0,IF(B11=2,Hypothèses!$B$29,IF(B11=3,Hypothèses!$C$29,Hypothèses!$D$29)))))*((A11)-INT((A11-1)/12)*12)/12)*$B$1 -> 0 | K11: =IF(A11<Hypothèses!$B$7,0,Hypothèses!$B$8*(1-Hypothèses!$B$9)^(A11-Hypothèses!$B$7)) -> 0 | L11: =C11+D11+E11+F11 -> 5.8 | M11: =(C11*Hypothèses!$B$11+D11*Hypothèses!$B$12+E11*Hypothèses!$B$13+F11*Hypothèses!$B$14)*(IF(B11=1,Hypothèses!$B$20,IF(B11=2,Hypothèses!$B$21,Hypothèses!$B$22))+(1-(IF(B11=1,Hypothèses!$B$20,IF(B11=2,Hypothèses!$B$21,Hypothèses!$B$22))))*11/12) -> 719.39333 | N11: =L11*IF(B11=1,Hypothèses!$C$20,IF(B11=2,Hypothèses!$C$21,Hypothèses!$C$22))*IF(B11=1,Hypothèses!$D$20,IF(B11=2,Hypothèses!$D$21,Hypothèses!$D$22)) -> 5.8 | O11: =IF(A11=18,IF($B$2>=1,Hypothèses!$B$33,0),IF(AND(OR(A11=30,A11=34),$D$2>=1),Hypothèses!$B$34*MIN(1,$D$2/3),0)) -> 0 | P11: =M11+N11+O11 -> 725.19333 | Q11: =P11/(1+Hypothèses!$B$6) -> 604.32778 | R11: =Hypothèses!$B$3*(1+Hypothèses!$B$4)^INT((A11-1)/3) -> 661.25 | S11: =0 -> 0 | T11: =S11*Hypothèses!$B$17 -> 0 | U11: =Q11*Hypothèses!$B$5 -> 6.0432778 | V11: =Q11-R11-T11-U11 -> -62.9655 | W11: =W10+V11 -> -37.61175
A12: 9 | B12: =INT((A12-1)/12)+1 -> 1 | C12: =ROUND(IF(MOD($A12,12)=0,G12,(IF(12=4,0,C11))*(1-$K12)+IF((IF(12=4,0,C11))*(1-$K12)<G12,(G12-(IF(12=4,0,C11))*(1-$K12))*Hypothèses!$B$10,0)),1) -> 2.2 | D12: =ROUND(IF(MOD($A12,12)=0,H12,(IF(12=4,0,D11))*(1-$K12)+IF((IF(12=4,0,D11))*(1-$K12)<H12,(H12-(IF(12=4,0,D11))*(1-$K12))*Hypothèses!$B$10,0)),1) -> 4.3 | E12: =ROUND(IF(MOD($A12,12)=0,I12,(IF(12=4,0,E11))*(1-$K12)+IF((IF(12=4,0,E11))*(1-$K12)<I12,(I12-(IF(12=4,0,E11))*(1-$K12))*Hypothèses!$B$10,0)),1) -> 0 | F12: =ROUND(IF(MOD($A12,12)=0,J12,(IF(12=4,0,F11))*(1-$K12)+IF((IF(12=4,0,F11))*(1-$K12)<J12,(J12-(IF(12=4,0,F11))*(1-$K12))*Hypothèses!$B$10,0)),1) -> 0 | G12: =(IF(B12=1,0,IF(B12=2,Hypothèses!$B$26,IF(B12=3,Hypothèses!$C$26,Hypothèses!$D$26)))+(IF(B12=1,Hypothèses!$B$26,IF(B12=2,Hypothèses!$C$26,IF(B12=3,Hypothèses!$D$26,Hypothèses!$D$26)))-(IF(B12=1,0,IF(B12=2,Hypothèses!$B$26,IF(B12=3,Hypothèses!$C$26,Hypothèses!$D$26)))))*((A12)-INT((A12-1)/12)*12)/12)*$B$1 -> 2.625 | H12: =(IF(B12=1,0,IF(B12=2,Hypothèses!$B$27,IF(B12=3,Hypothèses!$C$27,Hypothèses!$D$27)))+(IF(B12=1,Hypothèses!$B$27,IF(B12=2,Hypothèses!$C$27,IF(B12=3,Hypothèses!$D$27,Hypothèses!$D$27)))-(IF(B12=1,0,IF(B12=2,Hypothèses!$B$27,IF(B12=3,Hypothèses!$C$27,Hypothèses!$D$27)))))*((A12)-INT((A12-1)/12)*12)/12)*$B$1 -> 5.25 | I12: =(IF(B12=1,0,IF(B12=2,Hypothèses!$B$28,IF(B12=3,Hypothèses!$C$28,Hypothèses!$D$28)))+(IF(B12=1,Hypothèses!$B$28,IF(B12=2,Hypothèses!$C$28,IF(B12=3,Hypothèses!$D$28,Hypothèses!$D$28)))-(IF(B12=1,0,IF(B12=2,Hypothèses!$B$28,IF(B12=3,Hypothèses!$C$28,Hypothèses!$D$28)))))*((A12)-INT((A12-1)/12)*12)/12)*$B$1 -> 0 | J12: =(IF(B12=1,0,IF(B12=2,Hypothèses!$B$29,IF(B12=3,Hypothèses!$C$29,Hypothèses!$D$29)))+(IF(B12=1,Hypothèses!$B$29,IF(B12=2,Hypothèses!$C$29,IF(B12=3,Hypothèses!$D$29,Hypothèses!$D$29)))-(IF(B12=1,0,IF(B12=2,Hypothèses!$B$29,IF(B12=3,Hypothèses!$C$29,Hypothèses!$D$29)))))*((A12)-INT((A12-1)/12)*12)/12)*$B$1 -> 0 | K12: =IF(A12<Hypothèses!$B$7,0,Hypothèses!$B$8*(1-Hypothèses!$B$9)^(A12-Hypothèses!$B$7)) -> 0.05 | L12: =C12+D12+E12+F12 -> 6.5 | M12: =(C12*Hypothèses!$B$11+D12*Hypothèses!$B$12+E12*Hypothèses!$B$13+F12*Hypothèses!$B$14)*(IF(B12=1,Hypothèses!$B$20,IF(B12=2,Hypothèses!$B$21,Hypothèses!$B$22))+(1-(IF(B12=1,Hypothèses!$B$20,IF(B12=2,Hypothèses!$B$21,Hypothèses!$B$22))))*11/12) -> 808.61667 | N12: =L12*IF(B12=1,Hypothèses!$C$20,IF(B12=2,Hypothèses!$C$21,Hypothèses!$C$22))*IF(B12=1,Hypothèses!$D$20,IF(B12=2,Hypothèses!$D$21,Hypothèses!$D$22)) -> 6.5 | O12: =IF(A12=18,IF($B$2>=1,Hypothèses!$B$33,0),IF(AND(OR(A12=30,A12=34),$D$2>=1),Hypothèses!$B$34*MIN(1,$D$2/3),0)) -> 0 | P12: =M12+N12+O12 -> 815.11667 | Q12: =P12/(1+Hypothèses!$B$6) -> 679.26389 | R12: =Hypothèses!$B$3*(1+Hypothèses!$B$4)^INT((A12-1)/3) -> 661.25 | S12: =0 -> 0 | T12: =S12*Hypothèses!$B$17 -> 0 | U12: =Q12*Hypothèses!$B$5 -> 6.7926389 | V12: =Q12-R12-T12-U12 -> 11.22125 | W12: =W11+V12 -> -26.3905
A13: 10 | B13: =INT((A13-1)/12)+1 -> 1 | C13: =ROUND(IF(MOD($A13,12)=0,G13,(IF(13=4,0,C12))*(1-$K13)+IF((IF(13=4,0,C12))*(1-$K13)<G13,(G13-(IF(13=4,0,C12))*(1-$K13))*Hypothèses!$B$10,0)),1) -> 2.4 | D13: =ROUND(IF(MOD($A13,12)=0,H13,(IF(13=4,0,D12))*(1-$K13)+IF((IF(13=4,0,D12))*(1-$K13)<H13,(H13-(IF(13=4,0,D12))*(1-$K13))*Hypothèses!$B$10,0)),1) -> 4.8 | E13: =ROUND(IF(MOD($A13,12)=0,I13,(IF(13=4,0,E12))*(1-$K13)+IF((IF(13=4,0,E12))*(1-$K13)<I13,(I13-(IF(13=4,0,E12))*(1-$K13))*Hypothèses!$B$10,0)),1) -> 0 | F13: =ROUND(IF(MOD($A13,12)=0,J13,(IF(13=4,0,F12))*(1-$K13)+IF((IF(13=4,0,F12))*(1-$K13)<J13,(J13-(IF(13=4,0,F12))*(1-$K13))*Hypothèses!$B$10,0)),1) -> 0 | G13: =(IF(B13=1,0,IF(B13=2,Hypothèses!$B$26,IF(B13=3,Hypothèses!$C$26,Hypothèses!$D$26)))+(IF(B13=1,Hypothèses!$B$26,IF(B13=2,Hypothèses!$C$26,IF(B13=3,Hypothèses!$D$26,Hypothèses!$D$26)))-(IF(B13=1,0,IF(B13=2,Hypothèses!$B$26,IF(B13=3,Hypothèses!$C$26,Hypothèses!$D$26)))))*((A13)-INT((A13-1)/12)*12)/12)*$B$1 -> 2.9166667 | H13: =(IF(B13=1,0,IF(B13=2,Hypothèses!$B$27,IF(B13=3,Hypothèses!$C$27,Hypothèses!$D$27)))+(IF(B13=1,Hypothèses!$B$27,IF(B13=2,Hypothèses!$C$27,IF(B13=3,Hypothèses!$D$27,Hypothèses!$D$27)))-(IF(B13=1,0,IF(B13=2,Hypothèses!$B$27,IF(B13=3,Hypothèses!$C$27,Hypothèses!$D$27)))))*((A13)-INT((A13-1)/12)*12)/12)*$B$1 -> 5.8333333 | I13: =(IF(B13=1,0,IF(B13=2,Hypothèses!$B$28,IF(B13=3,Hypothèses!$C$28,Hypothèses!$D$28)))+(IF(B13=1,Hypothèses!$B$28,IF(B13=2,Hypothèses!$C$28,IF(B13=3,Hypothèses!$D$28,Hypothèses!$D$28)))-(IF(B13=1,0,IF(B13=2,Hypothèses!$B$28,IF(B13=3,Hypothèses!$C$28,Hypothèses!$D$28)))))*((A13)-INT((A13-1)/12)*12)/12)*$B$1 -> 0 | J13: =(IF(B13=1,0,IF(B13=2,Hypothèses!$B$29,IF(B13=3,Hypothèses!$C$29,Hypothèses!$D$29)))+(IF(B13=1,Hypothèses!$B$29,IF(B13=2,Hypothèses!$C$29,IF(B13=3,Hypothèses!$D$29,Hypothèses!$D$29)))-(IF(B13=1,0,IF(B13=2,Hypothèses!$B$29,IF(B13=3,Hypothèses!$C$29,Hypothèses!$D$29)))))*((A13)-INT((A13-1)/12)*12)/12)*$B$1 -> 0 | K13: =IF(A13<Hypothèses!$B$7,0,Hypothèses!$B$8*(1-Hypothèses!$B$9)^(A13-Hypothèses!$B$7)) -> 0.045 | L13: =C13+D13+E13+F13 -> 7.2 | M13: =(C13*Hypothèses!$B$11+D13*Hypothèses!$B$12+E13*Hypothèses!$B$13+F13*Hypothèses!$B$14)*(IF(B13=1,Hypothèses!$B$20,IF(B13=2,Hypothèses!$B$21,Hypothèses!$B$22))+(1-(IF(B13=1,Hypothèses!$B$20,IF(B13=2,Hypothèses!$B$21,Hypothèses!$B$22))))*11/12) -> 897.84 | N13: =L13*IF(B13=1,Hypothèses!$C$20,IF(B13=2,Hypothèses!$C$21,Hypothèses!$C$22))*IF(B13=1,Hypothèses!$D$20,IF(B13=2,Hypothèses!$D$21,Hypothèses!$D$22)) -> 7.2 | O13: =IF(A13=18,IF($B$2>=1,Hypothèses!$B$33,0),IF(AND(OR(A13=30,A13=34),$D$2>=1),Hypothèses!$B$34*MIN(1,$D$2/3),0)) -> 0 | P13: =M13+N13+O13 -> 905.04 | Q13: =P13/(1+Hypothèses!$B$6) -> 754.2 | R13: =Hypothèses!$B$3*(1+Hypothèses!$B$4)^INT((A13-1)/3) -> 760.4375 | S13: =0 -> 0 | T13: =S13*Hypothèses!$B$17 -> 0 | U13: =Q13*Hypothèses!$B$5 -> 7.542 | V13: =Q13-R13-T13-U13 -> -13.7795 | W13: =W12+V13 -> -40.17
A14: 11 | B14: =INT((A14-1)/12)+1 -> 1 | C14: =ROUND(IF(MOD($A14,12)=0,G14,(IF(14=4,0,C13))*(1-$K14)+IF((IF(14=4,0,C13))*(1-$K14)<G14,(G14-(IF(14=4,0,C13))*(1-$K14))*Hypothèses!$B$10,0)),1) -> 2.7 | D14: =ROUND(IF(MOD($A14,12)=0,H14,(IF(14=4,0,D13))*(1-$K14)+IF((IF(14=4,0,D13))*(1-$K14)<H14,(H14-(IF(14=4,0,D13))*(1-$K14))*Hypothèses!$B$10,0)),1) -> 5.3 | E14: =ROUND(IF(MOD($A14,12)=0,I14,(IF(14=4,0,E13))*(1-$K14)+IF((IF(14=4,0,E13))*(1-$K14)<I14,(I14-(IF(14=4,0,E13))*(1-$K14))*Hypothèses!$B$10,0)),1) -> 0 | F14: =ROUND(IF(MOD($A14,12)=0,J14,(IF(14=4,0,F13))*(1-$K14)+IF((IF(14=4,0,F13))*(1-$K14)<J14,(J14-(IF(14=4,0,F13))*(1-$K14))*Hypothèses!$B$10,0)),1) -> 0 | G14: =(IF(B14=1,0,IF(B14=2,Hypothèses!$B$26,IF(B14=3,Hypothèses!$C$26,Hypothèses!$D$26)))+(IF(B14=1,Hypothèses!$B$26,IF(B14=2,Hypothèses!$C$26,IF(B14=3,Hypothèses!$D$26,Hypothèses!$D$26)))-(IF(B14=1,0,IF(B14=2,Hypothèses!$B$26,IF(B14=3,Hypothèses!$C$26,Hypothèses!$D$26)))))*((A14)-INT((A14-1)/12)*12)/12)*$B$1 -> 3.2083333 | H14: =(IF(B14=1,0,IF(B14=2,Hypothèses!$B$27,IF(B14=3,Hypothèses!$C$27,Hypothèses!$D$27)))+(IF(B14=1,Hypothèses!$B$27,IF(B14=2,Hypothèses!$C$27,IF(B14=3,Hypothèses!$D$27,Hypothèses!$D$27)))-(IF(B14=1,0,IF(B14=2,Hypothèses!$B$27,IF(B14=3,Hypothèses!$C$27,Hypothèses!$D$27)))))*((A14)-INT((A14-1)/12)*12)/12)*$B$1 -> 6.4166667 | I14: =(IF(B14=1,0,IF(B14=2,Hypothèses!$B$28,IF(B14=3,Hypothèses!$C$28,Hypothèses!$D$28)))+(IF(B14=1,Hypothèses!$B$28,IF(B14=2,Hypothèses!$C$28,IF(B14=3,Hypothèses!$D$28,Hypothèses!$D$28)))-(IF(B14=1,0,IF(B14=2,Hypothèses!$B$28,IF(B14=3,Hypothèses!$C$28,Hypothèses!$D$28)))))*((A14)-INT((A14-1)/12)*12)/12)*$B$1 -> 0 | J14: =(IF(B14=1,0,IF(B14=2,Hypothèses!$B$29,IF(B14=3,Hypothèses!$C$29,Hypothèses!$D$29)))+(IF(B14=1,Hypothèses!$B$29,IF(B14=2,Hypothèses!$C$29,IF(B14=3,Hypothèses!$D$29,Hypothèses!$D$29)))-(IF(B14=1,0,IF(B14=2,Hypothèses!$B$29,IF(B14=3,Hypothèses!$C$29,Hypothèses!$D$29)))))*((A14)-INT((A14-1)/12)*12)/12)*$B$1 -> 0 | K14: =IF(A14<Hypothèses!$B$7,0,Hypothèses!$B$8*(1-Hypothèses!$B$9)^(A14-Hypothèses!$B$7)) -> 0.0405 | L14: =C14+D14+E14+F14 -> 8 | M14: =(C14*Hypothèses!$B$11+D14*Hypothèses!$B$12+E14*Hypothèses!$B$13+F14*Hypothèses!$B$14)*(IF(B14=1,Hypothèses!$B$20,IF(B14=2,Hypothèses!$B$21,Hypothèses!$B$22))+(1-(IF(B14=1,Hypothèses!$B$20,IF(B14=2,Hypothèses!$B$21,Hypothèses!$B$22))))*11/12) -> 995.66667 | N14: =L14*IF(B14=1,Hypothèses!$C$20,IF(B14=2,Hypothèses!$C$21,Hypothèses!$C$22))*IF(B14=1,Hypothèses!$D$20,IF(B14=2,Hypothèses!$D$21,Hypothèses!$D$22)) -> 8 | O14: =IF(A14=18,IF($B$2>=1,Hypothèses!$B$33,0),IF(AND(OR(A14=30,A14=34),$D$2>=1),Hypothèses!$B$34*MIN(1,$D$2/3),0)) -> 0 | P14: =M14+N14+O14 -> 1003.6667 | Q14: =P14/(1+Hypothèses!$B$6) -> 836.38889 | R14: =Hypothèses!$B$3*(1+Hypothèses!$B$4)^INT((A14-1)/3) -> 760.4375 | S14: =0 -> 0 | T14: =S14*Hypothèses!$B$17 -> 0 | U14: =Q14*Hypothèses!$B$5 -> 8.3638889 | V14: =Q14-R14-T14-U14 -> 67.5875 | W14: =W13+V14 -> 27.4175
A15: 12 | B15: =INT((A15-1)/12)+1 -> 1 | C15: =ROUND(IF(MOD($A15,12)=0,G15,(IF(15=4,0,C14))*(1-$K15)+IF((IF(15=4,0,C14))*(1-$K15)<G15,(G15-(IF(15=4,0,C14))*(1-$K15))*Hypothèses!$B$10,0)),1) -> 3.5 | D15: =ROUND(IF(MOD($A15,12)=0,H15,(IF(15=4,0,D14))*(1-$K15)+IF((IF(15=4,0,D14))*(1-$K15)<H15,(H15-(IF(15=4,0,D14))*(1-$K15))*Hypothèses!$B$10,0)),1) -> 7 | E15: =ROUND(IF(MOD($A15,12)=0,I15,(IF(15=4,0,E14))*(1-$K15)+IF((IF(15=4,0,E14))*(1-$K15)<I15,(I15-(IF(15=4,0,E14))*(1-$K15))*Hypothèses!$B$10,0)),1) -> 0 | F15: =ROUND(IF(MOD($A15,12)=0,J15,(IF(15=4,0,F14))*(1-$K15)+IF((IF(15=4,0,F14))*(1-$K15)<J15,(J15-(IF(15=4,0,F14))*(1-$K15))*Hypothèses!$B$10,0)),1) -> 0 | G15: =(IF(B15=1,0,IF(B15=2,Hypothèses!$B$26,IF(B15=3,Hypothèses!$C$26,Hypothèses!$D$26)))+(IF(B15=1,Hypothèses!$B$26,IF(B15=2,Hypothèses!$C$26,IF(B15=3,Hypothèses!$D$26,Hypothèses!$D$26)))-(IF(B15=1,0,IF(B15=2,Hypothèses!$B$26,IF(B15=3,Hypothèses!$C$26,Hypothèses!$D$26)))))*((A15)-INT((A15-1)/12)*12)/12)*$B$1 -> 3.5 | H15: =(IF(B15=1,0,IF(B15=2,Hypothèses!$B$27,IF(B15=3,Hypothèses!$C$27,Hypothèses!$D$27)))+(IF(B15=1,Hypothèses!$B$27,IF(B15=2,Hypothèses!$C$27,IF(B15=3,Hypothèses!$D$27,Hypothèses!$D$27)))-(IF(B15=1,0,IF(B15=2,Hypothèses!$B$27,IF(B15=3,Hypothèses!$C$27,Hypothèses!$D$27)))))*((A15)-INT((A15-1)/12)*12)/12)*$B$1 -> 7 | I15: =(IF(B15=1,0,IF(B15=2,Hypothèses!$B$28,IF(B15=3,Hypothèses!$C$28,Hypothèses!$D$28)))+(IF(B15=1,Hypothèses!$B$28,IF(B15=2,Hypothèses!$C$28,IF(B15=3,Hypothèses!$D$28,Hypothèses!$D$28)))-(IF(B15=1,0,IF(B15=2,Hypothèses!$B$28,IF(B15=3,Hypothèses!$C$28,Hypothèses!$D$28)))))*((A15)-INT((A15-1)/12)*12)/12)*$B$1 -> 0 | J15: =(IF(B15=1,0,IF(B15=2,Hypothèses!$B$29,IF(B15=3,Hypothèses!$C$29,Hypothèses!$D$29)))+(IF(B15=1,Hypothèses!$B$29,IF(B15=2,Hypothèses!$C$29,IF(B15=3,Hypothèses!$D$29,Hypothèses!$D$29)))-(IF(B15=1,0,IF(B15=2,Hypothèses!$B$29,IF(B15=3,Hypothèses!$C$29,Hypothèses!$D$29)))))*((A15)-INT((A15-1)/12)*12)/12)*$B$1 -> 0 | K15: =IF(A15<Hypothèses!$B$7,0,Hypothèses!$B$8*(1-Hypothèses!$B$9)^(A15-Hypothèses!$B$7)) -> 0.03645 | L15: =C15+D15+E15+F15 -> 10.5 | M15: =(C15*Hypothèses!$B$11+D15*Hypothèses!$B$12+E15*Hypothèses!$B$13+F15*Hypothèses!$B$14)*(IF(B15=1,Hypothèses!$B$20,IF(B15=2,Hypothèses!$B$21,Hypothèses!$B$22))+(1-(IF(B15=1,Hypothèses!$B$20,IF(B15=2,Hypothèses!$B$21,Hypothèses!$B$22))))*11/12) -> 1309.35 | N15: =L15*IF(B15=1,Hypothèses!$C$20,IF(B15=2,Hypothèses!$C$21,Hypothèses!$C$22))*IF(B15=1,Hypothèses!$D$20,IF(B15=2,Hypothèses!$D$21,Hypothèses!$D$22)) -> 10.5 | O15: =IF(A15=18,IF($B$2>=1,Hypothèses!$B$33,0),IF(AND(OR(A15=30,A15=34),$D$2>=1),Hypothèses!$B$34*MIN(1,$D$2/3),0)) -> 0 | P15: =M15+N15+O15 -> 1319.85 | Q15: =P15/(1+Hypothèses!$B$6) -> 1099.875 | R15: =Hypothèses!$B$3*(1+Hypothèses!$B$4)^INT((A15-1)/3) -> 760.4375 | S15: =0 -> 0 | T15: =S15*Hypothèses!$B$17 -> 0 | U15: =Q15*Hypothèses!$B$5 -> 10.99875 | V15: =Q15-R15-T15-U15 -> 328.43875 | W15: =W14+V15 -> 355.85625
A16: 13 | B16: =INT((A16-1)/12)+1 -> 2 | C16: =ROUND(IF(MOD($A16,12)=0,G16,(IF(16=4,0,C15))*(1-$K16)+IF((IF(16=4,0,C15))*(1-$K16)<G16,(G16-(IF(16=4,0,C15))*(1-$K16))*Hypothèses!$B$10,0)),1) -> 3.5 | D16: =ROUND(IF(MOD($A16,12)=0,H16,(IF(16=4,0,D15))*(1-$K16)+IF((IF(16=4,0,D15))*(1-$K16)<H16,(H16-(IF(16=4,0,D15))*(1-$K16))*Hypothèses!$B$10,0)),1) -> 7.4 | E16: =ROUND(IF(MOD($A16,12)=0,I16,(IF(16=4,0,E15))*(1-$K16)+IF((IF(16=4,0,E15))*(1-$K16)<I16,(I16-(IF(16=4,0,E15))*(1-$K16))*Hypothèses!$B$10,0)),1) -> 0 | F16: =ROUND(IF(MOD($A16,12)=0,J16,(IF(16=4,0,F15))*(1-$K16)+IF((IF(16=4,0,F15))*(1-$K16)<J16,(J16-(IF(16=4,0,F15))*(1-$K16))*Hypothèses!$B$10,0)),1) -> 0 | G16: =(IF(B16=1,0,IF(B16=2,Hypothèses!$B$26,IF(B16=3,Hypothèses!$C$26,Hypothèses!$D$26)))+(IF(B16=1,Hypothèses!$B$26,IF(B16=2,Hypothèses!$C$26,IF(B16=3,Hypothèses!$D$26,Hypothèses!$D$26)))-(IF(B16=1,0,IF(B16=2,Hypothèses!$B$26,IF(B16=3,Hypothèses!$C$26,Hypothèses!$D$26)))))*((A16)-INT((A16-1)/12)*12)/12)*$B$1 -> 3.7916667 | H16: =(IF(B16=1,0,IF(B16=2,Hypothèses!$B$27,IF(B16=3,Hypothèses!$C$27,Hypothèses!$D$27)))+(IF(B16=1,Hypothèses!$B$27,IF(B16=2,Hypothèses!$C$27,IF(B16=3,Hypothèses!$D$27,Hypothèses!$D$27)))-(IF(B16=1,0,IF(B16=2,Hypothèses!$B$27,IF(B16=3,Hypothèses!$C$27,Hypothèses!$D$27)))))*((A16)-INT((A16-1)/12)*12)/12)*$B$1 -> 8.4583333 | I16: =(IF(B16=1,0,IF(B16=2,Hypothèses!$B$28,IF(B16=3,Hypothèses!$C$28,Hypothèses!$D$28)))+(IF(B16=1,Hypothèses!$B$28,IF(B16=2,Hypothèses!$C$28,IF(B16=3,Hypothèses!$D$28,Hypothèses!$D$28)))-(IF(B16=1,0,IF(B16=2,Hypothèses!$B$28,IF(B16=3,Hypothèses!$C$28,Hypothèses!$D$28)))))*((A16)-INT((A16-1)/12)*12)/12)*$B$1 -> 0.058333333 | J16: =(IF(B16=1,0,IF(B16=2,Hypothèses!$B$29,IF(B16=3,Hypothèses!$C$29,Hypothèses!$D$29)))+(IF(B16=1,Hypothèses!$B$29,IF(B16=2,Hypothèses!$C$29,IF(B16=3,Hypothèses!$D$29,Hypothèses!$D$29)))-(IF(B16=1,0,IF(B16=2,Hypothèses!$B$29,IF(B16=3,Hypothèses!$C$29,Hypothèses!$D$29)))))*((A16)-INT((A16-1)/12)*12)/12)*$B$1 -> 0.058333333 | K16: =IF(A16<Hypothèses!$B$7,0,Hypothèses!$B$8*(1-Hypothèses!$B$9)^(A16-Hypothèses!$B$7)) -> 0.032805 | L16: =C16+D16+E16+F16 -> 10.9 | M16: =(C16*Hypothèses!$B$11+D16*Hypothèses!$B$12+E16*Hypothèses!$B$13+F16*Hypothèses!$B$14)*(IF(B16=1,Hypothèses!$B$20,IF(B16=2,Hypothèses!$B$21,Hypothèses!$B$22))+(1-(IF(B16=1,Hypothèses!$B$20,IF(B16=2,Hypothèses!$B$21,Hypothèses!$B$22))))*11/12) -> 1355.1792 | N16: =L16*IF(B16=1,Hypothèses!$C$20,IF(B16=2,Hypothèses!$C$21,Hypothèses!$C$22))*IF(B16=1,Hypothèses!$D$20,IF(B16=2,Hypothèses!$D$21,Hypothèses!$D$22)) -> 27.25 | O16: =IF(A16=18,IF($B$2>=1,Hypothèses!$B$33,0),IF(AND(OR(A16=30,A16=34),$D$2>=1),Hypothèses!$B$34*MIN(1,$D$2/3),0)) -> 0 | P16: =M16+N16+O16 -> 1382.4292 | Q16: =P16/(1+Hypothèses!$B$6) -> 1152.0243 | R16: =Hypothèses!$B$3*(1+Hypothèses!$B$4)^INT((A16-1)/3) -> 874.50312 | S16: =0 -> 0 | T16: =S16*Hypothèses!$B$17 -> 0 | U16: =Q16*Hypothèses!$B$5 -> 11.520243 | V16: =Q16-R16-T16-U16 -> 266.00094 | W16: =W15+V16 -> 621.85719
A17: 14 | B17: =INT((A17-1)/12)+1 -> 2 | C17: =ROUND(IF(MOD($A17,12)=0,G17,(IF(17=4,0,C16))*(1-$K17)+IF((IF(17=4,0,C16))*(1-$K17)<G17,(G17-(IF(17=4,0,C16))*(1-$K17))*Hypothèses!$B$10,0)),1) -> 3.7 | D17: =ROUND(IF(MOD($A17,12)=0,H17,(IF(17=4,0,D16))*(1-$K17)+IF((IF(17=4,0,D16))*(1-$K17)<H17,(H17-(IF(17=4,0,D16))*(1-$K17))*Hypothèses!$B$10,0)),1) -> 8.3 | E17: =ROUND(IF(MOD($A17,12)=0,I17,(IF(17=4,0,E16))*(1-$K17)+IF((IF(17=4,0,E16))*(1-$K17)<I17,(I17-(IF(17=4,0,E16))*(1-$K17))*Hypothèses!$B$10,0)),1) -> 0 | F17: =ROUND(IF(MOD($A17,12)=0,J17,(IF(17=4,0,F16))*(1-$K17)+IF((IF(17=4,0,F16))*(1-$K17)<J17,(J17-(IF(17=4,0,F16))*(1-$K17))*Hypothèses!$B$10,0)),1) -> 0 | G17: =(IF(B17=1,0,IF(B17=2,Hypothèses!$B$26,IF(B17=3,Hypothèses!$C$26,Hypothèses!$D$26)))+(IF(B17=1,Hypothèses!$B$26,IF(B17=2,Hypothèses!$C$26,IF(B17=3,Hypothèses!$D$26,Hypothèses!$D$26)))-(IF(B17=1,0,IF(B17=2,Hypothèses!$B$26,IF(B17=3,Hypothèses!$C$26,Hypothèses!$D$26)))))*((A17)-INT((A17-1)/12)*12)/12)*$B$1 -> 4.0833333 | H17: =(IF(B17=1,0,IF(B17=2,Hypothèses!$B$27,IF(B17=3,Hypothèses!$C$27,Hypothèses!$D$27)))+(IF(B17=1,Hypothèses!$B$27,IF(B17=2,Hypothèses!$C$27,IF(B17=3,Hypothèses!$D$27,Hypothèses!$D$27)))-(IF(B17=1,0,IF(B17=2,Hypothèses!$B$27,IF(B17=3,Hypothèses!$C$27,Hypothèses!$D$27)))))*((A17)-INT((A17-1)/12)*12)/12)*$B$1 -> 9.9166667 | I17: =(IF(B17=1,0,IF(B17=2,Hypothèses!$B$28,IF(B17=3,Hypothèses!$C$28,Hypothèses!$D$28)))+(IF(B17=1,Hypothèses!$B$28,IF(B17=2,Hypothèses!$C$28,IF(B17=3,Hypothèses!$D$28,Hypothèses!$D$28)))-(IF(B17=1,0,IF(B17=2,Hypothèses!$B$28,IF(B17=3,Hypothèses!$C$28,Hypothèses!$D$28)))))*((A17)-INT((A17-1)/12)*12)/12)*$B$1 -> 0.11666667 | J17: =(IF(B17=1,0,IF(B17=2,Hypothèses!$B$29,IF(B17=3,Hypothèses!$C$29,Hypothèses!$D$29)))+(IF(B17=1,Hypothèses!$B$29,IF(B17=2,Hypothèses!$C$29,IF(B17=3,Hypothèses!$D$29,Hypothèses!$D$29)))-(IF(B17=1,0,IF(B17=2,Hypothèses!$B$29,IF(B17=3,Hypothèses!$C$29,Hypothèses!$D$29)))))*((A17)-INT((A17-1)/12)*12)/12)*$B$1 -> 0.11666667 | K17: =IF(A17<Hypothèses!$B$7,0,Hypothèses!$B$8*(1-Hypothèses!$B$9)^(A17-Hypothèses!$B$7)) -> 0.0295245 | L17: =C17+D17+E17+F17 -> 12 | M17: =(C17*Hypothèses!$B$11+D17*Hypothèses!$B$12+E17*Hypothèses!$B$13+F17*Hypothèses!$B$14)*(IF(B17=1,Hypothèses!$B$20,IF(B17=2,Hypothèses!$B$21,Hypothèses!$B$22))+(1-(IF(B17=1,Hypothèses!$B$20,IF(B17=2,Hypothèses!$B$21,Hypothèses!$B$22))))*11/12) -> 1500.75 | N17: =L17*IF(B17=1,Hypothèses!$C$20,IF(B17=2,Hypothèses!$C$21,Hypothèses!$C$22))*IF(B17=1,Hypothèses!$D$20,IF(B17=2,Hypothèses!$D$21,Hypothèses!$D$22)) -> 30 | O17: =IF(A17=18,IF($B$2>=1,Hypothèses!$B$33,0),IF(AND(OR(A17=30,A17=34),$D$2>=1),Hypothèses!$B$34*MIN(1,$D$2/3),0)) -> 0 | P17: =M17+N17+O17 -> 1530.75 | Q17: =P17/(1+Hypothèses!$B$6) -> 1275.625 | R17: =Hypothèses!$B$3*(1+Hypothèses!$B$4)^INT((A17-1)/3) -> 874.50312 | S17: =0 -> 0 | T17: =S17*Hypothèses!$B$17 -> 0 | U17: =Q17*Hypothèses!$B$5 -> 12.75625 | V17: =Q17-R17-T17-U17 -> 388.36563 | W17: =W16+V17 -> 1010.2228
A18: 15 | B18: =INT((A18-1)/12)+1 -> 2 | C18: =ROUND(IF(MOD($A18,12)=0,G18,(IF(18=4,0,C17))*(1-$K18)+IF((IF(18=4,0,C17))*(1-$K18)<G18,(G18-(IF(18=4,0,C17))*(1-$K18))*Hypothèses!$B$10,0)),1) -> 3.9 | D18: =ROUND(IF(MOD($A18,12)=0,H18,(IF(18=4,0,D17))*(1-$K18)+IF((IF(18=4,0,D17))*(1-$K18)<H18,(H18-(IF(18=4,0,D17))*(1-$K18))*Hypothèses!$B$10,0)),1) -> 9.4 | E18: =ROUND(IF(MOD($A18,12)=0,I18,(IF(18=4,0,E17))*(1-$K18)+IF((IF(18=4,0,E17))*(1-$K18)<I18,(I18-(IF(18=4,0,E17))*(1-$K18))*Hypothèses!$B$10,0)),1) -> 0.1 | F18: =ROUND(IF(MOD($A18,12)=0,J18,(IF(18=4,0,F17))*(1-$K18)+IF((IF(18=4,0,F17))*(1-$K18)<J18,(J18-(IF(18=4,0,F17))*(1-$K18))*Hypothèses!$B$10,0)),1) -> 0.1 | G18: =(IF(B18=1,0,IF(B18=2,Hypothèses!$B$26,IF(B18=3,Hypothèses!$C$26,Hypothèses!$D$26)))+(IF(B18=1,Hypothèses!$B$26,IF(B18=2,Hypothèses!$C$26,IF(B18=3,Hypothèses!$D$26,Hypothèses!$D$26)))-(IF(B18=1,0,IF(B18=2,Hypothèses!$B$26,IF(B18=3,Hypothèses!$C$26,Hypothèses!$D$26)))))*((A18)-INT((A18-1)/12)*12)/12)*$B$1 -> 4.375 | H18: =(IF(B18=1,0,IF(B18=2,Hypothèses!$B$27,IF(B18=3,Hypothèses!$C$27,Hypothèses!$D$27)))+(IF(B18=1,Hypothèses!$B$27,IF(B18=2,Hypothèses!$C$27,IF(B18=3,Hypothèses!$D$27,Hypothèses!$D$27)))-(IF(B18=1,0,IF(B18=2,Hypothèses!$B$27,IF(B18=3,Hypothèses!$C$27,Hypothèses!$D$27)))))*((A18)-INT((A18-1)/12)*12)/12)*$B$1 -> 11.375 | I18: =(IF(B18=1,0,IF(B18=2,Hypothèses!$B$28,IF(B18=3,Hypothèses!$C$28,Hypothèses!$D$28)))+(IF(B18=1,Hypothèses!$B$28,IF(B18=2,Hypothèses!$C$28,IF(B18=3,Hypothèses!$D$28,Hypothèses!$D$28)))-(IF(B18=1,0,IF(B18=2,Hypothèses!$B$28,IF(B18=3,Hypothèses!$C$28,Hypothèses!$D$28)))))*((A18)-INT((A18-1)/12)*12)/12)*$B$1 -> 0.175 | J18: =(IF(B18=1,0,IF(B18=2,Hypothèses!$B$29,IF(B18=3,Hypothèses!$C$29,Hypothèses!$D$29)))+(IF(B18=1,Hypothèses!$B$29,IF(B18=2,Hypothèses!$C$29,IF(B18=3,Hypothèses!$D$29,Hypothèses!$D$29)))-(IF(B18=1,0,IF(B18=2,Hypothèses!$B$29,IF(B18=3,Hypothèses!$C$29,Hypothèses!$D$29)))))*((A18)-INT((A18-1)/12)*12)/12)*$B$1 -> 0.175 | K18: =IF(A18<Hypothèses!$B$7,0,Hypothèses!$B$8*(1-Hypothèses!$B$9)^(A18-Hypothèses!$B$7)) -> 0.02657205 | L18: =C18+D18+E18+F18 -> 13.5 | M18: =(C18*Hypothèses!$B$11+D18*Hypothèses!$B$12+E18*Hypothèses!$B$13+F18*Hypothèses!$B$14)*(IF(B18=1,Hypothèses!$B$20,IF(B18=2,Hypothèses!$B$21,Hypothèses!$B$22))+(1-(IF(B18=1,Hypothèses!$B$20,IF(B18=2,Hypothèses!$B$21,Hypothèses!$B$22))))*11/12) -> 1817.575 | N18: =L18*IF(B18=1,Hypothèses!$C$20,IF(B18=2,Hypothèses!$C$21,Hypothèses!$C$22))*IF(B18=1,Hypothèses!$D$20,IF(B18=2,Hypothèses!$D$21,Hypothèses!$D$22)) -> 33.75 | O18: =IF(A18=18,IF($B$2>=1,Hypothèses!$B$33,0),IF(AND(OR(A18=30,A18=34),$D$2>=1),Hypothèses!$B$34*MIN(1,$D$2/3),0)) -> 0 | P18: =M18+N18+O18 -> 1851.325 | Q18: =P18/(1+Hypothèses!$B$6) -> 1542.7708 | R18: =Hypothèses!$B$3*(1+Hypothèses!$B$4)^INT((A18-1)/3) -> 874.50312 | S18: =0 -> 0 | T18: =S18*Hypothèses!$B$17 -> 0 | U18: =Q18*Hypothèses!$B$5 -> 15.427708 | V18: =Q18-R18-T18-U18 -> 652.84 | W18: =W17+V18 -> 1663.0628
A19: 16 | B19: =INT((A19-1)/12)+1 -> 2 | C19: =ROUND(IF(MOD($A19,12)=0,G19,(IF(19=4,0,C18))*(1-$K19)+IF((IF(19=4,0,C18))*(1-$K19)<G19,(G19-(IF(19=4,0,C18))*(1-$K19))*Hypothèses!$B$10,0)),1) -> 4.2 | D19: =ROUND(IF(MOD($A19,12)=0,H19,(IF(19=4,0,D18))*(1-$K19)+IF((IF(19=4,0,D18))*(1-$K19)<H19,(H19-(IF(19=4,0,D18))*(1-$K19))*Hypothèses!$B$10,0)),1) -> 10.6 | E19: =ROUND(IF(MOD($A19,12)=0,I19,(IF(19=4,0,E18))*(1-$K19)+IF((IF(19=4,0,E18))*(1-$K19)<I19,(I19-(IF(19=4,0,E18))*(1-$K19))*Hypothèses!$B$10,0)),1) -> 0.2 | F19: =ROUND(IF(MOD($A19,12)=0,J19,(IF(19=4,0,F18))*(1-$K19)+IF((IF(19=4,0,F18))*(1-$K19)<J19,(J19-(IF(19=4,0,F18))*(1-$K19))*Hypothèses!$B$10,0)),1) -> 0.2 | G19: =(IF(B19=1,0,IF(B19=2,Hypothèses!$B$26,IF(B19=3,Hypothèses!$C$26,Hypothèses!$D$26)))+(IF(B19=1,Hypothèses!$B$26,IF(B19=2,Hypothèses!$C$26,IF(B19=3,Hypothèses!$D$26,Hypothèses!$D$26)))-(IF(B19=1,0,IF(B19=2,Hypothèses!$B$26,IF(B19=3,Hypothèses!$C$26,Hypothèses!$D$26)))))*((A19)-INT((A19-1)/12)*12)/12)*$B$1 -> 4.6666667 | H19: =(IF(B19=1,0,IF(B19=2,Hypothèses!$B$27,IF(B19=3,Hypothèses!$C$27,Hypothèses!$D$27)))+(IF(B19=1,Hypothèses!$B$27,IF(B19=2,Hypothèses!$C$27,IF(B19=3,Hypothèses!$D$27,Hypothèses!$D$27)))-(IF(B19=1,0,IF(B19=2,Hypothèses!$B$27,IF(B19=3,Hypothèses!$C$27,Hypothèses!$D$27)))))*((A19)-INT((A19-1)/12)*12)/12)*$B$1 -> 12.833333 | I19: =(IF(B19=1,0,IF(B19=2,Hypothèses!$B$28,IF(B19=3,Hypothèses!$C$28,Hypothèses!$D$28)))+(IF(B19=1,Hypothèses!$B$28,IF(B19=2,Hypothèses!$C$28,IF(B19=3,Hypothèses!$D$28,Hypothèses!$D$28)))-(IF(B19=1,0,IF(B19=2,Hypothèses!$B$28,IF(B19=3,Hypothèses!$C$28,Hypothèses!$D$28)))))*((A19)-INT((A19-1)/12)*12)/12)*$B$1 -> 0.23333333 | J19: =(IF(B19=1,0,IF(B19=2,Hypothèses!$B$29,IF(B19=3,Hypothèses!$C$29,Hypothèses!$D$29)))+(IF(B19=1,Hypothèses!$B$29,IF(B19=2,Hypothèses!$C$29,IF(B19=3,Hypothèses!$D$29,Hypothèses!$D$29)))-(IF(B19=1,0,IF(B19=2,Hypothèses!$B$29,IF(B19=3,Hypothèses!$C$29,Hypothèses!$D$29)))))*((A19)-INT((A19-1)/12)*12)/12)*$B$1 -> 0.23333333 | K19: =IF(A19<Hypothèses!$B$7,0,Hypothèses!$B$8*(1-Hypothèses!$B$9)^(A19-Hypothèses!$B$7)) -> 0.023914845 | L19: =C19+D19+E19+F19 -> 15.2 | M19: =(C19*Hypothèses!$B$11+D19*Hypothèses!$B$12+E19*Hypothèses!$B$13+F19*Hypothèses!$B$14)*(IF(B19=1,Hypothèses!$B$20,IF(B19=2,Hypothèses!$B$21,Hypothèses!$B$22))+(1-(IF(B19=1,Hypothèses!$B$20,IF(B19=2,Hypothèses!$B$21,Hypothèses!$B$22))))*11/12) -> 2157.2083 | N19: =L19*IF(B19=1,Hypothèses!$C$20,IF(B19=2,Hypothèses!$C$21,Hypothèses!$C$22))*IF(B19=1,Hypothèses!$D$20,IF(B19=2,Hypothèses!$D$21,Hypothèses!$D$22)) -> 38 | O19: =IF(A19=18,IF($B$2>=1,Hypothèses!$B$33,0),IF(AND(OR(A19=30,A19=34),$D$2>=1),Hypothèses!$B$34*MIN(1,$D$2/3),0)) -> 0 | P19: =M19+N19+O19 -> 2195.2083 | Q19: =P19/(1+Hypothèses!$B$6) -> 1829.3403 | R19: =Hypothèses!$B$3*(1+Hypothèses!$B$4)^INT((A19-1)/3) -> 1005.6786 | S19: =0 -> 0 | T19: =S19*Hypothèses!$B$17 -> 0 | U19: =Q19*Hypothèses!$B$5 -> 18.293403 | V19: =Q19-R19-T19-U19 -> 805.36828 | W19: =W18+V19 -> 2468.4311
A20: 17 | B20: =INT((A20-1)/12)+1 -> 2 | C20: =ROUND(IF(MOD($A20,12)=0,G20,(IF(20=4,0,C19))*(1-$K20)+IF((IF(20=4,0,C19))*(1-$K20)<G20,(G20-(IF(20=4,0,C19))*(1-$K20))*Hypothèses!$B$10,0)),1) -> 4.4 | D20: =ROUND(IF(MOD($A20,12)=0,H20,(IF(20=4,0,D19))*(1-$K20)+IF((IF(20=4,0,D19))*(1-$K20)<H20,(H20-(IF(20=4,0,D19))*(1-$K20))*Hypothèses!$B$10,0)),1) -> 11.9 | E20: =ROUND(IF(MOD($A20,12)=0,I20,(IF(20=4,0,E19))*(1-$K20)+IF((IF(20=4,0,E19))*(1-$K20)<I20,(I20-(IF(20=4,0,E19))*(1-$K20))*Hypothèses!$B$10,0)),1) -> 0.2 | F20: =ROUND(IF(MOD($A20,12)=0,J20,(IF(20=4,0,F19))*(1-$K20)+IF((IF(20=4,0,F19))*(1-$K20)<J20,(J20-(IF(20=4,0,F19))*(1-$K20))*Hypothèses!$B$10,0)),1) -> 0.2 | G20: =(IF(B20=1,0,IF(B20=2,Hypothèses!$B$26,IF(B20=3,Hypothèses!$C$26,Hypothèses!$D$26)))+(IF(B20=1,Hypothèses!$B$26,IF(B20=2,Hypothèses!$C$26,IF(B20=3,Hypothèses!$D$26,Hypothèses!$D$26)))-(IF(B20=1,0,IF(B20=2,Hypothèses!$B$26,IF(B20=3,Hypothèses!$C$26,Hypothèses!$D$26)))))*((A20)-INT((A20-1)/12)*12)/12)*$B$1 -> 4.9583333 | H20: =(IF(B20=1,0,IF(B20=2,Hypothèses!$B$27,IF(B20=3,Hypothèses!$C$27,Hypothèses!$D$27)))+(IF(B20=1,Hypothèses!$B$27,IF(B20=2,Hypothèses!$C$27,IF(B20=3,Hypothèses!$D$27,Hypothèses!$D$27)))-(IF(B20=1,0,IF(B20=2,Hypothèses!$B$27,IF(B20=3,Hypothèses!$C$27,Hypothèses!$D$27)))))*((A20)-INT((A20-1)/12)*12)/12)*$B$1 -> 14.291667 | I20: =(IF(B20=1,0,IF(B20=2,Hypothèses!$B$28,IF(B20=3,Hypothèses!$C$28,Hypothèses!$D$28)))+(IF(B20=1,Hypothèses!$B$28,IF(B20=2,Hypothèses!$C$28,IF(B20=3,Hypothèses!$D$28,Hypothèses!$D$28)))-(IF(B20=1,0,IF(B20=2,Hypothèses!$B$28,IF(B20=3,Hypothèses!$C$28,Hypothèses!$D$28)))))*((A20)-INT((A20-1)/12)*12)/12)*$B$1 -> 0.29166667 | J20: =(IF(B20=1,0,IF(B20=2,Hypothèses!$B$29,IF(B20=3,Hypothèses!$C$29,Hypothèses!$D$29)))+(IF(B20=1,Hypothèses!$B$29,IF(B20=2,Hypothèses!$C$29,IF(B20=3,Hypothèses!$D$29,Hypothèses!$D$29)))-(IF(B20=1,0,IF(B20=2,Hypothèses!$B$29,IF(B20=3,Hypothèses!$C$29,Hypothèses!$D$29)))))*((A20)-INT((A20-1)/12)*12)/12)*$B$1 -> 0.29166667 | K20: =IF(A20<Hypothèses!$B$7,0,Hypothèses!$B$8*(1-Hypothèses!$B$9)^(A20-Hypothèses!$B$7)) -> 0.021523361 | L20: =C20+D20+E20+F20 -> 16.7 | M20: =(C20*Hypothèses!$B$11+D20*Hypothèses!$B$12+E20*Hypothèses!$B$13+F20*Hypothèses!$B$14)*(IF(B20=1,Hypothèses!$B$20,IF(B20=2,Hypothèses!$B$21,Hypothèses!$B$22))+(1-(IF(B20=1,Hypothèses!$B$20,IF(B20=2,Hypothèses!$B$21,Hypothèses!$B$22))))*11/12) -> 2359.8958 | N20: =L20*IF(B20=1,Hypothèses!$C$20,IF(B20=2,Hypothèses!$C$21,Hypothèses!$C$22))*IF(B20=1,Hypothèses!$D$20,IF(B20=2,Hypothèses!$D$21,Hypothèses!$D$22)) -> 41.75 | O20: =IF(A20=18,IF($B$2>=1,Hypothèses!$B$33,0),IF(AND(OR(A20=30,A20=34),$D$2>=1),Hypothèses!$B$34*MIN(1,$D$2/3),0)) -> 0 | P20: =M20+N20+O20 -> 2401.6458 | Q20: =P20/(1+Hypothèses!$B$6) -> 2001.3715 | R20: =Hypothèses!$B$3*(1+Hypothèses!$B$4)^INT((A20-1)/3) -> 1005.6786 | S20: =0 -> 0 | T20: =S20*Hypothèses!$B$17 -> 0 | U20: =Q20*Hypothèses!$B$5 -> 20.013715 | V20: =Q20-R20-T20-U20 -> 975.67922 | W20: =W19+V20 -> 3444.1103
A21: 18 | B21: =INT((A21-1)/12)+1 -> 2 | C21: =ROUND(IF(MOD($A21,12)=0,G21,(IF(21=4,0,C20))*(1-$K21)+IF((IF(21=4,0,C20))*(1-$K21)<G21,(G21-(IF(21=4,0,C20))*(1-$K21))*Hypothèses!$B$10,0)),1) -> 4.7 | D21: =ROUND(IF(MOD($A21,12)=0,H21,(IF(21=4,0,D20))*(1-$K21)+IF((IF(21=4,0,D20))*(1-$K21)<H21,(H21-(IF(21=4,0,D20))*(1-$K21))*Hypothèses!$B$10,0)),1) -> 13.3 | E21: =ROUND(IF(MOD($A21,12)=0,I21,(IF(21=4,0,E20))*(1-$K21)+IF((IF(21=4,0,E20))*(1-$K21)<I21,(I21-(IF(21=4,0,E20))*(1-$K21))*Hypothèses!$B$10,0)),1) -> 0.3 | F21: =ROUND(IF(MOD($A21,12)=0,J21,(IF(21=4,0,F20))*(1-$K21)+IF((IF(21=4,0,F20))*(1-$K21)<J21,(J21-(IF(21=4,0,F20))*(1-$K21))*Hypothèses!$B$10,0)),1) -> 0.3 | G21: =(IF(B21=1,0,IF(B21=2,Hypothèses!$B$26,IF(B21=3,Hypothèses!$C$26,Hypothèses!$D$26)))+(IF(B21=1,Hypothèses!$B$26,IF(B21=2,Hypothèses!$C$26,IF(B21=3,Hypothèses!$D$26,Hypothèses!$D$26)))-(IF(B21=1,0,IF(B21=2,Hypothèses!$B$26,IF(B21=3,Hypothèses!$C$26,Hypothèses!$D$26)))))*((A21)-INT((A21-1)/12)*12)/12)*$B$1 -> 5.25 | H21: =(IF(B21=1,0,IF(B21=2,Hypothèses!$B$27,IF(B21=3,Hypothèses!$C$27,Hypothèses!$D$27)))+(IF(B21=1,Hypothèses!$B$27,IF(B21=2,Hypothèses!$C$27,IF(B21=3,Hypothèses!$D$27,Hypothèses!$D$27)))-(IF(B21=1,0,IF(B21=2,Hypothèses!$B$27,IF(B21=3,Hypothèses!$C$27,Hypothèses!$D$27)))))*((A21)-INT((A21-1)/12)*12)/12)*$B$1 -> 15.75 | I21: =(IF(B21=1,0,IF(B21=2,Hypothèses!$B$28,IF(B21=3,Hypothèses!$C$28,Hypothèses!$D$28)))+(IF(B21=1,Hypothèses!$B$28,IF(B21=2,Hypothèses!$C$28,IF(B21=3,Hypothèses!$D$28,Hypothèses!$D$28)))-(IF(B21=1,0,IF(B21=2,Hypothèses!$B$28,IF(B21=3,Hypothèses!$C$28,Hypothèses!$D$28)))))*((A21)-INT((A21-1)/12)*12)/12)*$B$1 -> 0.35 | J21: =(IF(B21=1,0,IF(B21=2,Hypothèses!$B$29,IF(B21=3,Hypothèses!$C$29,Hypothèses!$D$29)))+(IF(B21=1,Hypothèses!$B$29,IF(B21=2,Hypothèses!$C$29,IF(B21=3,Hypothèses!$D$29,Hypothèses!$D$29)))-(IF(B21=1,0,IF(B21=2,Hypothèses!$B$29,IF(B21=3,Hypothèses!$C$29,Hypothèses!$D$29)))))*((A21)-INT((A21-1)/12)*12)/12)*$B$1 -> 0.35 | K21: =IF(A21<Hypothèses!$B$7,0,Hypothèses!$B$8*(1-Hypothèses!$B$9)^(A21-Hypothèses!$B$7)) -> 0.019371024 | L21: =C21+D21+E21+F21 -> 18.6 | M21: =(C21*Hypothèses!$B$11+D21*Hypothèses!$B$12+E21*Hypothèses!$B$13+F21*Hypothèses!$B$14)*(IF(B21=1,Hypothèses!$B$20,IF(B21=2,Hypothèses!$B$21,Hypothèses!$B$22))+(1-(IF(B21=1,Hypothèses!$B$20,IF(B21=2,Hypothèses!$B$21,Hypothèses!$B$22))))*11/12) -> 2728.0875 | N21: =L21*IF(B21=1,Hypothèses!$C$20,IF(B21=2,Hypothèses!$C$21,Hypothèses!$C$22))*IF(B21=1,Hypothèses!$D$20,IF(B21=2,Hypothèses!$D$21,Hypothèses!$D$22)) -> 46.5 | O21: =IF(A21=18,IF($B$2>=1,Hypothèses!$B$33,0),IF(AND(OR(A21=30,A21=34),$D$2>=1),Hypothèses!$B$34*MIN(1,$D$2/3),0)) -> 15000 | P21: =M21+N21+O21 -> 17774.588 | Q21: =P21/(1+Hypothèses!$B$6) -> 14812.156 | R21: =Hypothèses!$B$3*(1+Hypothèses!$B$4)^INT((A21-1)/3) -> 1005.6786 | S21: =0 -> 0 | T21: =S21*Hypothèses!$B$17 -> 0 | U21: =Q21*Hypothèses!$B$5 -> 148.12156 | V21: =Q21-R21-T21-U21 -> 13658.356 | W21: =W20+V21 -> 17102.466
A22: 19 | B22: =INT((A22-1)/12)+1 -> 2 | C22: =ROUND(IF(MOD($A22,12)=0,G22,(IF(22=4,0,C21))*(1-$K22)+IF((IF(22=4,0,C21))*(1-$K22)<G22,(G22-(IF(22=4,0,C21))*(1-$K22))*Hypothèses!$B$10,0)),1) -> 5 | D22: =ROUND(IF(MOD($A22,12)=0,H22,(IF(22=4,0,D21))*(1-$K22)+IF((IF(22=4,0,D21))*(1-$K22)<H22,(H22-(IF(22=4,0,D21))*(1-$K22))*Hypothèses!$B$10,0)),1) -> 14.7 | E22: =ROUND(IF(MOD($A22,12)=0,I22,(IF(22=4,0,E21))*(1-$K22)+IF((IF(22=4,0,E21))*(1-$K22)<I22,(I22-(IF(22=4,0,E21))*(1-$K22))*Hypothèses!$B$10,0)),1) -> 0.3 | F22: =ROUND(IF(MOD($A22,12)=0,J22,(IF(22=4,0,F21))*(1-$K22)+IF((IF(22=4,0,F21))*(1-$K22)<J22,(J22-(IF(22=4,0,F21))*(1-$K22))*Hypothèses!$B$10,0)),1) -> 0.3 | G22: =(IF(B22=1,0,IF(B22=2,Hypothèses!$B$26,IF(B22=3,Hypothèses!$C$26,Hypothèses!$D$26)))+(IF(B22=1,Hypothèses!$B$26,IF(B22=2,Hypothèses!$C$26,IF(B22=3,Hypothèses!$D$26,Hypothèses!$D$26)))-(IF(B22=1,0,IF(B22=2,Hypothèses!$B$26,IF(B22=3,Hypothèses!$C$26,Hypothèses!$D$26)))))*((A22)-INT((A22-1)/12)*12)/12)*$B$1 -> 5.5416667 | H22: =(IF(B22=1,0,IF(B22=2,Hypothèses!$B$27,IF(B22=3,Hypothèses!$C$27,Hypothèses!$D$27)))+(IF(B22=1,Hypothèses!$B$27,IF(B22=2,Hypothèses!$C$27,IF(B22=3,Hypothèses!$D$27,Hypothèses!$D$27)))-(IF(B22=1,0,IF(B22=2,Hypothèses!$B$27,IF(B22=3,Hypothèses!$C$27,Hypothèses!$D$27)))))*((A22)-INT((A22-1)/12)*12)/12)*$B$1 -> 17.208333 | I22: =(IF(B22=1,0,IF(B22=2,Hypothèses!$B$28,IF(B22=3,Hypothèses!$C$28,Hypothèses!$D$28)))+(IF(B22=1,Hypothèses!$B$28,IF(B22=2,Hypothèses!$C$28,IF(B22=3,Hypothèses!$D$28,Hypothèses!$D$28)))-(IF(B22=1,0,IF(B22=2,Hypothèses!$B$28,IF(B22=3,Hypothèses!$C$28,Hypothèses!$D$28)))))*((A22)-INT((A22-1)/12)*12)/12)*$B$1 -> 0.40833333 | J22: =(IF(B22=1,0,IF(B22=2,Hypothèses!$B$29,IF(B22=3,Hypothèses!$C$29,Hypothèses!$D$29)))+(IF(B22=1,Hypothèses!$B$29,IF(B22=2,Hypothèses!$C$29,IF(B22=3,Hypothèses!$D$29,Hypothèses!$D$29)))-(IF(B22=1,0,IF(B22=2,Hypothèses!$B$29,IF(B22=3,Hypothèses!$C$29,Hypothèses!$D$29)))))*((A22)-INT((A22-1)/12)*12)/12)*$B$1 -> 0.40833333 | K22: =IF(A22<Hypothèses!$B$7,0,Hypothèses!$B$8*(1-Hypothèses!$B$9)^(A22-Hypothèses!$B$7)) -> 0.017433922 | L22: =C22+D22+E22+F22 -> 20.3 | M22: =(C22*Hypothèses!$B$11+D22*Hypothèses!$B$12+E22*Hypothèses!$B$13+F22*Hypothèses!$B$14)*(IF(B22=1,Hypothèses!$B$20,IF(B22=2,Hypothèses!$B$21,Hypothèses!$B$22))+(1-(IF(B22=1,Hypothèses!$B$20,IF(B22=2,Hypothèses!$B$21,Hypothèses!$B$22))))*11/12) -> 2953.5833 | N22: =L22*IF(B22=1,Hypothèses!$C$20,IF(B22=2,Hypothèses!$C$21,Hypothèses!$C$22))*IF(B22=1,Hypothèses!$D$20,IF(B22=2,Hypothèses!$D$21,Hypothèses!$D$22)) -> 50.75 | O22: =IF(A22=18,IF($B$2>=1,Hypothèses!$B$33,0),IF(AND(OR(A22=30,A22=34),$D$2>=1),Hypothèses!$B$34*MIN(1,$D$2/3),0)) -> 0 | P22: =M22+N22+O22 -> 3004.3333 | Q22: =P22/(1+Hypothèses!$B$6) -> 2503.6111 | R22: =Hypothèses!$B$3*(1+Hypothèses!$B$4)^INT((A22-1)/3) -> 1156.5304 | S22: =0 -> 0 | T22: =S22*Hypothèses!$B$17 -> 0 | U22: =Q22*Hypothèses!$B$5 -> 25.036111 | V22: =Q22-R22-T22-U22 -> 1322.0446 | W22: =W21+V22 -> 18424.511
A23: 20 | B23: =INT((A23-1)/12)+1 -> 2 | C23: =ROUND(IF(MOD($A23,12)=0,G23,(IF(23=4,0,C22))*(1-$K23)+IF((IF(23=4,0,C22))*(1-$K23)<G23,(G23-(IF(23=4,0,C22))*(1-$K23))*Hypothèses!$B$10,0)),1) -> 5.3 | D23: =ROUND(IF(MOD($A23,12)=0,H23,(IF(23=4,0,D22))*(1-$K23)+IF((IF(23=4,0,D22))*(1-$K23)<H23,(H23-(IF(23=4,0,D22))*(1-$K23))*Hypothèses!$B$10,0)),1) -> 16.1 | E23: =ROUND(IF(MOD($A23,12)=0,I23,(IF(23=4,0,E22))*(1-$K23)+IF((IF(23=4,0,E22))*(1-$K23)<I23,(I23-(IF(23=4,0,E22))*(1-$K23))*Hypothèses!$B$10,0)),1) -> 0.4 | F23: =ROUND(IF(MOD($A23,12)=0,J23,(IF(23=4,0,F22))*(1-$K23)+IF((IF(23=4,0,F22))*(1-$K23)<J23,(J23-(IF(23=4,0,F22))*(1-$K23))*Hypothèses!$B$10,0)),1) -> 0.4 | G23: =(IF(B23=1,0,IF(B23=2,Hypothèses!$B$26,IF(B23=3,Hypothèses!$C$26,Hypothèses!$D$26)))+(IF(B23=1,Hypothèses!$B$26,IF(B23=2,Hypothèses!$C$26,IF(B23=3,Hypothèses!$D$26,Hypothèses!$D$26)))-(IF(B23=1,0,IF(B23=2,Hypothèses!$B$26,IF(B23=3,Hypothèses!$C$26,Hypothèses!$D$26)))))*((A23)-INT((A23-1)/12)*12)/12)*$B$1 -> 5.8333333 | H23: =(IF(B23=1,0,IF(B23=2,Hypothèses!$B$27,IF(B23=3,Hypothèses!$C$27,Hypothèses!$D$27)))+(IF(B23=1,Hypothèses!$B$27,IF(B23=2,Hypothèses!$C$27,IF(B23=3,Hypothèses!$D$27,Hypothèses!$D$27)))-(IF(B23=1,0,IF(B23=2,Hypothèses!$B$27,IF(B23=3,Hypothèses!$C$27,Hypothèses!$D$27)))))*((A23)-INT((A23-1)/12)*12)/12)*$B$1 -> 18.666667 | I23: =(IF(B23=1,0,IF(B23=2,Hypothèses!$B$28,IF(B23=3,Hypothèses!$C$28,Hypothèses!$D$28)))+(IF(B23=1,Hypothèses!$B$28,IF(B23=2,Hypothèses!$C$28,IF(B23=3,Hypothèses!$D$28,Hypothèses!$D$28)))-(IF(B23=1,0,IF(B23=2,Hypothèses!$B$28,IF(B23=3,Hypothèses!$C$28,Hypothèses!$D$28)))))*((A23)-INT((A23-1)/12)*12)/12)*$B$1 -> 0.46666667 | J23: =(IF(B23=1,0,IF(B23=2,Hypothèses!$B$29,IF(B23=3,Hypothèses!$C$29,Hypothèses!$D$29)))+(IF(B23=1,Hypothèses!$B$29,IF(B23=2,Hypothèses!$C$29,IF(B23=3,Hypothèses!$D$29,Hypothèses!$D$29)))-(IF(B23=1,0,IF(B23=2,Hypothèses!$B$29,IF(B23=3,Hypothèses!$C$29,Hypothèses!$D$29)))))*((A23)-INT((A23-1)/12)*12)/12)*$B$1 -> 0.46666667 | K23: =IF(A23<Hypothèses!$B$7,0,Hypothèses!$B$8*(1-Hypothèses!$B$9)^(A23-Hypothèses!$B$7)) -> 0.01569053 | L23: =C23+D23+E23+F23 -> 22.2 | M23: =(C23*Hypothèses!$B$11+D23*Hypothèses!$B$12+E23*Hypothèses!$B$13+F23*Hypothèses!$B$14)*(IF(B23=1,Hypothèses!$B$20,IF(B23=2,Hypothèses!$B$21,Hypothèses!$B$22))+(1-(IF(B23=1,Hypothèses!$B$20,IF(B23=2,Hypothèses!$B$21,Hypothèses!$B$22))))*11/12) -> 3321.775 | N23: =L23*IF(B23=1,Hypothèses!$C$20,IF(B23=2,Hypothèses!$C$21,Hypothèses!$C$22))*IF(B23=1,Hypothèses!$D$20,IF(B23=2,Hypothèses!$D$21,Hypothèses!$D$22)) -> 55.5 | O23: =IF(A23=18,IF($B$2>=1,Hypothèses!$B$33,0),IF(AND(OR(A23=30,A23=34),$D$2>=1),Hypothèses!$B$34*MIN(1,$D$2/3),0)) -> 0 | P23: =M23+N23+O23 -> 3377.275 | Q23: =P23/(1+Hypothèses!$B$6) -> 2814.3958 | R23: =Hypothèses!$B$3*(1+Hypothèses!$B$4)^INT((A23-1)/3) -> 1156.5304 | S23: =0 -> 0 | T23: =S23*Hypothèses!$B$17 -> 0 | U23: =Q23*Hypothèses!$B$5 -> 28.143958 | V23: =Q23-R23-T23-U23 -> 1629.7215 | W23: =W22+V23 -> 20054.233
